Workbook
Name a: [1]設定!$B$11
Name averagerate: [2]設定!$B$15
Name currency: [2]設定!$B$11
Name currencycodeYEN: [3]設定!$C$10
Name factory: [2]設定!$B$8
Name lastyear: [2]設定!$B$3
Name lastyeardays: [2]設定!$C$24
Name lastyearpastdays: [2]設定!$B$24
Name month: [2]設定!$B$4
Name planningaveragerate: [2]設定!$B$17
Name planningtax: [2]設定!$B$21
Name previousaveragerate: [2]設定!$B$16
Name previoustax: [2]設定!$B$20
Name RECOM: [4]DEF!$B$4
Name RECOMNAME: [4]DEF!$C$4
Name RECUR: [4]DEF!$B$5
Name REMAE_DL: [4]DEF!$C$11
Name REMAE_MET: [4]DEF!$D$11
Name REMAE_UL: [4]DEF!$B$11
Name REPERNAME: [4]DEF!$C$2
Name representative: [2]設定!$B$34
Name RETDF_DL: [4]DEF!$C$12
Name RETDF_MET: [4]DEF!$D$12
Name RETDF_UL: [4]DEF!$B$12
Name REVER: [4]DEF!$B$1
Name ta: [5]TABLE!$A$2:$D$1683
Name TABLE: [4]TABLE!$A$2:$D$1714
Name tax: [2]設定!$B$19
Name thisyear: [2]設定!$B$2
Name thisyeardays: [2]設定!$C$23
Name thisyearpastdays: [2]設定!$B$23
Name unit: [2]設定!$C$11
Name unitname: [2]設定!$D$11

Sheet Quản lý MT năm
B1: QUẢN LÝ HẠNG MỤC COSTDOWN PHÒNG CƠ KHÍ | I1: Ngày báo cáo:
I2: Đơn vị tính: ( TriệuVND)
B3: Tháng | C3: MT/TT | D3: 1.Nội tác linh kiện tồn kho | E3: 2.Nội tác linh kiện khuôn thành hình | F3: 3.Nội tác linh kiện khuôn dập | G3: MT từng tháng | H3: TT từng tháng | I3: MT Lũy Kế | J3: TT Lũy Kế | M3: T1 | N3: T2 | O3: T3 | P3: T4 | Q3: T5 | R3: T6 | S3: T7 | T3: T8 | U3: T9 | V3: T10 | W3: T11 | X3: T12
B4: T1 | C4: Mục tiêu | D4: ='1.Nội tác linh kiện tòn kho '!T104 -> 69.473393 | E4: ='2.Nội tác LK thành hình'!S32 -> 63.540775 | F4: ='3.Nội tác LK khuôn dập'!T94 -> 57.207854 | G4: =SUM(D4:F4) -> 190.22202 | I4: =SUM(D4:F4) -> 190.22202 | J4: =H5 -> 251.97753 | L4: MT đơn tháng | M4: =G4 -> 190.22202 | N4: =G6 -> 132.89129 | O4: =G8 -> 324.12377 | P4: =G10 -> 326.69296 | Q4: =G12 -> 325.52909 | R4: =G14 -> 312.7414 | S4: =G16 -> 311.58999 | T4: =G18 -> 308.13623 | U4: =G20 -> 320.07877 | V4: =G22 -> 287.69636 | W4: =G24 -> 275.64558 | X4: =G26 -> 249.12347 | AA4: MỤC TIÊU -THỰC TÍCH THÁNG 4/2026(triệu VND)
B5: T1 | C5: Thực tích | D5: ='THỰC TẾ GIA CÔNG '!R8 -> 39.938956 | E5: ='THỰC TẾ GIA CÔNG '!R9 -> 52.59774 | F5: ='THỰC TẾ GIA CÔNG '!R10 -> 159.44083 | G5: =SUM(D5:F5) -> 251.97753 | H5: =SUM(D5:F5) -> 251.97753 | I5: =I4 -> 190.22202 | J5: =J4 -> 251.97753 | K5: =J5/I5 -> 1.3246496 | L5: MT Lũy kế | M5: =M4 -> 190.22202 | N5: =M5+N4 -> 323.11331 | O5: =N5+O4 -> 647.23708 | P5: =O5+P4 -> 973.93004 | Q5: =P5+Q4 -> 1299.4591 | R5: =Q5+R4 -> 1612.2005 | S5: =R5+S4 -> 1923.7905 | T5: =S5+T4 -> 2231.9268 | U5: =T5+U4 -> 2552.0055 | ... X5: =W5+X4 -> 3364.4709 | AA5: Các hạng mục costdown năm 2026 | AB5: 1.Nội tác linh kiện tồn kho | AC5: 2.Nội tác linh kiện khuôn thành hình | AD5: 3.Nội tác linh kiện khuôn dập
B6: T2 | C6: Mục tiêu | D6: ='1.Nội tác linh kiện tòn kho '!U104 -> 27.54574 | E6: ='2.Nội tác LK thành hình'!T32 -> 72.462414 | F6: ='3.Nội tác LK khuôn dập'!U94 -> 32.883132 | G6: =SUM(D6:F6) -> 132.89129 | I6: =I4+G6 -> 323.11331 | J6: =J7 -> 325.42567 | AA6: Mục tiêu | AB6: =D10 -> 148.31054 | AC6: =E10 -> 69.873857 | AD6: =F10 -> 108.50857
B7: T2 | C7: Thực tích | D7: ='THỰC TẾ GIA CÔNG '!T8 -> 0 | E7: ='THỰC TẾ GIA CÔNG '!T9 -> 62.294148 | F7: ='THỰC TẾ GIA CÔNG '!T10 -> 11.154 | H7: =SUM(D7:F7) -> 73.448148 | I7: =I6 -> 323.11331 | J7: =H7+J5 -> 325.42567 | K7: =J7/I7 -> 1.0071565 | AA7: Thực tích | AB7: 120 | AC7: =E11 -> 0 | AD7: =F11 -> 0
B8: T3 | C8: Mục tiêu | D8: ='1.Nội tác linh kiện tòn kho '!V104 -> 132.91869 | E8: ='2.Nội tác LK thành hình'!U32 -> 99.335062 | F8: ='3.Nội tác LK khuôn dập'!V94 -> 91.870024 | G8: =SUM(D8:F8) -> 324.12377 | I8: =I6+G8 -> 647.23708 | J8: =J9 -> 666.47104
B9: T3 | C9: Thực tích | D9: ='THỰC TẾ GIA CÔNG '!V8 -> 23.0932 | E9: ='THỰC TẾ GIA CÔNG '!V9 -> 254.65881 | F9: ='THỰC TẾ GIA CÔNG '!V10 -> 63.29336 | H9: =SUM(D9:F9) -> 341.04537 | I9: =I8 -> 647.23708 | J9: =SUM(J7,H9) -> 666.47104 | K9: =J9/I9 -> 1.029717
B10: T4 | C10: Mục tiêu | D10: ='1.Nội tác linh kiện tòn kho '!W104 -> 148.31054 | E10: ='2.Nội tác LK thành hình'!V32 -> 69.873857 | F10: ='3.Nội tác LK khuôn dập'!W94 -> 108.50857 | G10: =SUM(D10:F10) -> 326.69296 | I10: =I8+G10 -> 973.93004 | J10: =J11 -> 666.47104
B11: T4 | C11: Thực tích | D11: ='1.Nội tác linh kiện tòn kho '!AV104 -> 0 | E11: ='2.Nội tác LK thành hình'!AU32 -> 0 | F11: ='3.Nội tác LK khuôn dập'!AU94 -> 0 | H11: =SUM(D11:F11) -> 0 | I11: =I10 -> 973.93004 | J11: =SUM(J9,H11) -> 666.47104 | K11: =J11/I11 -> 0.684311
B12: T5 | C12: Mục tiêu | D12: ='1.Nội tác linh kiện tòn kho '!X104 -> 137.54751 | E12: ='2.Nội tác LK thành hình'!W32 -> 69.834409 | F12: ='3.Nội tác LK khuôn dập'!X94 -> 118.14717 | G12: =SUM(D12:F12) -> 325.52909 | I12: =I10+G12 -> 1299.4591 | J12: =J13 -> 666.47104
B13: T5 | C13: Thực tích | D13: ='1.Nội tác linh kiện tòn kho '!AX104 -> 0 | E13: ='2.Nội tác LK thành hình'!AW32 -> 0 | F13: ='3.Nội tác LK khuôn dập'!AW94 -> 0 | H13: =SUM(D13:F13) -> 0 | I13: =I12 -> 1299.4591 | J13: =SUM(J11,H13) -> 666.47104 | K13: =J13/I13 -> 0.51288342
B14: T6 | C14: Mục tiêu | D14: ='1.Nội tác linh kiện tòn kho '!Y104 -> 126.38706 | E14: ='2.Nội tác LK thành hình'!X32 -> 89.584065 | F14: ='3.Nội tác LK khuôn dập'!Y94 -> 96.770284 | G14: =SUM(D14:F14) -> 312.7414 | I14: =I12+G14 -> 1612.2005 | J14: =J15 -> 666.47104
B15: T6 | C15: Thực tích | D15: ='1.Nội tác linh kiện tòn kho '!AZ104 -> 0 | E15: ='2.Nội tác LK thành hình'!AY32 -> 0 | F15: ='3.Nội tác LK khuôn dập'!AY94 -> 0 | H15: =SUM(D15:F15) -> 0 | I15: =I14 -> 1612.2005 | J15: =SUM(J13,H15) -> 666.47104 | K15: =J15/I15 -> 0.41339215
B16: T7 | C16: Mục tiêu | D16: ='1.Nội tác linh kiện tòn kho '!Z104 -> 129.32571 | E16: ='2.Nội tác LK thành hình'!Y32 -> 87.443518 | F16: ='3.Nội tác LK khuôn dập'!Z94 -> 94.820759 | G16: =SUM(D16:F16) -> 311.58999 | I16: =I14+G16 -> 1923.7905 | J16: =J17 -> 666.47104
B17: T7 | C17: Thực tích | D17: ='1.Nội tác linh kiện tòn kho '!BB104 -> 0 | E17: ='2.Nội tác LK thành hình'!BA32 -> 0 | F17: ='3.Nội tác LK khuôn dập'!BA94 -> 0 | H17: =SUM(D17:F17) -> 0 | I17: =I16 -> 1923.7905 | J17: =SUM(J15,H17) -> 666.47104 | K17: =J17/I17 -> 0.34643639
B18: T8 | C18: Mục tiêu | D18: ='1.Nội tác linh kiện tòn kho '!AA104 -> 132.44306 | E18: ='2.Nội tác LK thành hình'!Z32 -> 67.112738 | F18: ='3.Nội tác LK khuôn dập'!AA94 -> 108.58043 | G18: =SUM(D18:F18) -> 308.13623 | I18: =I16+G18 -> 2231.9268 | J18: =J19 -> 666.47104
B19: T8 | C19: Thực tích | D19: ='1.Nội tác linh kiện tòn kho '!BD104 -> 0 | E19: ='2.Nội tác LK thành hình'!BC32 -> 0 | F19: ='3.Nội tác LK khuôn dập'!BC94 -> 0 | H19: =SUM(D19:F19) -> 0 | I19: =I18 -> 2231.9268 | J19: =SUM(J17,H19) -> 666.47104 | K19: =J19/I19 -> 0.29860794
B20: T9 | C20: Mục tiêu | D20: ='1.Nội tác linh kiện tòn kho '!AB104 -> 127.89451 | E20: ='2.Nội tác LK thành hình'!AA32 -> 83.321858 | F20: ='3.Nội tác LK khuôn dập'!AB94 -> 108.86241 | G20: =SUM(D20:F20) -> 320.07877 | I20: =I18+G20 -> 2552.0055 | J20: =J21 -> 666.47104
B21: T9 | C21: Thực tích | D21: ='1.Nội tác linh kiện tòn kho '!BF104 -> 0 | E21: ='2.Nội tác LK thành hình'!BE32 -> 0 | F21: ='3.Nội tác LK khuôn dập'!BE94 -> 0 | H21: =SUM(D21:F21) -> 0 | I21: =I20 -> 2552.0055 | J21: =SUM(J19,H21) -> 666.47104 | K21: =J21/I21 -> 0.2611558
B22: T10 | C22: Mục tiêu | D22: ='1.Nội tác linh kiện tòn kho '!AC104 -> 97.888753 | E22: ='2.Nội tác LK thành hình'!AB32 -> 57.545747 | F22: ='3.Nội tác LK khuôn dập'!AC94 -> 132.26186 | G22: =SUM(D22:F22) -> 287.69636 | I22: =I20+G22 -> 2839.7019 | J22: =J23 -> 666.47104
B23: T10 | C23: Thực tích | D23: ='1.Nội tác linh kiện tòn kho '!BH104 -> 0 | E23: ='2.Nội tác LK thành hình'!BG32 -> 0 | F23: ='3.Nội tác LK khuôn dập'!BG94 -> 0 | H23: =SUM(D23:F23) -> 0 | I23: =I22 -> 2839.7019 | J23: =SUM(J21,H23) -> 666.47104 | K23: =J23/I23 -> 0.23469754
B24: T11 | C24: Mục tiêu | D24: ='1.Nội tác linh kiện tòn kho '!AD104 -> 96.873761 | E24: ='2.Nội tác LK thành hình'!AC32 -> 85.297826 | F24: ='3.Nội tác LK khuôn dập'!AD94 -> 93.473997 | G24: =SUM(D24:F24) -> 275.64558 | I24: =I22+G24 -> 3115.3475 | J24: =J25 -> 666.47104
B25: T11 | C25: Thực tích | D25: ='1.Nội tác linh kiện tòn kho '!BJ104 -> 0 | E25: ='2.Nội tác LK thành hình'!BI32 -> 0 | F25: ='3.Nội tác LK khuôn dập'!BI94 -> 0 | H25: =SUM(D25:F25) -> 0 | I25: =I24 -> 3115.3475 | J25: =SUM(J23,H25) -> 666.47104 | K25: =J25/I25 -> 0.21393153
B26: T12 | C26: Mục tiêu | D26: ='1.Nội tác linh kiện tòn kho '!AE104 -> 99.983086 | E26: ='2.Nội tác LK thành hình'!AD32 -> 81.145649 | F26: ='3.Nội tác LK khuôn dập'!AE94 -> 67.994736 | G26: =SUM(D26:F26) -> 249.12347 | I26: =I24+G26 -> 3364.4709 | J26: =J27 -> 666.47104
B27: T12 | C27: Thực tích | D27: ='1.Nội tác linh kiện tòn kho '!BL104 -> 0 | E27: ='2.Nội tác LK thành hình'!BK32 -> 0 | F27: ='3.Nội tác LK khuôn dập'!BK94 -> 0 | H27: =SUM(D27:F27) -> 0 | I27: =I26 -> 3364.4709 | J27: =SUM(J25,H27) -> 666.47104 | K27: =J27/I27 -> 0.19809089
B28: Tổng | D28: =D4+D6+D8+D10+D12+D14+D16+D18+D20+D22+D24+D26 -> 1326.5918 | E28: =E4+E6+E8+E10+E12+E14+E16+E18+E20+E22+E24+E26 -> 926.49792 | F28: =F4+F6+F8+F10+F12+F14+F16+F18+F20+F22+F24+F26 -> 1111.3812 | I28: =D28+E28+F28 -> 3364.4709
D29: =D5+D7+D7+D9+D11+D13+D15+D17+D19+D21+D23+D25+D27 -> 63.032156 | E29: =E5+E7+E9+E11+E13+E15+E17+E19+E21+E23+E25+E27 -> 369.5507 | F29: =F5+F7+F9+F11+F13+F15+F17+F19+F21+F23+F25+F27 -> 233.88819 | I29: =D29+E29+F29 -> 666.47104

Sheet So sánh MT 2025
A1: SO SÁNH MỤC TIÊU 2026 VỚI THỰC TÍCH 2025
B2: 1.Nội tác linh kiện tồn kho | E2: 2.Nội tác LK khuôn thành hình | H2: 3.Nội tác LK khuôn dập | K2: Tổng số Sno | L2: Tổng số pcs | M2: Tổng số tiền (TRIỆU VND)
A3: Hạng mục nội tác | B3: Số Sno | C3: Số Pcs | D3: Số tiền(triệu Vnd) | E3: Số Sno | F3: Số Pcs | G3: Số tiền(triệu Vnd) | H3: Số Sno | I3: Số Pcs | J3: Số tiền(triệu Vnd)
A4: Thực tích 2025 | B4: 102 | C4: 156 | D4: =883670/1000 -> 883.67 | E4: 27 | F4: 108 | G4: =939810/1000 -> 939.81 | H4: 88 | I4: 179 | J4: =1246420/1000 -> 1246.42 | K4: =B4+E4+H4 -> 217 | L4: =C4+F4+I4 -> 443 | M4: =D4+G4+J4 -> 3069.9
A5: Mục tiêu 2026 | B5: ='1.Nội tác linh kiện tòn kho '!A102 -> 98 | C5: ='1.Nội tác linh kiện tòn kho '!D103 -> 230 | D5: ='1.Nội tác linh kiện tòn kho '!AF104 -> 1326.5918 | E5: ='2.Nội tác LK thành hình'!A30 -> 27 | F5: ='2.Nội tác LK thành hình'!P31 -> 54 | G5: ='2.Nội tác LK thành hình'!AE32 -> 926.49792 | H5: ='3.Nội tác LK khuôn dập'!A92 -> 88 | I5: ='3.Nội tác LK khuôn dập'!D93 -> 126 | J5: ='3.Nội tác LK khuôn dập'!AF94 -> 1111.3812 | K5: =B5+E5+H5 -> 213 | L5: =C5+F5+I5 -> 410 | M5: =D5+G5+J5 -> 3364.4709
A6: So sánh | B6: =(B5-B4)/B4 -> -0.039215686 | C6: =(C5-C4)/C4 -> 0.47435897 | D6: =(D5-D4)/D4 -> 0.50122988 | E6: =(E5-E4)/E4 -> 0 | F6: =(F5-F4)/F4 -> -0.5 | G6: =(G5-G4)/G4 -> -0.014164651 | H6: =(H5-H4)/H4 -> 0 | I6: =(I5-I4)/I4 -> -0.29608939 | J6: =(J5-J4)/J4 -> -0.10834131 | K6: =K5/K4-1 -> -0.01843318 | L6: =L5/L4-1 -> -0.074492099 | M6: =M5/M4-1 -> 0.095954573

Sheet 1.Nội tác linh kiện tòn kho 
A2: Stt | B2: S,R no | C2: File PDF | D2: Kế hoạch 2026 (PCS) | E2: Đơn Giá costdown (USD) | F2: Kế hoạch gia công | R2: Tổng | T2: Mục tiêu CostDown từng tháng | AG2: Quản lí tiến độ | AM2: Ghi chú | AO2: Thực tích costdown từng tháng
F3: 1月 | G3: 2月 | H3: 3月 | I3: 4月 | J3: 5月 | K3: 6月 | L3: 7月 | M3: 8月 | N3: 9月 | O3: 10月 | P3: 11月 | Q3: 12月 | T3: 1月 | U3: 2月 | V3: 3月 | W3: 4月 | X3: 5月 | Y3: 6月 | Z3: 7月 | AA3: 8月 | AB3: 9月 | AC3: 10月 | AD3: 11月 | AE3: 12月 | AG3: Số Y/c | AH3: REP | AI3: Số Pcs | AJ3: CĐ H TẠI | AK3: CĐ TIẾP THEO | AL3: KÌ HẠN | AO3: 1月 | AQ3: 2月 | AS3: 3月 | AU3: 4月 | AW3: 5月 | AY3: 6月 | BA3: 7月 | BC3: 8月 | BE3: 9月 | BG3: 10月 | BI3: 11月 | BK3: 12月
AO4: SL | AP4: CD | AQ4: SL | AR4: CD | AS4: SL | AT4: CD | AU4: SL | AV4: CD | AW4: SL | AX4: CD | AY4: SL | AZ4: CD | BA4: SL | BB4: CD | BC4: SL | BD4: CD | BE4: SL | BF4: CD | BG4: SL | BH4: CD | BI4: SL | BJ4: CD | BK4: SL | BL4: CD
A5: 1 | B5: ='[6]NOI TAC 2026'!B7 -> S442628 | C5: =IF(B5="","",HYPERLINK("\\vdm-fsvr\Cokhi-機工\CONG VIEC CHUNG 2026\★2026年度年次目標設定\5.COSTDOWN 2026\5.MỤC TIÊU 2026\COSTDOWN 2026\PDF\"&B5&".pdf","XEM")) -> XEM | D5: ='[6]NOI TAC 2026'!F7 -> 1 | E5: ='[6]NOI TAC 2026'!AL7 -> 16.94784 | G5: 1 | R5: =SUM(F5:Q5) -> 1 | T5: =$E5*F5 -> 0 | U5: =$E5*G5 -> 16.94784 | V5: =$E5*H5 -> 0 | W5: =$E5*I5 -> 0 | X5: =$E5*J5 -> 0 | Y5: =$E5*K5 -> 0 | Z5: =$E5*L5 -> 0 | AA5: =$E5*M5 -> 0 | ... AE5: =$E5*Q5 -> 0 | AG5: #N/A | AH5: #N/A | AI5: #N/A | AJ5: #N/A | AK5: #N/A | AL5: #N/A | AP5: =AO5*E5 -> 0 | AR5: =AQ5*E5 -> 0 | AT5: =AS5*E5 -> 0 | AV5: =AU5*E5 -> 0 | AX5: =AW5*E5 -> 0 | AZ5: =AY5*E5 -> 0 | BB5: =BA5*E5 -> 0 | BD5: =BC5*E5 -> 0 | BF5: =BE5*E5 -> 0 | BH5: =BG5*E5 -> 0 | BJ5: =BI5*E5 -> 0 | BL5: =BK5*E5 -> 0
A6: 2 | B6: ='[6]NOI TAC 2026'!B8 -> S785023 | C6: =IF(B6="","",HYPERLINK("\\vdm-fsvr\Cokhi-機工\CONG VIEC CHUNG 2026\★2026年度年次目標設定\5.COSTDOWN 2026\5.MỤC TIÊU 2026\COSTDOWN 2026\PDF\"&B6&".pdf","XEM")) -> XEM | D6: ='[6]NOI TAC 2026'!F8 -> 1 | E6: ='[6]NOI TAC 2026'!AL8 -> 8.53264 | H6: 1 | R6: =SUM(F6:Q6) -> 1 | T6: =$E6*F6 -> 0 | U6: =$E6*G6 -> 0 | V6: =$E6*H6 -> 8.53264 | W6: =$E6*I6 -> 0 | X6: =$E6*J6 -> 0 | Y6: =$E6*K6 -> 0 | Z6: =$E6*L6 -> 0 | AA6: =$E6*M6 -> 0 | ... AE6: =$E6*Q6 -> 0 | AG6: #N/A | AH6: #N/A | AI6: #N/A | AJ6: #N/A | AK6: #N/A | AL6: #N/A | AP6: =AO6*E6 -> 0 | AR6: =AQ6*E6 -> 0 | AT6: =AS6*E6 -> 0 | AV6: =AU6*E6 -> 0 | AX6: =AW6*E6 -> 0 | AZ6: =AY6*E6 -> 0 | BB6: =BA6*E6 -> 0 | BD6: =BC6*E6 -> 0 | BF6: =BE6*E6 -> 0 | BH6: =BG6*E6 -> 0 | BJ6: =BI6*E6 -> 0 | BL6: =BK6*E6 -> 0
A7: 3 | B7: ='[6]NOI TAC 2026'!B9 -> S012373 | C7: =IF(B7="","",HYPERLINK("\\vdm-fsvr\Cokhi-機工\CONG VIEC CHUNG 2026\★2026年度年次目標設定\5.COSTDOWN 2026\5.MỤC TIÊU 2026\COSTDOWN 2026\PDF\"&B7&".pdf","XEM")) -> XEM | D7: ='[6]NOI TAC 2026'!F9 -> 1 | E7: ='[6]NOI TAC 2026'!AL9 -> 21.99784 | I7: 1 | R7: =SUM(F7:Q7) -> 1 | T7: =$E7*F7 -> 0 | U7: =$E7*G7 -> 0 | V7: =$E7*H7 -> 0 | W7: =$E7*I7 -> 21.99784 | X7: =$E7*J7 -> 0 | Y7: =$E7*K7 -> 0 | Z7: =$E7*L7 -> 0 | AA7: =$E7*M7 -> 0 | ... AE7: =$E7*Q7 -> 0 | AG7: #N/A | AH7: #N/A | AI7: #N/A | AJ7: #N/A | AK7: #N/A | AL7: #N/A | AP7: =AO7*E7 -> 0 | AR7: =AQ7*E7 -> 0 | AT7: =AS7*E7 -> 0 | AV7: =AU7*E7 -> 0 | AX7: =AW7*E7 -> 0 | AZ7: =AY7*E7 -> 0 | BB7: =BA7*E7 -> 0 | BD7: =BC7*E7 -> 0 | BF7: =BE7*E7 -> 0 | BH7: =BG7*E7 -> 0 | BJ7: =BI7*E7 -> 0 | BL7: =BK7*E7 -> 0
A8: 4 | B8: ='[6]NOI TAC 2026'!B10 -> S030900 | C8: =IF(B8="","",HYPERLINK("\\vdm-fsvr\Cokhi-機工\CONG VIEC CHUNG 2026\★2026年度年次目標設定\5.COSTDOWN 2026\5.MỤC TIÊU 2026\COSTDOWN 2026\PDF\"&B8&".pdf","XEM")) -> XEM | D8: ='[6]NOI TAC 2026'!F10 -> 1 | E8: ='[6]NOI TAC 2026'!AL10 -> 21.99784 | J8: 1 | R8: =SUM(F8:Q8) -> 1 | T8: =$E8*F8 -> 0 | U8: =$E8*G8 -> 0 | V8: =$E8*H8 -> 0 | W8: =$E8*I8 -> 0 | X8: =$E8*J8 -> 21.99784 | Y8: =$E8*K8 -> 0 | Z8: =$E8*L8 -> 0 | AA8: =$E8*M8 -> 0 | ... AE8: =$E8*Q8 -> 0 | AG8: #N/A | AH8: #N/A | AI8: #N/A | AJ8: #N/A | AK8: #N/A | AL8: #N/A | AP8: =AO8*E8 -> 0 | AR8: =AQ8*E8 -> 0 | AT8: =AS8*E8 -> 0 | AV8: =AU8*E8 -> 0 | AX8: =AW8*E8 -> 0 | AZ8: =AY8*E8 -> 0 | BB8: =BA8*E8 -> 0 | BD8: =BC8*E8 -> 0 | BF8: =BE8*E8 -> 0 | BH8: =BG8*E8 -> 0 | BJ8: =BI8*E8 -> 0 | BL8: =BK8*E8 -> 0
A9: 5 | B9: ='[6]NOI TAC 2026'!B11 -> S030909 | C9: =IF(B9="","",HYPERLINK("\\vdm-fsvr\Cokhi-機工\CONG VIEC CHUNG 2026\★2026年度年次目標設定\5.COSTDOWN 2026\5.MỤC TIÊU 2026\COSTDOWN 2026\PDF\"&B9&".pdf","XEM")) -> XEM | D9: ='[6]NOI TAC 2026'!F11 -> 1 | E9: ='[6]NOI TAC 2026'!AL11 -> 22.37784 | K9: 1 | R9: =SUM(F9:Q9) -> 1 | T9: =$E9*F9 -> 0 | U9: =$E9*G9 -> 0 | V9: =$E9*H9 -> 0 | W9: =$E9*I9 -> 0 | X9: =$E9*J9 -> 0 | Y9: =$E9*K9 -> 22.37784 | Z9: =$E9*L9 -> 0 | AA9: =$E9*M9 -> 0 | ... AE9: =$E9*Q9 -> 0 | AG9: #N/A | AH9: #N/A | AI9: #N/A | AJ9: #N/A | AK9: #N/A | AL9: #N/A | AP9: =AO9*E9 -> 0 | AR9: =AQ9*E9 -> 0 | AT9: =AS9*E9 -> 0 | AV9: =AU9*E9 -> 0 | AX9: =AW9*E9 -> 0 | AZ9: =AY9*E9 -> 0 | BB9: =BA9*E9 -> 0 | BD9: =BC9*E9 -> 0 | BF9: =BE9*E9 -> 0 | BH9: =BG9*E9 -> 0 | BJ9: =BI9*E9 -> 0 | BL9: =BK9*E9 -> 0
A10: 6 | B10: ='[6]NOI TAC 2026'!B12 -> R061193 | C10: =IF(B10="","",HYPERLINK("\\vdm-fsvr\Cokhi-機工\CONG VIEC CHUNG 2026\★2026年度年次目標設定\5.COSTDOWN 2026\5.MỤC TIÊU 2026\COSTDOWN 2026\PDF\"&B10&".pdf","XEM")) -> XEM | D10: ='[6]NOI TAC 2026'!F12 -> 3 | E10: ='[6]NOI TAC 2026'!AL12 -> 17.10184 | G10: 1 | L10: 1 | P10: 1 | R10: =SUM(F10:Q10) -> 3 | T10: =$E10*F10 -> 0 | U10: =$E10*G10 -> 17.10184 | V10: =$E10*H10 -> 0 | W10: =$E10*I10 -> 0 | X10: =$E10*J10 -> 0 | Y10: =$E10*K10 -> 0 | Z10: =$E10*L10 -> 17.10184 | AA10: =$E10*M10 -> 0 | ... AE10: =$E10*Q10 -> 0 | AG10: #N/A | AH10: #N/A | AI10: #N/A | AJ10: #N/A | AK10: #N/A | AL10: #N/A | AP10: =AO10*E10 -> 0 | AR10: =AQ10*E10 -> 0 | AT10: =AS10*E10 -> 0 | AV10: =AU10*E10 -> 0 | AX10: =AW10*E10 -> 0 | AZ10: =AY10*E10 -> 0 | BB10: =BA10*E10 -> 0 | BD10: =BC10*E10 -> 0 | BF10: =BE10*E10 -> 0 | BH10: =BG10*E10 -> 0 | BJ10: =BI10*E10 -> 0 | BL10: =BK10*E10 -> 0
A11: 7 | B11: ='[6]NOI TAC 2026'!B13 -> S063800 | C11: =IF(B11="","",HYPERLINK("\\vdm-fsvr\Cokhi-機工\CONG VIEC CHUNG 2026\★2026年度年次目標設定\5.COSTDOWN 2026\5.MỤC TIÊU 2026\COSTDOWN 2026\PDF\"&B11&".pdf","XEM")) -> XEM | D11: ='[6]NOI TAC 2026'!F13 -> 1 | E11: ='[6]NOI TAC 2026'!AL13 -> 25.157623 | H11: 1 | R11: =SUM(F11:Q11) -> 1 | T11: =$E11*F11 -> 0 | U11: =$E11*G11 -> 0 | V11: =$E11*H11 -> 25.157623 | W11: =$E11*I11 -> 0 | X11: =$E11*J11 -> 0 | Y11: =$E11*K11 -> 0 | Z11: =$E11*L11 -> 0 | AA11: =$E11*M11 -> 0 | ... AE11: =$E11*Q11 -> 0 | AG11: #N/A | AH11: #N/A | AI11: #N/A | AJ11: #N/A | AK11: #N/A | AL11: #N/A | AP11: =AO11*E11 -> 0 | AR11: =AQ11*E11 -> 0 | AT11: =AS11*E11 -> 0 | AV11: =AU11*E11 -> 0 | AX11: =AW11*E11 -> 0 | AZ11: =AY11*E11 -> 0 | BB11: =BA11*E11 -> 0 | BD11: =BC11*E11 -> 0 | BF11: =BE11*E11 -> 0 | BH11: =BG11*E11 -> 0 | BJ11: =BI11*E11 -> 0 | BL11: =BK11*E11 -> 0
A12: 8 | B12: ='[6]NOI TAC 2026'!B14 -> S763490 | C12: =IF(B12="","",HYPERLINK("\\vdm-fsvr\Cokhi-機工\CONG VIEC CHUNG 2026\★2026年度年次目標設定\5.COSTDOWN 2026\5.MỤC TIÊU 2026\COSTDOWN 2026\PDF\"&B12&".pdf","XEM")) -> XEM | D12: ='[6]NOI TAC 2026'!F14 -> 3 | E12: ='[6]NOI TAC 2026'!AL14 -> 29.81264 | I12: 1 | M12: 1 | Q12: 1 | R12: =SUM(F12:Q12) -> 3 | T12: =$E12*F12 -> 0 | U12: =$E12*G12 -> 0 | V12: =$E12*H12 -> 0 | W12: =$E12*I12 -> 29.81264 | X12: =$E12*J12 -> 0 | Y12: =$E12*K12 -> 0 | Z12: =$E12*L12 -> 0 | AA12: =$E12*M12 -> 29.81264 | ... AE12: =$E12*Q12 -> 29.81264 | AG12: #N/A | AH12: #N/A | AI12: #N/A | AJ12: #N/A | AK12: #N/A | AL12: #N/A | AP12: =AO12*E12 -> 0 | AR12: =AQ12*E12 -> 0 | AT12: =AS12*E12 -> 0 | AV12: =AU12*E12 -> 0 | AX12: =AW12*E12 -> 0 | AZ12: =AY12*E12 -> 0 | BB12: =BA12*E12 -> 0 | BD12: =BC12*E12 -> 0 | BF12: =BE12*E12 -> 0 | BH12: =BG12*E12 -> 0 | BJ12: =BI12*E12 -> 0 | BL12: =BK12*E12 -> 0
A13: 9 | B13: ='[6]NOI TAC 2026'!B15 -> S763484 | C13: =IF(B13="","",HYPERLINK("\\vdm-fsvr\Cokhi-機工\CONG VIEC CHUNG 2026\★2026年度年次目標設定\5.COSTDOWN 2026\5.MỤC TIÊU 2026\COSTDOWN 2026\PDF\"&B13&".pdf","XEM")) -> XEM | D13: ='[6]NOI TAC 2026'!F15 -> 1 | E13: ='[6]NOI TAC 2026'!AL15 -> 31.33264 | J13: 1 | R13: =SUM(F13:Q13) -> 1 | T13: =$E13*F13 -> 0 | U13: =$E13*G13 -> 0 | V13: =$E13*H13 -> 0 | W13: =$E13*I13 -> 0 | X13: =$E13*J13 -> 31.33264 | Y13: =$E13*K13 -> 0 | Z13: =$E13*L13 -> 0 | AA13: =$E13*M13 -> 0 | ... AE13: =$E13*Q13 -> 0 | AG13: #N/A | AH13: #N/A | AI13: #N/A | AJ13: #N/A | AK13: #N/A | AL13: #N/A | AP13: =AO13*E13 -> 0 | AR13: =AQ13*E13 -> 0 | AT13: =AS13*E13 -> 0 | AV13: =AU13*E13 -> 0 | AX13: =AW13*E13 -> 0 | AZ13: =AY13*E13 -> 0 | BB13: =BA13*E13 -> 0 | BD13: =BC13*E13 -> 0 | BF13: =BE13*E13 -> 0 | BH13: =BG13*E13 -> 0 | BJ13: =BI13*E13 -> 0 | BL13: =BK13*E13 -> 0
A14: 10 | B14: ='[6]NOI TAC 2026'!B16 -> S013300 | C14: =IF(B14="","",HYPERLINK("\\vdm-fsvr\Cokhi-機工\CONG VIEC CHUNG 2026\★2026年度年次目標設定\5.COSTDOWN 2026\5.MỤC TIÊU 2026\COSTDOWN 2026\PDF\"&B14&".pdf","XEM")) -> XEM | D14: ='[6]NOI TAC 2026'!F16 -> 1 | E14: ='[6]NOI TAC 2026'!AL16 -> 36.668 | K14: 1 | R14: =SUM(F14:Q14) -> 1 | T14: =$E14*F14 -> 0 | U14: =$E14*G14 -> 0 | V14: =$E14*H14 -> 0 | W14: =$E14*I14 -> 0 | X14: =$E14*J14 -> 0 | Y14: =$E14*K14 -> 36.668 | Z14: =$E14*L14 -> 0 | AA14: =$E14*M14 -> 0 | ... AE14: =$E14*Q14 -> 0 | AG14: #N/A | AH14: #N/A | AI14: #N/A | AJ14: #N/A | AK14: #N/A | AL14: #N/A | AP14: =AO14*E14 -> 0 | AR14: =AQ14*E14 -> 0 | AT14: =AS14*E14 -> 0 | AV14: =AU14*E14 -> 0 | AX14: =AW14*E14 -> 0 | AZ14: =AY14*E14 -> 0 | BB14: =BA14*E14 -> 0 | BD14: =BC14*E14 -> 0 | BF14: =BE14*E14 -> 0 | BH14: =BG14*E14 -> 0 | BJ14: =BI14*E14 -> 0 | BL14: =BK14*E14 -> 0
A15: 11 | B15: ='[6]NOI TAC 2026'!B17 -> S417746 | C15: =IF(B15="","",HYPERLINK("\\vdm-fsvr\Cokhi-機工\CONG VIEC CHUNG 2026\★2026年度年次目標設定\5.COSTDOWN 2026\5.MỤC TIÊU 2026\COSTDOWN 2026\PDF\"&B15&".pdf","XEM")) -> XEM | D15: ='[6]NOI TAC 2026'!F17 -> 1 | E15: ='[6]NOI TAC 2026'!AL17 -> 52.85168 | L15: 1 | R15: =SUM(F15:Q15) -> 1 | T15: =$E15*F15 -> 0 | U15: =$E15*G15 -> 0 | V15: =$E15*H15 -> 0 | W15: =$E15*I15 -> 0 | X15: =$E15*J15 -> 0 | Y15: =$E15*K15 -> 0 | Z15: =$E15*L15 -> 52.85168 | AA15: =$E15*M15 -> 0 | ... AE15: =$E15*Q15 -> 0 | AG15: #N/A | AH15: #N/A | AI15: #N/A | AJ15: #N/A | AK15: #N/A | AL15: #N/A | AP15: =AO15*E15 -> 0 | AR15: =AQ15*E15 -> 0 | AT15: =AS15*E15 -> 0 | AV15: =AU15*E15 -> 0 | AX15: =AW15*E15 -> 0 | AZ15: =AY15*E15 -> 0 | BB15: =BA15*E15 -> 0 | BD15: =BC15*E15 -> 0 | BF15: =BE15*E15 -> 0 | BH15: =BG15*E15 -> 0 | BJ15: =BI15*E15 -> 0 | BL15: =BK15*E15 -> 0
A16: 12 | B16: ='[6]NOI TAC 2026'!B18 -> S417748 | C16: =IF(B16="","",HYPERLINK("\\vdm-fsvr\Cokhi-機工\CONG VIEC CHUNG 2026\★2026年度年次目標設定\5.COSTDOWN 2026\5.MỤC TIÊU 2026\COSTDOWN 2026\PDF\"&B16&".pdf","XEM")) -> XEM | D16: ='[6]NOI TAC 2026'!F18 -> 1 | E16: ='[6]NOI TAC 2026'!AL18 -> 54.57168 | M16: 1 | R16: =SUM(F16:Q16) -> 1 | T16: =$E16*F16 -> 0 | U16: =$E16*G16 -> 0 | V16: =$E16*H16 -> 0 | W16: =$E16*I16 -> 0 | X16: =$E16*J16 -> 0 | Y16: =$E16*K16 -> 0 | Z16: =$E16*L16 -> 0 | AA16: =$E16*M16 -> 54.57168 | ... AE16: =$E16*Q16 -> 0 | AG16: #N/A | AH16: #N/A | AI16: #N/A | AJ16: #N/A | AK16: #N/A | AL16: #N/A | AP16: =AO16*E16 -> 0 | AR16: =AQ16*E16 -> 0 | AT16: =AS16*E16 -> 0 | AV16: =AU16*E16 -> 0 | AX16: =AW16*E16 -> 0 | AZ16: =AY16*E16 -> 0 | BB16: =BA16*E16 -> 0 | BD16: =BC16*E16 -> 0 | BF16: =BE16*E16 -> 0 | BH16: =BG16*E16 -> 0 | BJ16: =BI16*E16 -> 0 | BL16: =BK16*E16 -> 0
A17: 13 | B17: ='[6]NOI TAC 2026'!B19 -> R062214 | C17: =IF(B17="","",HYPERLINK("\\vdm-fsvr\Cokhi-機工\CONG VIEC CHUNG 2026\★2026年度年次目標設定\5.COSTDOWN 2026\5.MỤC TIÊU 2026\COSTDOWN 2026\PDF\"&B17&".pdf","XEM")) -> XEM | D17: ='[6]NOI TAC 2026'!F19 -> 1 | E17: ='[6]NOI TAC 2026'!AL19 -> 55.55364 | N17: 1 | R17: =SUM(F17:Q17) -> 1 | T17: =$E17*F17 -> 0 | U17: =$E17*G17 -> 0 | V17: =$E17*H17 -> 0 | W17: =$E17*I17 -> 0 | X17: =$E17*J17 -> 0 | Y17: =$E17*K17 -> 0 | Z17: =$E17*L17 -> 0 | AA17: =$E17*M17 -> 0 | ... AE17: =$E17*Q17 -> 0 | AG17: #N/A | AH17: #N/A | AI17: #N/A | AJ17: #N/A | AK17: #N/A | AL17: #N/A | AP17: =AO17*E17 -> 0 | AR17: =AQ17*E17 -> 0 | AT17: =AS17*E17 -> 0 | AV17: =AU17*E17 -> 0 | AX17: =AW17*E17 -> 0 | AZ17: =AY17*E17 -> 0 | BB17: =BA17*E17 -> 0 | BD17: =BC17*E17 -> 0 | BF17: =BE17*E17 -> 0 | BH17: =BG17*E17 -> 0 | BJ17: =BI17*E17 -> 0 | BL17: =BK17*E17 -> 0
A18: 14 | B18: ='[6]NOI TAC 2026'!B20 -> R062217 | C18: =IF(B18="","",HYPERLINK("\\vdm-fsvr\Cokhi-機工\CONG VIEC CHUNG 2026\★2026年度年次目標設定\5.COSTDOWN 2026\5.MỤC TIÊU 2026\COSTDOWN 2026\PDF\"&B18&".pdf","XEM")) -> XEM | D18: ='[6]NOI TAC 2026'!F20 -> 1 | E18: ='[6]NOI TAC 2026'!AL20 -> 72.7042 | O18: 1 | R18: =SUM(F18:Q18) -> 1 | T18: =$E18*F18 -> 0 | U18: =$E18*G18 -> 0 | V18: =$E18*H18 -> 0 | W18: =$E18*I18 -> 0 | X18: =$E18*J18 -> 0 | Y18: =$E18*K18 -> 0 | Z18: =$E18*L18 -> 0 | AA18: =$E18*M18 -> 0 | ... AE18: =$E18*Q18 -> 0 | AG18: #N/A | AH18: #N/A | AI18: #N/A | AJ18: #N/A | AK18: #N/A | AL18: #N/A | AP18: =AO18*E18 -> 0 | AR18: =AQ18*E18 -> 0 | AT18: =AS18*E18 -> 0 | AV18: =AU18*E18 -> 0 | AX18: =AW18*E18 -> 0 | AZ18: =AY18*E18 -> 0 | BB18: =BA18*E18 -> 0 | BD18: =BC18*E18 -> 0 | BF18: =BE18*E18 -> 0 | BH18: =BG18*E18 -> 0 | BJ18: =BI18*E18 -> 0 | BL18: =BK18*E18 -> 0
A19: 15 | B19: ='[6]NOI TAC 2026'!B21 -> R369692 | C19: =IF(B19="","",HYPERLINK("\\vdm-fsvr\Cokhi-機工\CONG VIEC CHUNG 2026\★2026年度年次目標設定\5.COSTDOWN 2026\5.MỤC TIÊU 2026\COSTDOWN 2026\PDF\"&B19&".pdf","XEM")) -> XEM | D19: ='[6]NOI TAC 2026'!F21 -> 1 | E19: ='[6]NOI TAC 2026'!AL21 -> 54.75312 | P19: 1 | R19: =SUM(F19:Q19) -> 1 | T19: =$E19*F19 -> 0 | U19: =$E19*G19 -> 0 | V19: =$E19*H19 -> 0 | W19: =$E19*I19 -> 0 | X19: =$E19*J19 -> 0 | Y19: =$E19*K19 -> 0 | Z19: =$E19*L19 -> 0 | AA19: =$E19*M19 -> 0 | ... AE19: =$E19*Q19 -> 0 | AG19: #N/A | AH19: #N/A | AI19: #N/A | AJ19: #N/A | AK19: #N/A | AL19: #N/A | AP19: =AO19*E19 -> 0 | AR19: =AQ19*E19 -> 0 | AT19: =AS19*E19 -> 0 | AV19: =AU19*E19 -> 0 | AX19: =AW19*E19 -> 0 | AZ19: =AY19*E19 -> 0 | BB19: =BA19*E19 -> 0 | BD19: =BC19*E19 -> 0 | BF19: =BE19*E19 -> 0 | BH19: =BG19*E19 -> 0 | BJ19: =BI19*E19 -> 0 | BL19: =BK19*E19 -> 0
A20: 16 | B20: ='[6]NOI TAC 2026'!B22 -> R337601 | C20: =IF(B20="","",HYPERLINK("\\vdm-fsvr\Cokhi-機工\CONG VIEC CHUNG 2026\★2026年度年次目標設定\5.COSTDOWN 2026\5.MỤC TIÊU 2026\COSTDOWN 2026\PDF\"&B20&".pdf","XEM")) -> XEM | D20: ='[6]NOI TAC 2026'!F22 -> 1 | E20: ='[6]NOI TAC 2026'!AL22 -> 86.26428 | Q20: 1 | R20: =SUM(F20:Q20) -> 1 | T20: =$E20*F20 -> 0 | U20: =$E20*G20 -> 0 | V20: =$E20*H20 -> 0 | W20: =$E20*I20 -> 0 | X20: =$E20*J20 -> 0 | Y20: =$E20*K20 -> 0 | Z20: =$E20*L20 -> 0 | AA20: =$E20*M20 -> 0 | ... AE20: =$E20*Q20 -> 86.26428 | AG20: #N/A | AH20: #N/A | AI20: #N/A | AJ20: #N/A | AK20: #N/A | AL20: #N/A | AP20: =AO20*E20 -> 0 | AR20: =AQ20*E20 -> 0 | AT20: =AS20*E20 -> 0 | AV20: =AU20*E20 -> 0 | AX20: =AW20*E20 -> 0 | AZ20: =AY20*E20 -> 0 | BB20: =BA20*E20 -> 0 | BD20: =BC20*E20 -> 0 | BF20: =BE20*E20 -> 0 | BH20: =BG20*E20 -> 0 | BJ20: =BI20*E20 -> 0 | BL20: =BK20*E20 -> 0
A21: 17 | B21: ='[6]NOI TAC 2026'!B23 -> R009210 | C21: =IF(B21="","",HYPERLINK("\\vdm-fsvr\Cokhi-機工\CONG VIEC CHUNG 2026\★2026年度年次目標設定\5.COSTDOWN 2026\5.MỤC TIÊU 2026\COSTDOWN 2026\PDF\"&B21&".pdf","XEM")) -> XEM | D21: ='[6]NOI TAC 2026'!F23 -> 1 | E21: ='[6]NOI TAC 2026'!AL23 -> 137.97264 | F21: 1 | R21: =SUM(F21:Q21) -> 1 | T21: =$E21*F21 -> 137.97264 | U21: =$E21*G21 -> 0 | V21: =$E21*H21 -> 0 | W21: =$E21*I21 -> 0 | X21: =$E21*J21 -> 0 | Y21: =$E21*K21 -> 0 | Z21: =$E21*L21 -> 0 | AA21: =$E21*M21 -> 0 | ... AE21: =$E21*Q21 -> 0 | AG21: #N/A | AH21: #N/A | AI21: #N/A | AJ21: #N/A | AK21: #N/A | AL21: #N/A | AP21: =AO21*E21 -> 0 | AR21: =AQ21*E21 -> 0 | AT21: =AS21*E21 -> 0 | AV21: =AU21*E21 -> 0 | AX21: =AW21*E21 -> 0 | AZ21: =AY21*E21 -> 0 | BB21: =BA21*E21 -> 0 | BD21: =BC21*E21 -> 0 | BF21: =BE21*E21 -> 0 | BH21: =BG21*E21 -> 0 | BJ21: =BI21*E21 -> 0 | BL21: =BK21*E21 -> 0
A22: 18 | B22: ='[6]NOI TAC 2026'!B24 -> S210886 | C22: =IF(B22="","",HYPERLINK("\\vdm-fsvr\Cokhi-機工\CONG VIEC CHUNG 2026\★2026年度年次目標設定\5.COSTDOWN 2026\5.MỤC TIÊU 2026\COSTDOWN 2026\PDF\"&B22&".pdf","XEM")) -> XEM | D22: ='[6]NOI TAC 2026'!F24 -> 1 | E22: ='[6]NOI TAC 2026'!AL24 -> 126.60041 | H22: 1 | R22: =SUM(F22:Q22) -> 1 | T22: =$E22*F22 -> 0 | U22: =$E22*G22 -> 0 | V22: =$E22*H22 -> 126.60041 | W22: =$E22*I22 -> 0 | X22: =$E22*J22 -> 0 | Y22: =$E22*K22 -> 0 | Z22: =$E22*L22 -> 0 | AA22: =$E22*M22 -> 0 | ... AE22: =$E22*Q22 -> 0 | AG22: #N/A | AH22: #N/A | AI22: #N/A | AJ22: #N/A | AK22: #N/A | AL22: #N/A | AP22: =AO22*E22 -> 0 | AR22: =AQ22*E22 -> 0 | AT22: =AS22*E22 -> 0 | AV22: =AU22*E22 -> 0 | AX22: =AW22*E22 -> 0 | AZ22: =AY22*E22 -> 0 | BB22: =BA22*E22 -> 0 | BD22: =BC22*E22 -> 0 | BF22: =BE22*E22 -> 0 | BH22: =BG22*E22 -> 0 | BJ22: =BI22*E22 -> 0 | BL22: =BK22*E22 -> 0
A23: 19 | B23: ='[6]NOI TAC 2026'!B25 -> R061781 | C23: =IF(B23="","",HYPERLINK("\\vdm-fsvr\Cokhi-機工\CONG VIEC CHUNG 2026\★2026年度年次目標設定\5.COSTDOWN 2026\5.MỤC TIÊU 2026\COSTDOWN 2026\PDF\"&B23&".pdf","XEM")) -> XEM | D23: ='[6]NOI TAC 2026'!F25 -> 1 | E23: ='[6]NOI TAC 2026'!AL25 -> 166.59896 | I23: 1 | R23: =SUM(F23:Q23) -> 1 | T23: =$E23*F23 -> 0 | U23: =$E23*G23 -> 0 | V23: =$E23*H23 -> 0 | W23: =$E23*I23 -> 166.59896 | X23: =$E23*J23 -> 0 | Y23: =$E23*K23 -> 0 | Z23: =$E23*L23 -> 0 | AA23: =$E23*M23 -> 0 | ... AE23: =$E23*Q23 -> 0 | AG23: #N/A | AH23: #N/A | AI23: #N/A | AJ23: #N/A | AK23: #N/A | AL23: #N/A | AP23: =AO23*E23 -> 0 | AR23: =AQ23*E23 -> 0 | AT23: =AS23*E23 -> 0 | AV23: =AU23*E23 -> 0 | AX23: =AW23*E23 -> 0 | AZ23: =AY23*E23 -> 0 | BB23: =BA23*E23 -> 0 | BD23: =BC23*E23 -> 0 | BF23: =BE23*E23 -> 0 | BH23: =BG23*E23 -> 0 | BJ23: =BI23*E23 -> 0 | BL23: =BK23*E23 -> 0
A24: 20 | B24: ='[6]NOI TAC 2026'!B26 -> R021019 | C24: =IF(B24="","",HYPERLINK("\\vdm-fsvr\Cokhi-機工\CONG VIEC CHUNG 2026\★2026年度年次目標設定\5.COSTDOWN 2026\5.MỤC TIÊU 2026\COSTDOWN 2026\PDF\"&B24&".pdf","XEM")) -> XEM | D24: ='[6]NOI TAC 2026'!F26 -> 5 | E24: ='[6]NOI TAC 2026'!AL26 -> 137.7042 | G24: 1 | J24: 1 | M24: 1 | O24: 1 | Q24: 1 | R24: =SUM(F24:Q24) -> 5 | T24: =$E24*F24 -> 0 | U24: =$E24*G24 -> 137.7042 | V24: =$E24*H24 -> 0 | W24: =$E24*I24 -> 0 | X24: =$E24*J24 -> 137.7042 | Y24: =$E24*K24 -> 0 | Z24: =$E24*L24 -> 0 | AA24: =$E24*M24 -> 137.7042 | ... AE24: =$E24*Q24 -> 137.7042 | AG24: #N/A | AH24: #N/A | AI24: #N/A | AJ24: #N/A | AK24: #N/A | AL24: #N/A | AP24: =AO24*E24 -> 0 | AR24: =AQ24*E24 -> 0 | AT24: =AS24*E24 -> 0 | AV24: =AU24*E24 -> 0 | AX24: =AW24*E24 -> 0 | AZ24: =AY24*E24 -> 0 | BB24: =BA24*E24 -> 0 | BD24: =BC24*E24 -> 0 | BF24: =BE24*E24 -> 0 | BH24: =BG24*E24 -> 0 | BJ24: =BI24*E24 -> 0 | BL24: =BK24*E24 -> 0
A25: 21 | B25: ='[6]NOI TAC 2026'!B27 -> R029254 | C25: =IF(B25="","",HYPERLINK("\\vdm-fsvr\Cokhi-機工\CONG VIEC CHUNG 2026\★2026年度年次目標設定\5.COSTDOWN 2026\5.MỤC TIÊU 2026\COSTDOWN 2026\PDF\"&B25&".pdf","XEM")) -> XEM | D25: ='[6]NOI TAC 2026'!F27 -> 1 | E25: ='[6]NOI TAC 2026'!AL27 -> 277.4854 | H25: 1 | R25: =SUM(F25:Q25) -> 1 | T25: =$E25*F25 -> 0 | U25: =$E25*G25 -> 0 | V25: =$E25*H25 -> 277.4854 | W25: =$E25*I25 -> 0 | X25: =$E25*J25 -> 0 | Y25: =$E25*K25 -> 0 | Z25: =$E25*L25 -> 0 | AA25: =$E25*M25 -> 0 | ... AE25: =$E25*Q25 -> 0 | AG25: #N/A | AH25: #N/A | AI25: #N/A | AJ25: #N/A | AK25: #N/A | AL25: #N/A | AP25: =AO25*E25 -> 0 | AR25: =AQ25*E25 -> 0 | AT25: =AS25*E25 -> 0 | AV25: =AU25*E25 -> 0 | AX25: =AW25*E25 -> 0 | AZ25: =AY25*E25 -> 0 | BB25: =BA25*E25 -> 0 | BD25: =BC25*E25 -> 0 | BF25: =BE25*E25 -> 0 | BH25: =BG25*E25 -> 0 | BJ25: =BI25*E25 -> 0 | BL25: =BK25*E25 -> 0
A26: 22 | B26: ='[6]NOI TAC 2026'!B28 -> S919918 | C26: =IF(B26="","",HYPERLINK("\\vdm-fsvr\Cokhi-機工\CONG VIEC CHUNG 2026\★2026年度年次目標設定\5.COSTDOWN 2026\5.MỤC TIÊU 2026\COSTDOWN 2026\PDF\"&B26&".pdf","XEM")) -> XEM | D26: ='[6]NOI TAC 2026'!F28 -> 1 | E26: ='[6]NOI TAC 2026'!AL28 -> 340.1528 | I26: 1 | R26: =SUM(F26:Q26) -> 1 | T26: =$E26*F26 -> 0 | U26: =$E26*G26 -> 0 | V26: =$E26*H26 -> 0 | W26: =$E26*I26 -> 340.1528 | X26: =$E26*J26 -> 0 | Y26: =$E26*K26 -> 0 | Z26: =$E26*L26 -> 0 | AA26: =$E26*M26 -> 0 | ... AE26: =$E26*Q26 -> 0 | AG26: #N/A | AH26: #N/A | AI26: #N/A | AJ26: #N/A | AK26: #N/A | AL26: #N/A | AP26: =AO26*E26 -> 0 | AR26: =AQ26*E26 -> 0 | AT26: =AS26*E26 -> 0 | AV26: =AU26*E26 -> 0 | AX26: =AW26*E26 -> 0 | AZ26: =AY26*E26 -> 0 | BB26: =BA26*E26 -> 0 | BD26: =BC26*E26 -> 0 | BF26: =BE26*E26 -> 0 | BH26: =BG26*E26 -> 0 | BJ26: =BI26*E26 -> 0 | BL26: =BK26*E26 -> 0
A27: 23 | B27: ='[6]NOI TAC 2026'!B29 -> S814330 | C27: =IF(B27="","",HYPERLINK("\\vdm-fsvr\Cokhi-機工\CONG VIEC CHUNG 2026\★2026年度年次目標設定\5.COSTDOWN 2026\5.MỤC TIÊU 2026\COSTDOWN 2026\PDF\"&B27&".pdf","XEM")) -> XEM | D27: ='[6]NOI TAC 2026'!F29 -> 1 | E27: ='[6]NOI TAC 2026'!AL29 -> 388.68712 | J27: 1 | R27: =SUM(F27:Q27) -> 1 | T27: =$E27*F27 -> 0 | U27: =$E27*G27 -> 0 | V27: =$E27*H27 -> 0 | W27: =$E27*I27 -> 0 | X27: =$E27*J27 -> 388.68712 | Y27: =$E27*K27 -> 0 | Z27: =$E27*L27 -> 0 | AA27: =$E27*M27 -> 0 | ... AE27: =$E27*Q27 -> 0 | AG27: #N/A | AH27: #N/A | AI27: #N/A | AJ27: #N/A | AK27: #N/A | AL27: #N/A | AP27: =AO27*E27 -> 0 | AR27: =AQ27*E27 -> 0 | AT27: =AS27*E27 -> 0 | AV27: =AU27*E27 -> 0 | AX27: =AW27*E27 -> 0 | AZ27: =AY27*E27 -> 0 | BB27: =BA27*E27 -> 0 | BD27: =BC27*E27 -> 0 | BF27: =BE27*E27 -> 0 | BH27: =BG27*E27 -> 0 | BJ27: =BI27*E27 -> 0 | BL27: =BK27*E27 -> 0
A28: 24 | B28: ='[6]NOI TAC 2026'!B30 -> S945605 | C28: =IF(B28="","",HYPERLINK("\\vdm-fsvr\Cokhi-機工\CONG VIEC CHUNG 2026\★2026年度年次目標設定\5.COSTDOWN 2026\5.MỤC TIÊU 2026\COSTDOWN 2026\PDF\"&B28&".pdf","XEM")) -> XEM | D28: ='[6]NOI TAC 2026'!F30 -> 1 | E28: ='[6]NOI TAC 2026'!AL30 -> 324.71084 | K28: 1 | R28: =SUM(F28:Q28) -> 1 | T28: =$E28*F28 -> 0 | U28: =$E28*G28 -> 0 | V28: =$E28*H28 -> 0 | W28: =$E28*I28 -> 0 | X28: =$E28*J28 -> 0 | Y28: =$E28*K28 -> 324.71084 | Z28: =$E28*L28 -> 0 | AA28: =$E28*M28 -> 0 | ... AE28: =$E28*Q28 -> 0 | AG28: #N/A | AH28: #N/A | AI28: #N/A | AJ28: #N/A | AK28: #N/A | AL28: #N/A | AP28: =AO28*E28 -> 0 | AR28: =AQ28*E28 -> 0 | AT28: =AS28*E28 -> 0 | AV28: =AU28*E28 -> 0 | AX28: =AW28*E28 -> 0 | AZ28: =AY28*E28 -> 0 | BB28: =BA28*E28 -> 0 | BD28: =BC28*E28 -> 0 | BF28: =BE28*E28 -> 0 | BH28: =BG28*E28 -> 0 | BJ28: =BI28*E28 -> 0 | BL28: =BK28*E28 -> 0
A29: 25 | B29: ='[6]NOI TAC 2026'!B31 -> R031206 | C29: =IF(B29="","",HYPERLINK("\\vdm-fsvr\Cokhi-機工\CONG VIEC CHUNG 2026\★2026年度年次目標設定\5.COSTDOWN 2026\5.MỤC TIÊU 2026\COSTDOWN 2026\PDF\"&B29&".pdf","XEM")) -> XEM | D29: ='[6]NOI TAC 2026'!F31 -> 1 | E29: ='[6]NOI TAC 2026'!AL31 -> 390.59956 | L29: 1 | R29: =SUM(F29:Q29) -> 1 | T29: =$E29*F29 -> 0 | U29: =$E29*G29 -> 0 | V29: =$E29*H29 -> 0 | W29: =$E29*I29 -> 0 | X29: =$E29*J29 -> 0 | Y29: =$E29*K29 -> 0 | Z29: =$E29*L29 -> 390.59956 | AA29: =$E29*M29 -> 0 | ... AE29: =$E29*Q29 -> 0 | AG29: #N/A | AH29: #N/A | AI29: #N/A | AJ29: #N/A | AK29: #N/A | AL29: #N/A | AP29: =AO29*E29 -> 0 | AR29: =AQ29*E29 -> 0 | AT29: =AS29*E29 -> 0 | AV29: =AU29*E29 -> 0 | AX29: =AW29*E29 -> 0 | AZ29: =AY29*E29 -> 0 | BB29: =BA29*E29 -> 0 | BD29: =BC29*E29 -> 0 | BF29: =BE29*E29 -> 0 | BH29: =BG29*E29 -> 0 | BJ29: =BI29*E29 -> 0 | BL29: =BK29*E29 -> 0
A30: 26 | B30: ='[6]NOI TAC 2026'!B32 -> S919631 | C30: =IF(B30="","",HYPERLINK("\\vdm-fsvr\Cokhi-機工\CONG VIEC CHUNG 2026\★2026年度年次目標設定\5.COSTDOWN 2026\5.MỤC TIÊU 2026\COSTDOWN 2026\PDF\"&B30&".pdf","XEM")) -> XEM | D30: ='[6]NOI TAC 2026'!F32 -> 1 | E30: ='[6]NOI TAC 2026'!AL32 -> 450.93884 | M30: 1 | R30: =SUM(F30:Q30) -> 1 | T30: =$E30*F30 -> 0 | U30: =$E30*G30 -> 0 | V30: =$E30*H30 -> 0 | W30: =$E30*I30 -> 0 | X30: =$E30*J30 -> 0 | Y30: =$E30*K30 -> 0 | Z30: =$E30*L30 -> 0 | AA30: =$E30*M30 -> 450.93884 | ... AE30: =$E30*Q30 -> 0 | AG30: #N/A | AH30: #N/A | AI30: #N/A | AJ30: #N/A | AK30: #N/A | AL30: #N/A | AP30: =AO30*E30 -> 0 | AR30: =AQ30*E30 -> 0 | AT30: =AS30*E30 -> 0 | AV30: =AU30*E30 -> 0 | AX30: =AW30*E30 -> 0 | AZ30: =AY30*E30 -> 0 | BB30: =BA30*E30 -> 0 | BD30: =BC30*E30 -> 0 | BF30: =BE30*E30 -> 0 | BH30: =BG30*E30 -> 0 | BJ30: =BI30*E30 -> 0 | BL30: =BK30*E30 -> 0
A31: 27 | B31: ='[6]NOI TAC 2026'!B33 -> S029583 | C31: =IF(B31="","",HYPERLINK("\\vdm-fsvr\Cokhi-機工\CONG VIEC CHUNG 2026\★2026年度年次目標設定\5.COSTDOWN 2026\5.MỤC TIÊU 2026\COSTDOWN 2026\PDF\"&B31&".pdf","XEM")) -> XEM | D31: ='[6]NOI TAC 2026'!F33 -> 1 | E31: ='[6]NOI TAC 2026'!AL33 -> 483.10576 | N31: 1 | R31: =SUM(F31:Q31) -> 1 | T31: =$E31*F31 -> 0 | U31: =$E31*G31 -> 0 | V31: =$E31*H31 -> 0 | W31: =$E31*I31 -> 0 | X31: =$E31*J31 -> 0 | Y31: =$E31*K31 -> 0 | Z31: =$E31*L31 -> 0 | AA31: =$E31*M31 -> 0 | ... AE31: =$E31*Q31 -> 0 | AG31: #N/A | AH31: #N/A | AI31: #N/A | AJ31: #N/A | AK31: #N/A | AL31: #N/A | AP31: =AO31*E31 -> 0 | AR31: =AQ31*E31 -> 0 | AT31: =AS31*E31 -> 0 | AV31: =AU31*E31 -> 0 | AX31: =AW31*E31 -> 0 | AZ31: =AY31*E31 -> 0 | BB31: =BA31*E31 -> 0 | BD31: =BC31*E31 -> 0 | BF31: =BE31*E31 -> 0 | BH31: =BG31*E31 -> 0 | BJ31: =BI31*E31 -> 0 | BL31: =BK31*E31 -> 0
A32: 28 | B32: ='[6]NOI TAC 2026'!B34 -> R462231 | C32: =IF(B32="","",HYPERLINK("\\vdm-fsvr\Cokhi-機工\CONG VIEC CHUNG 2026\★2026年度年次目標設定\5.COSTDOWN 2026\5.MỤC TIÊU 2026\COSTDOWN 2026\PDF\"&B32&".pdf","XEM")) -> XEM | D32: ='[6]NOI TAC 2026'!F34 -> 1 | E32: ='[6]NOI TAC 2026'!AL34 -> 2.1008576 | O32: 1 | R32: =SUM(F32:Q32) -> 1 | T32: =$E32*F32 -> 0 | U32: =$E32*G32 -> 0 | V32: =$E32*H32 -> 0 | W32: =$E32*I32 -> 0 | X32: =$E32*J32 -> 0 | Y32: =$E32*K32 -> 0 | Z32: =$E32*L32 -> 0 | AA32: =$E32*M32 -> 0 | ... AE32: =$E32*Q32 -> 0 | AG32: #N/A | AH32: #N/A | AI32: #N/A | AJ32: #N/A | AK32: #N/A | AL32: #N/A | AP32: =AO32*E32 -> 0 | AR32: =AQ32*E32 -> 0 | AT32: =AS32*E32 -> 0 | AV32: =AU32*E32 -> 0 | AX32: =AW32*E32 -> 0 | AZ32: =AY32*E32 -> 0 | BB32: =BA32*E32 -> 0 | BD32: =BC32*E32 -> 0 | BF32: =BE32*E32 -> 0 | BH32: =BG32*E32 -> 0 | BJ32: =BI32*E32 -> 0 | BL32: =BK32*E32 -> 0
A33: 29 | B33: ='[6]NOI TAC 2026'!B35 -> R028995 | C33: =IF(B33="","",HYPERLINK("\\vdm-fsvr\Cokhi-機工\CONG VIEC CHUNG 2026\★2026年度年次目標設定\5.COSTDOWN 2026\5.MỤC TIÊU 2026\COSTDOWN 2026\PDF\"&B33&".pdf","XEM")) -> XEM | D33: ='[6]NOI TAC 2026'!F35 -> 1 | E33: ='[6]NOI TAC 2026'!AL35 -> 59.678271 | P33: 1 | R33: =SUM(F33:Q33) -> 1 | T33: =$E33*F33 -> 0 | U33: =$E33*G33 -> 0 | V33: =$E33*H33 -> 0 | W33: =$E33*I33 -> 0 | X33: =$E33*J33 -> 0 | Y33: =$E33*K33 -> 0 | Z33: =$E33*L33 -> 0 | AA33: =$E33*M33 -> 0 | ... AE33: =$E33*Q33 -> 0 | AG33: #N/A | AH33: #N/A | AI33: #N/A | AJ33: #N/A | AK33: #N/A | AL33: #N/A | AP33: =AO33*E33 -> 0 | AR33: =AQ33*E33 -> 0 | AT33: =AS33*E33 -> 0 | AV33: =AU33*E33 -> 0 | AX33: =AW33*E33 -> 0 | AZ33: =AY33*E33 -> 0 | BB33: =BA33*E33 -> 0 | BD33: =BC33*E33 -> 0 | BF33: =BE33*E33 -> 0 | BH33: =BG33*E33 -> 0 | BJ33: =BI33*E33 -> 0 | BL33: =BK33*E33 -> 0
A34: 30 | B34: ='[6]NOI TAC 2026'!B36 -> R408546 | C34: =IF(B34="","",HYPERLINK("\\vdm-fsvr\Cokhi-機工\CONG VIEC CHUNG 2026\★2026年度年次目標設定\5.COSTDOWN 2026\5.MỤC TIÊU 2026\COSTDOWN 2026\PDF\"&B34&".pdf","XEM")) -> XEM | D34: ='[6]NOI TAC 2026'!F36 -> 1 | E34: ='[6]NOI TAC 2026'!AL36 -> 34.102066 | F34: 1 | R34: =SUM(F34:Q34) -> 1 | T34: =$E34*F34 -> 34.102066 | U34: =$E34*G34 -> 0 | V34: =$E34*H34 -> 0 | W34: =$E34*I34 -> 0 | X34: =$E34*J34 -> 0 | Y34: =$E34*K34 -> 0 | Z34: =$E34*L34 -> 0 | AA34: =$E34*M34 -> 0 | ... AE34: =$E34*Q34 -> 0 | AG34: #N/A | AH34: #N/A | AI34: #N/A | AJ34: #N/A | AK34: #N/A | AL34: #N/A | AP34: =AO34*E34 -> 0 | AR34: =AQ34*E34 -> 0 | AT34: =AS34*E34 -> 0 | AV34: =AU34*E34 -> 0 | AX34: =AW34*E34 -> 0 | AZ34: =AY34*E34 -> 0 | BB34: =BA34*E34 -> 0 | BD34: =BC34*E34 -> 0 | BF34: =BE34*E34 -> 0 | BH34: =BG34*E34 -> 0 | BJ34: =BI34*E34 -> 0 | BL34: =BK34*E34 -> 0
A35: 31 | B35: ='[6]NOI TAC 2026'!B37 -> R173347 | C35: =IF(B35="","",HYPERLINK("\\vdm-fsvr\Cokhi-機工\CONG VIEC CHUNG 2026\★2026年度年次目標設定\5.COSTDOWN 2026\5.MỤC TIÊU 2026\COSTDOWN 2026\PDF\"&B35&".pdf","XEM")) -> XEM | D35: ='[6]NOI TAC 2026'!F37 -> 1 | E35: ='[6]NOI TAC 2026'!AL37 -> 52.346831 | I35: 1 | R35: =SUM(F35:Q35) -> 1 | T35: =$E35*F35 -> 0 | U35: =$E35*G35 -> 0 | V35: =$E35*H35 -> 0 | W35: =$E35*I35 -> 52.346831 | X35: =$E35*J35 -> 0 | Y35: =$E35*K35 -> 0 | Z35: =$E35*L35 -> 0 | AA35: =$E35*M35 -> 0 | ... AE35: =$E35*Q35 -> 0 | AG35: #N/A | AH35: #N/A | AI35: #N/A | AJ35: #N/A | AK35: #N/A | AL35: #N/A | AP35: =AO35*E35 -> 0 | AR35: =AQ35*E35 -> 0 | AT35: =AS35*E35 -> 0 | AV35: =AU35*E35 -> 0 | AX35: =AW35*E35 -> 0 | AZ35: =AY35*E35 -> 0 | BB35: =BA35*E35 -> 0 | BD35: =BC35*E35 -> 0 | BF35: =BE35*E35 -> 0 | BH35: =BG35*E35 -> 0 | BJ35: =BI35*E35 -> 0 | BL35: =BK35*E35 -> 0
A36: 32 | B36: ='[6]NOI TAC 2026'!B38 -> S445272 | C36: =IF(B36="","",HYPERLINK("\\vdm-fsvr\Cokhi-機工\CONG VIEC CHUNG 2026\★2026年度年次目標設定\5.COSTDOWN 2026\5.MỤC TIÊU 2026\COSTDOWN 2026\PDF\"&B36&".pdf","XEM")) -> XEM | D36: ='[6]NOI TAC 2026'!F38 -> 2 | E36: ='[6]NOI TAC 2026'!AL38 -> 51.651456 | G36: 1 | O36: 1 | R36: =SUM(F36:Q36) -> 2 | T36: =$E36*F36 -> 0 | U36: =$E36*G36 -> 51.651456 | V36: =$E36*H36 -> 0 | W36: =$E36*I36 -> 0 | X36: =$E36*J36 -> 0 | Y36: =$E36*K36 -> 0 | Z36: =$E36*L36 -> 0 | AA36: =$E36*M36 -> 0 | ... AE36: =$E36*Q36 -> 0 | AG36: #N/A | AH36: #N/A | AI36: #N/A | AJ36: #N/A | AK36: #N/A | AL36: #N/A | AP36: =AO36*E36 -> 0 | AR36: =AQ36*E36 -> 0 | AT36: =AS36*E36 -> 0 | AV36: =AU36*E36 -> 0 | AX36: =AW36*E36 -> 0 | AZ36: =AY36*E36 -> 0 | BB36: =BA36*E36 -> 0 | BD36: =BC36*E36 -> 0 | BF36: =BE36*E36 -> 0 | BH36: =BG36*E36 -> 0 | BJ36: =BI36*E36 -> 0 | BL36: =BK36*E36 -> 0
A37: 33 | B37: ='[6]NOI TAC 2026'!B39 -> R028307 | C37: =IF(B37="","",HYPERLINK("\\vdm-fsvr\Cokhi-機工\CONG VIEC CHUNG 2026\★2026年度年次目標設定\5.COSTDOWN 2026\5.MỤC TIÊU 2026\COSTDOWN 2026\PDF\"&B37&".pdf","XEM")) -> XEM | D37: ='[6]NOI TAC 2026'!F39 -> 1 | E37: ='[6]NOI TAC 2026'!AL39 -> 316.4408 | P37: 1 | R37: =SUM(F37:Q37) -> 1 | T37: =$E37*F37 -> 0 | U37: =$E37*G37 -> 0 | V37: =$E37*H37 -> 0 | W37: =$E37*I37 -> 0 | X37: =$E37*J37 -> 0 | Y37: =$E37*K37 -> 0 | Z37: =$E37*L37 -> 0 | AA37: =$E37*M37 -> 0 | ... AE37: =$E37*Q37 -> 0 | AG37: #N/A | AH37: #N/A | AI37: #N/A | AJ37: #N/A | AK37: #N/A | AL37: #N/A | AP37: =AO37*E37 -> 0 | AR37: =AQ37*E37 -> 0 | AT37: =AS37*E37 -> 0 | AV37: =AU37*E37 -> 0 | AX37: =AW37*E37 -> 0 | AZ37: =AY37*E37 -> 0 | BB37: =BA37*E37 -> 0 | BD37: =BC37*E37 -> 0 | BF37: =BE37*E37 -> 0 | BH37: =BG37*E37 -> 0 | BJ37: =BI37*E37 -> 0 | BL37: =BK37*E37 -> 0
A38: 34 | B38: ='[6]NOI TAC 2026'!B40 -> R063169 | C38: =IF(B38="","",HYPERLINK("\\vdm-fsvr\Cokhi-機工\CONG VIEC CHUNG 2026\★2026年度年次目標設定\5.COSTDOWN 2026\5.MỤC TIÊU 2026\COSTDOWN 2026\PDF\"&B38&".pdf","XEM")) -> XEM | D38: ='[6]NOI TAC 2026'!F40 -> 1 | E38: ='[6]NOI TAC 2026'!AL40 -> 851.5544 | L38: 1 | R38: =SUM(F38:Q38) -> 1 | T38: =$E38*F38 -> 0 | U38: =$E38*G38 -> 0 | V38: =$E38*H38 -> 0 | W38: =$E38*I38 -> 0 | X38: =$E38*J38 -> 0 | Y38: =$E38*K38 -> 0 | Z38: =$E38*L38 -> 851.5544 | AA38: =$E38*M38 -> 0 | ... AE38: =$E38*Q38 -> 0 | AG38: #N/A | AH38: #N/A | AI38: #N/A | AJ38: #N/A | AK38: #N/A | AL38: #N/A | AP38: =AO38*E38 -> 0 | AR38: =AQ38*E38 -> 0 | AT38: =AS38*E38 -> 0 | AV38: =AU38*E38 -> 0 | AX38: =AW38*E38 -> 0 | AZ38: =AY38*E38 -> 0 | BB38: =BA38*E38 -> 0 | BD38: =BC38*E38 -> 0 | BF38: =BE38*E38 -> 0 | BH38: =BG38*E38 -> 0 | BJ38: =BI38*E38 -> 0 | BL38: =BK38*E38 -> 0
A39: 35 | B39: ='[6]NOI TAC 2026'!B41 -> R422776 | C39: =IF(B39="","",HYPERLINK("\\vdm-fsvr\Cokhi-機工\CONG VIEC CHUNG 2026\★2026年度年次目標設定\5.COSTDOWN 2026\5.MỤC TIÊU 2026\COSTDOWN 2026\PDF\"&B39&".pdf","XEM")) -> XEM | D39: ='[6]NOI TAC 2026'!F41 -> 4 | E39: ='[6]NOI TAC 2026'!AL41 -> 164.3748 | I39: 1 | L39: 1 | N39: 1 | Q39: 1 | R39: =SUM(F39:Q39) -> 4 | T39: =$E39*F39 -> 0 | U39: =$E39*G39 -> 0 | V39: =$E39*H39 -> 0 | W39: =$E39*I39 -> 164.3748 | X39: =$E39*J39 -> 0 | Y39: =$E39*K39 -> 0 | Z39: =$E39*L39 -> 164.3748 | AA39: =$E39*M39 -> 0 | ... AE39: =$E39*Q39 -> 164.3748 | AG39: #N/A | AH39: #N/A | AI39: #N/A | AJ39: #N/A | AK39: #N/A | AL39: #N/A | AP39: =AO39*E39 -> 0 | AR39: =AQ39*E39 -> 0 | AT39: =AS39*E39 -> 0 | AV39: =AU39*E39 -> 0 | AX39: =AW39*E39 -> 0 | AZ39: =AY39*E39 -> 0 | BB39: =BA39*E39 -> 0 | BD39: =BC39*E39 -> 0 | BF39: =BE39*E39 -> 0 | BH39: =BG39*E39 -> 0 | BJ39: =BI39*E39 -> 0 | BL39: =BK39*E39 -> 0
A40: 36 | B40: ='[6]NOI TAC 2026'!B42 -> R530898 | C40: =IF(B40="","",HYPERLINK("\\vdm-fsvr\Cokhi-機工\CONG VIEC CHUNG 2026\★2026年度年次目標設定\5.COSTDOWN 2026\5.MỤC TIÊU 2026\COSTDOWN 2026\PDF\"&B40&".pdf","XEM")) -> XEM | D40: ='[6]NOI TAC 2026'!F42 -> 1 | E40: ='[6]NOI TAC 2026'!AL42 -> 172.2836 | F40: 1 | R40: =SUM(F40:Q40) -> 1 | T40: =$E40*F40 -> 172.2836 | U40: =$E40*G40 -> 0 | V40: =$E40*H40 -> 0 | W40: =$E40*I40 -> 0 | X40: =$E40*J40 -> 0 | Y40: =$E40*K40 -> 0 | Z40: =$E40*L40 -> 0 | AA40: =$E40*M40 -> 0 | ... AE40: =$E40*Q40 -> 0 | AG40: #N/A | AH40: #N/A | AI40: #N/A | AJ40: #N/A | AK40: #N/A | AL40: #N/A | AP40: =AO40*E40 -> 0 | AR40: =AQ40*E40 -> 0 | AT40: =AS40*E40 -> 0 | AV40: =AU40*E40 -> 0 | AX40: =AW40*E40 -> 0 | AZ40: =AY40*E40 -> 0 | BB40: =BA40*E40 -> 0 | BD40: =BC40*E40 -> 0 | BF40: =BE40*E40 -> 0 | BH40: =BG40*E40 -> 0 | BJ40: =BI40*E40 -> 0 | BL40: =BK40*E40 -> 0
A41: 37 | B41: ='[6]NOI TAC 2026'!B43 -> R558748 | C41: =IF(B41="","",HYPERLINK("\\vdm-fsvr\Cokhi-機工\CONG VIEC CHUNG 2026\★2026年度年次目標設定\5.COSTDOWN 2026\5.MỤC TIÊU 2026\COSTDOWN 2026\PDF\"&B41&".pdf","XEM")) -> XEM | D41: ='[6]NOI TAC 2026'!F43 -> 1 | E41: ='[6]NOI TAC 2026'!AL43 -> 230.97565 | H41: 1 | R41: =SUM(F41:Q41) -> 1 | T41: =$E41*F41 -> 0 | U41: =$E41*G41 -> 0 | V41: =$E41*H41 -> 230.97565 | W41: =$E41*I41 -> 0 | X41: =$E41*J41 -> 0 | Y41: =$E41*K41 -> 0 | Z41: =$E41*L41 -> 0 | AA41: =$E41*M41 -> 0 | ... AE41: =$E41*Q41 -> 0 | AG41: #N/A | AH41: #N/A | AI41: #N/A | AJ41: #N/A | AK41: #N/A | AL41: #N/A | AP41: =AO41*E41 -> 0 | AR41: =AQ41*E41 -> 0 | AT41: =AS41*E41 -> 0 | AV41: =AU41*E41 -> 0 | AX41: =AW41*E41 -> 0 | AZ41: =AY41*E41 -> 0 | BB41: =BA41*E41 -> 0 | BD41: =BC41*E41 -> 0 | BF41: =BE41*E41 -> 0 | BH41: =BG41*E41 -> 0 | BJ41: =BI41*E41 -> 0 | BL41: =BK41*E41 -> 0
...

Sheet 2.Nội tác LK thành hình
AN1: Thực tích costdown từng tháng
A2: KẾ HOẠCH GIA CÔNG | S2: Mục tiêu CostDown từng tháng | AF2: KỲ HẠN GIA CÔNG | AN2: 1月 | AP2: 2月 | AR2: 3月 | AT2: 4月 | AV2: 5月 | AX2: 6月 | AZ2: 7月 | BB2: 8月 | BD2: 9月 | BF2: 10月 | BH2: 11月 | BJ2: 12月
A3: No | B3: S,R no | C3: File PDF | D3: T1 | E3: T2 | F3: T3 | G3: T4 | H3: T5 | I3: T6 | J3: T7 | K3: T8 | L3: T9 | M3: T10 | N3: T11 | O3: T12 | P3: TỔNG | Q3: Đơn giá | S3: T1 | T3: T2 | U3: T3 | V3: T4 | W3: T5 | X3: T6 | Y3: T7 | Z3: T8 | AA3: T9 | AB3: T10 | AC3: T11 | AD3: T12 | AF3: SYC | AG3: REP | AH3: SL | AI3: CĐ-HT | AJ3: CĐ-TT | AK3: KH | AL3: CHÚ Ý | AN3: SL | AO3: CD | AP3: SL | AQ3: CD | AR3: SL | AS3: CD | AT3: SL | AU3: CD | AV3: SL | AW3: CD | AX3: SL | AY3: CD | AZ3: SL | BA3: CD | BB3: SL | BC3: CD | BD3: SL | BE3: CD | BF3: SL | BG3: CD | BH3: SL | BI3: CD | BJ3: SL | BK3: CD
A4: 1 | B4: ='[7]LIST S.NO'!C7 -> R067135 | C4: =IF(B4="","",HYPERLINK("\\vdm-fsvr\Cokhi-機工\CONG VIEC CHUNG 2026\★2026年度年次目標設定\5.COSTDOWN 2026\5.MỤC TIÊU 2026\COSTDOWN 2026\PDF\"&B4&".pdf","XEM")) -> XEM | F4: 1 | L4: 1 | P4: =SUM(D4:O4) -> 2 | Q4: ='[7]LIST S.NO'!AM7 -> 1112.0412 | S4: =$Q4*D4 -> 0 | T4: =$Q4*E4 -> 0 | U4: =$Q4*F4 -> 1112.0412 | V4: =$Q4*G4 -> 0 | W4: =$Q4*H4 -> 0 | X4: =$Q4*I4 -> 0 | Y4: =$Q4*J4 -> 0 | Z4: =$Q4*K4 -> 0 | ... AD4: =$Q4*O4 -> 0 | AF4: 2136038309 | AG4: 9 | AH4: 1 | AI4: GR | AJ4: GS ED EW GR2 GS2 EN GS3 GP AF | AK4: 46135 | AO4: =AN4*Q4 -> 0 | AQ4: =AP4*Q4 -> 0 | AS4: =AR4*Q4 -> 0 | AU4: =AT4*Q4 -> 0 | AW4: =AV4*Q4 -> 0 | AY4: =AX4*Q4 -> 0 | BA4: =AZ4*Q4 -> 0 | BC4: =BB4*Q4 -> 0 | BE4: =BD4*Q4 -> 0 | BG4: =BF4*Q4 -> 0 | BI4: =BH4*Q4 -> 0 | BK4: =BJ4*Q4 -> 0
A5: 2 | B5: ='[7]LIST S.NO'!C8 -> R062763 | C5: =IF(B5="","",HYPERLINK("\\vdm-fsvr\Cokhi-機工\CONG VIEC CHUNG 2026\★2026年度年次目標設定\5.COSTDOWN 2026\5.MỤC TIÊU 2026\COSTDOWN 2026\PDF\"&B5&".pdf","XEM")) -> XEM | E5: 1 | K5: 1 | P5: =SUM(D5:O5) -> 2 | Q5: ='[7]LIST S.NO'!AM8 -> 1291.8607 | S5: =$Q5*D5 -> 0 | T5: =$Q5*E5 -> 1291.8607 | U5: =$Q5*F5 -> 0 | V5: =$Q5*G5 -> 0 | W5: =$Q5*H5 -> 0 | X5: =$Q5*I5 -> 0 | Y5: =$Q5*J5 -> 0 | Z5: =$Q5*K5 -> 1291.8607 | ... AD5: =$Q5*O5 -> 0 | AF5: 2136038310 | AG5: 10 | AH5: 1 | AI5: BJ | AJ5: HT GR GS ED EW GR2 GS2 EN GP | AK5: 46136 | AO5: =AN5*Q5 -> 0 | AQ5: =AP5*Q5 -> 0 | AS5: =AR5*Q5 -> 0 | AU5: =AT5*Q5 -> 0 | AW5: =AV5*Q5 -> 0 | AY5: =AX5*Q5 -> 0 | BA5: =AZ5*Q5 -> 0 | BC5: =BB5*Q5 -> 0 | BE5: =BD5*Q5 -> 0 | BG5: =BF5*Q5 -> 0 | BI5: =BH5*Q5 -> 0 | BK5: =BJ5*Q5 -> 0
A6: 3 | B6: ='[7]LIST S.NO'!C9 -> S031476 | C6: =IF(B6="","",HYPERLINK("\\vdm-fsvr\Cokhi-機工\CONG VIEC CHUNG 2026\★2026年度年次目標設定\5.COSTDOWN 2026\5.MỤC TIÊU 2026\COSTDOWN 2026\PDF\"&B6&".pdf","XEM")) -> XEM | D6: 1 | J6: 1 | P6: =SUM(D6:O6) -> 2 | Q6: ='[7]LIST S.NO'!AM9 -> 1040.0568 | S6: =$Q6*D6 -> 1040.0568 | T6: =$Q6*E6 -> 0 | U6: =$Q6*F6 -> 0 | V6: =$Q6*G6 -> 0 | W6: =$Q6*H6 -> 0 | X6: =$Q6*I6 -> 0 | Y6: =$Q6*J6 -> 1040.0568 | Z6: =$Q6*K6 -> 0 | ... AD6: =$Q6*O6 -> 0 | AF6: #N/A | AG6: #N/A | AH6: #N/A | AI6: #N/A | AJ6: #N/A | AK6: #N/A | AO6: =AN6*Q6 -> 0 | AQ6: =AP6*Q6 -> 0 | AS6: =AR6*Q6 -> 0 | AU6: =AT6*Q6 -> 0 | AW6: =AV6*Q6 -> 0 | AY6: =AX6*Q6 -> 0 | BA6: =AZ6*Q6 -> 0 | BC6: =BB6*Q6 -> 0 | BE6: =BD6*Q6 -> 0 | BG6: =BF6*Q6 -> 0 | BI6: =BH6*Q6 -> 0 | BK6: =BJ6*Q6 -> 0
A7: 4 | B7: ='[7]LIST S.NO'!C10 -> S899529 | C7: =IF(B7="","",HYPERLINK("\\vdm-fsvr\Cokhi-機工\CONG VIEC CHUNG 2026\★2026年度年次目標設定\5.COSTDOWN 2026\5.MỤC TIÊU 2026\COSTDOWN 2026\PDF\"&B7&".pdf","XEM")) -> XEM | G7: 1 | M7: 1 | P7: =SUM(D7:O7) -> 2 | Q7: ='[7]LIST S.NO'!AM10 -> 1079.1915 | S7: =$Q7*D7 -> 0 | T7: =$Q7*E7 -> 0 | U7: =$Q7*F7 -> 0 | V7: =$Q7*G7 -> 1079.1915 | W7: =$Q7*H7 -> 0 | X7: =$Q7*I7 -> 0 | Y7: =$Q7*J7 -> 0 | Z7: =$Q7*K7 -> 0 | ... AD7: =$Q7*O7 -> 0 | AF7: 213512225A | AG7: 48 | AH7: 1 | AI7: OK | AK7: 2026/06/02 | AL7: T4 | AO7: =AN7*Q7 -> 0 | AQ7: =AP7*Q7 -> 0 | AR7: 1 | AS7: =AR7*Q7 -> 1079.1915 | AU7: =AT7*Q7 -> 0 | AW7: =AV7*Q7 -> 0 | AY7: =AX7*Q7 -> 0 | BA7: =AZ7*Q7 -> 0 | BC7: =BB7*Q7 -> 0 | BE7: =BD7*Q7 -> 0 | BG7: =BF7*Q7 -> 0 | BI7: =BH7*Q7 -> 0 | BK7: =BJ7*Q7 -> 0
A8: 5 | B8: ='[7]LIST S.NO'!C11 -> S742878 | C8: =IF(B8="","",HYPERLINK("\\vdm-fsvr\Cokhi-機工\CONG VIEC CHUNG 2026\★2026年度年次目標設定\5.COSTDOWN 2026\5.MỤC TIÊU 2026\COSTDOWN 2026\PDF\"&B8&".pdf","XEM")) -> XEM | F8: 1 | L8: 1 | P8: =SUM(D8:O8) -> 2 | Q8: ='[7]LIST S.NO'!AM11 -> 639.56459 | S8: =$Q8*D8 -> 0 | T8: =$Q8*E8 -> 0 | U8: =$Q8*F8 -> 639.56459 | V8: =$Q8*G8 -> 0 | W8: =$Q8*H8 -> 0 | X8: =$Q8*I8 -> 0 | Y8: =$Q8*J8 -> 0 | Z8: =$Q8*K8 -> 0 | ... AD8: =$Q8*O8 -> 0 | AF8: 2136038311 | AG8: 11 | AH8: 1 | AI8: BJ | AJ8: HT GR GS GJ EN AF | AK8: 46115 | AO8: =AN8*Q8 -> 0 | AQ8: =AP8*Q8 -> 0 | AS8: =AR8*Q8 -> 0 | AU8: =AT8*Q8 -> 0 | AW8: =AV8*Q8 -> 0 | AY8: =AX8*Q8 -> 0 | BA8: =AZ8*Q8 -> 0 | BC8: =BB8*Q8 -> 0 | BE8: =BD8*Q8 -> 0 | BG8: =BF8*Q8 -> 0 | BI8: =BH8*Q8 -> 0 | BK8: =BJ8*Q8 -> 0
A9: 6 | B9: ='[7]LIST S.NO'!C12 -> S899525 | C9: =IF(B9="","",HYPERLINK("\\vdm-fsvr\Cokhi-機工\CONG VIEC CHUNG 2026\★2026年度年次目標設定\5.COSTDOWN 2026\5.MỤC TIÊU 2026\COSTDOWN 2026\PDF\"&B9&".pdf","XEM")) -> XEM | H9: 1 | N9: 1 | P9: =SUM(D9:O9) -> 2 | Q9: ='[7]LIST S.NO'!AM12 -> 847.60756 | S9: =$Q9*D9 -> 0 | T9: =$Q9*E9 -> 0 | U9: =$Q9*F9 -> 0 | V9: =$Q9*G9 -> 0 | W9: =$Q9*H9 -> 847.60756 | X9: =$Q9*I9 -> 0 | Y9: =$Q9*J9 -> 0 | Z9: =$Q9*K9 -> 0 | ... AD9: =$Q9*O9 -> 0 | AF9: #N/A | AG9: #N/A | AH9: #N/A | AI9: #N/A | AJ9: #N/A | AK9: #N/A | AO9: =AN9*Q9 -> 0 | AQ9: =AP9*Q9 -> 0 | AS9: =AR9*Q9 -> 0 | AU9: =AT9*Q9 -> 0 | AW9: =AV9*Q9 -> 0 | AY9: =AX9*Q9 -> 0 | BA9: =AZ9*Q9 -> 0 | BC9: =BB9*Q9 -> 0 | BE9: =BD9*Q9 -> 0 | BG9: =BF9*Q9 -> 0 | BI9: =BH9*Q9 -> 0 | BK9: =BJ9*Q9 -> 0
A10: 7 | B10: ='[7]LIST S.NO'!C13 -> S202159 | C10: =IF(B10="","",HYPERLINK("\\vdm-fsvr\Cokhi-機工\CONG VIEC CHUNG 2026\★2026年度年次目標設定\5.COSTDOWN 2026\5.MỤC TIÊU 2026\COSTDOWN 2026\PDF\"&B10&".pdf","XEM")) -> XEM | I10: 1 | O10: 1 | P10: =SUM(D10:O10) -> 2 | Q10: ='[7]LIST S.NO'!AM13 -> 201.93641 | S10: =$Q10*D10 -> 0 | T10: =$Q10*E10 -> 0 | U10: =$Q10*F10 -> 0 | V10: =$Q10*G10 -> 0 | W10: =$Q10*H10 -> 0 | X10: =$Q10*I10 -> 201.93641 | Y10: =$Q10*J10 -> 0 | Z10: =$Q10*K10 -> 0 | ... AD10: =$Q10*O10 -> 201.93641 | AF10: 213509054A | AG10: 30 | AH10: 1 | AI10: OK | AK10: 2026/03/09 | AL10: T4 | AO10: =AN10*Q10 -> 0 | AQ10: =AP10*Q10 -> 0 | AR10: 1 | AS10: =AR10*Q10 -> 201.93641 | AU10: =AT10*Q10 -> 0 | AW10: =AV10*Q10 -> 0 | AY10: =AX10*Q10 -> 0 | BA10: =AZ10*Q10 -> 0 | BC10: =BB10*Q10 -> 0 | BE10: =BD10*Q10 -> 0 | BG10: =BF10*Q10 -> 0 | BI10: =BH10*Q10 -> 0 | BK10: =BJ10*Q10 -> 0
A11: 8 | B11: ='[7]LIST S.NO'!C14 -> R485016 | C11: =IF(B11="","",HYPERLINK("\\vdm-fsvr\Cokhi-機工\CONG VIEC CHUNG 2026\★2026年度年次目標設定\5.COSTDOWN 2026\5.MỤC TIÊU 2026\COSTDOWN 2026\PDF\"&B11&".pdf","XEM")) -> XEM | D11: 1 | K11: 1 | P11: =SUM(D11:O11) -> 2 | Q11: ='[7]LIST S.NO'!AM14 -> 411.30382 | S11: =$Q11*D11 -> 411.30382 | T11: =$Q11*E11 -> 0 | U11: =$Q11*F11 -> 0 | V11: =$Q11*G11 -> 0 | W11: =$Q11*H11 -> 0 | X11: =$Q11*I11 -> 0 | Y11: =$Q11*J11 -> 0 | Z11: =$Q11*K11 -> 411.30382 | ... AD11: =$Q11*O11 -> 0 | AF11: #N/A | AG11: #N/A | AH11: #N/A | AI11: #N/A | AJ11: #N/A | AK11: #N/A | AO11: =AN11*Q11 -> 0 | AQ11: =AP11*Q11 -> 0 | AS11: =AR11*Q11 -> 0 | AU11: =AT11*Q11 -> 0 | AW11: =AV11*Q11 -> 0 | AY11: =AX11*Q11 -> 0 | BA11: =AZ11*Q11 -> 0 | BC11: =BB11*Q11 -> 0 | BE11: =BD11*Q11 -> 0 | BG11: =BF11*Q11 -> 0 | BI11: =BH11*Q11 -> 0 | BK11: =BJ11*Q11 -> 0
A12: 9 | B12: ='[7]LIST S.NO'!C15 -> R485011 | C12: =IF(B12="","",HYPERLINK("\\vdm-fsvr\Cokhi-機工\CONG VIEC CHUNG 2026\★2026年度年次目標設定\5.COSTDOWN 2026\5.MỤC TIÊU 2026\COSTDOWN 2026\PDF\"&B12&".pdf","XEM")) -> XEM | E12: 1 | J12: 1 | P12: =SUM(D12:O12) -> 2 | Q12: ='[7]LIST S.NO'!AM15 -> 62.352179 | S12: =$Q12*D12 -> 0 | T12: =$Q12*E12 -> 62.352179 | U12: =$Q12*F12 -> 0 | V12: =$Q12*G12 -> 0 | W12: =$Q12*H12 -> 0 | X12: =$Q12*I12 -> 0 | Y12: =$Q12*J12 -> 62.352179 | Z12: =$Q12*K12 -> 0 | ... AD12: =$Q12*O12 -> 0 | AF12: #N/A | AG12: #N/A | AH12: #N/A | AI12: #N/A | AJ12: #N/A | AK12: #N/A | AO12: =AN12*Q12 -> 0 | AQ12: =AP12*Q12 -> 0 | AS12: =AR12*Q12 -> 0 | AU12: =AT12*Q12 -> 0 | AW12: =AV12*Q12 -> 0 | AY12: =AX12*Q12 -> 0 | BA12: =AZ12*Q12 -> 0 | BC12: =BB12*Q12 -> 0 | BE12: =BD12*Q12 -> 0 | BG12: =BF12*Q12 -> 0 | BI12: =BH12*Q12 -> 0 | BK12: =BJ12*Q12 -> 0
A13: 10 | B13: ='[7]LIST S.NO'!C16 -> R059797 | C13: =IF(B13="","",HYPERLINK("\\vdm-fsvr\Cokhi-機工\CONG VIEC CHUNG 2026\★2026年度年次目標設定\5.COSTDOWN 2026\5.MỤC TIÊU 2026\COSTDOWN 2026\PDF\"&B13&".pdf","XEM")) -> XEM | J13: 1 | L13: 1 | P13: =SUM(D13:O13) -> 2 | Q13: ='[7]LIST S.NO'!AM16 -> 348.68872 | S13: =$Q13*D13 -> 0 | T13: =$Q13*E13 -> 0 | U13: =$Q13*F13 -> 0 | V13: =$Q13*G13 -> 0 | W13: =$Q13*H13 -> 0 | X13: =$Q13*I13 -> 0 | Y13: =$Q13*J13 -> 348.68872 | Z13: =$Q13*K13 -> 0 | ... AD13: =$Q13*O13 -> 0 | AF13: 213510091A | AG13: 6 | AH13: 1 | AI13: OK | AK13: 2026/01/23 | AL13: T1 | AN13: 1 | AO13: =AN13*Q13 -> 348.68872 | AQ13: =AP13*Q13 -> 0 | AS13: =AR13*Q13 -> 0 | AU13: =AT13*Q13 -> 0 | AW13: =AV13*Q13 -> 0 | AY13: =AX13*Q13 -> 0 | BA13: =AZ13*Q13 -> 0 | BC13: =BB13*Q13 -> 0 | BE13: =BD13*Q13 -> 0 | BG13: =BF13*Q13 -> 0 | BI13: =BH13*Q13 -> 0 | BK13: =BJ13*Q13 -> 0
A14: 11 | B14: ='[7]LIST S.NO'!C17 -> R067136 | C14: =IF(B14="","",HYPERLINK("\\vdm-fsvr\Cokhi-機工\CONG VIEC CHUNG 2026\★2026年度年次目標設定\5.COSTDOWN 2026\5.MỤC TIÊU 2026\COSTDOWN 2026\PDF\"&B14&".pdf","XEM")) -> XEM | F14: 1 | L14: 1 | P14: =SUM(D14:O14) -> 2 | Q14: ='[7]LIST S.NO'!AM17 -> 462.11179 | S14: =$Q14*D14 -> 0 | T14: =$Q14*E14 -> 0 | U14: =$Q14*F14 -> 462.11179 | V14: =$Q14*G14 -> 0 | W14: =$Q14*H14 -> 0 | X14: =$Q14*I14 -> 0 | Y14: =$Q14*J14 -> 0 | Z14: =$Q14*K14 -> 0 | ... AD14: =$Q14*O14 -> 0 | AF14: 213510092A | AG14: 7 | AH14: 1 | AI14: OK | AK14: 2026/01/20 | AL14: T1 | AN14: 1 | AO14: =AN14*Q14 -> 462.11179 | AQ14: =AP14*Q14 -> 0 | AS14: =AR14*Q14 -> 0 | AU14: =AT14*Q14 -> 0 | AW14: =AV14*Q14 -> 0 | AY14: =AX14*Q14 -> 0 | BA14: =AZ14*Q14 -> 0 | BC14: =BB14*Q14 -> 0 | BE14: =BD14*Q14 -> 0 | BG14: =BF14*Q14 -> 0 | BI14: =BH14*Q14 -> 0 | BK14: =BJ14*Q14 -> 0
A15: 12 | B15: ='[7]LIST S.NO'!C18 -> R067143 | C15: =IF(B15="","",HYPERLINK("\\vdm-fsvr\Cokhi-機工\CONG VIEC CHUNG 2026\★2026年度年次目標設定\5.COSTDOWN 2026\5.MỤC TIÊU 2026\COSTDOWN 2026\PDF\"&B15&".pdf","XEM")) -> XEM | G15: 1 | N15: 1 | P15: =SUM(D15:O15) -> 2 | Q15: ='[7]LIST S.NO'!AM18 -> 123.58064 | S15: =$Q15*D15 -> 0 | T15: =$Q15*E15 -> 0 | U15: =$Q15*F15 -> 0 | V15: =$Q15*G15 -> 123.58064 | W15: =$Q15*H15 -> 0 | X15: =$Q15*I15 -> 0 | Y15: =$Q15*J15 -> 0 | Z15: =$Q15*K15 -> 0 | ... AD15: =$Q15*O15 -> 0 | AF15: 213510093A | AG15: 8 | AH15: 1 | AI15: OK | AK15: 2026/02/27 | AL15: T4 | AO15: =AN15*Q15 -> 0 | AQ15: =AP15*Q15 -> 0 | AR15: 1 | AS15: =AR15*Q15 -> 123.58064 | AU15: =AT15*Q15 -> 0 | AW15: =AV15*Q15 -> 0 | AY15: =AX15*Q15 -> 0 | BA15: =AZ15*Q15 -> 0 | BC15: =BB15*Q15 -> 0 | BE15: =BD15*Q15 -> 0 | BG15: =BF15*Q15 -> 0 | BI15: =BH15*Q15 -> 0 | BK15: =BJ15*Q15 -> 0
A16: 13 | B16: ='[7]LIST S.NO'!C19 -> R062773 | C16: =IF(B16="","",HYPERLINK("\\vdm-fsvr\Cokhi-機工\CONG VIEC CHUNG 2026\★2026年度年次目標設定\5.COSTDOWN 2026\5.MỤC TIÊU 2026\COSTDOWN 2026\PDF\"&B16&".pdf","XEM")) -> XEM | I16: 1 | M16: 1 | P16: =SUM(D16:O16) -> 2 | Q16: ='[7]LIST S.NO'!AM19 -> 127.12987 | S16: =$Q16*D16 -> 0 | T16: =$Q16*E16 -> 0 | U16: =$Q16*F16 -> 0 | V16: =$Q16*G16 -> 0 | W16: =$Q16*H16 -> 0 | X16: =$Q16*I16 -> 127.12987 | Y16: =$Q16*J16 -> 0 | Z16: =$Q16*K16 -> 0 | ... AD16: =$Q16*O16 -> 0 | AF16: 213506240A | AG16: 3 | AH16: 3 | AI16: OK | AK16: 2026/02/23 | AL16: T2+t4 | AO16: =AN16*Q16 -> 0 | AP16: 2 | AQ16: =AP16*Q16 -> 254.25974 | AR16: 3 | AS16: =AR16*Q16 -> 381.38962 | AU16: =AT16*Q16 -> 0 | AW16: =AV16*Q16 -> 0 | AY16: =AX16*Q16 -> 0 | BA16: =AZ16*Q16 -> 0 | BC16: =BB16*Q16 -> 0 | BE16: =BD16*Q16 -> 0 | BG16: =BF16*Q16 -> 0 | BI16: =BH16*Q16 -> 0 | BK16: =BJ16*Q16 -> 0
A17: 14 | B17: ='[7]LIST S.NO'!C20 -> R070100 | C17: =IF(B17="","",HYPERLINK("\\vdm-fsvr\Cokhi-機工\CONG VIEC CHUNG 2026\★2026年度年次目標設定\5.COSTDOWN 2026\5.MỤC TIÊU 2026\COSTDOWN 2026\PDF\"&B17&".pdf","XEM")) -> XEM | D17: 1 | K17: 1 | P17: =SUM(D17:O17) -> 2 | Q17: ='[7]LIST S.NO'!AM20 -> 513.20382 | S17: =$Q17*D17 -> 513.20382 | T17: =$Q17*E17 -> 0 | U17: =$Q17*F17 -> 0 | V17: =$Q17*G17 -> 0 | W17: =$Q17*H17 -> 0 | X17: =$Q17*I17 -> 0 | Y17: =$Q17*J17 -> 0 | Z17: =$Q17*K17 -> 513.20382 | ... AD17: =$Q17*O17 -> 0 | AF17: #N/A | AG17: #N/A | AH17: #N/A | AI17: #N/A | AJ17: #N/A | AK17: #N/A | AO17: =AN17*Q17 -> 0 | AQ17: =AP17*Q17 -> 0 | AS17: =AR17*Q17 -> 0 | AU17: =AT17*Q17 -> 0 | AW17: =AV17*Q17 -> 0 | AY17: =AX17*Q17 -> 0 | BA17: =AZ17*Q17 -> 0 | BC17: =BB17*Q17 -> 0 | BE17: =BD17*Q17 -> 0 | BG17: =BF17*Q17 -> 0 | BI17: =BH17*Q17 -> 0 | BK17: =BJ17*Q17 -> 0
A18: 15 | B18: ='[7]LIST S.NO'!C21 -> R175058 | C18: =IF(B18="","",HYPERLINK("\\vdm-fsvr\Cokhi-機工\CONG VIEC CHUNG 2026\★2026年度年次目標設定\5.COSTDOWN 2026\5.MỤC TIÊU 2026\COSTDOWN 2026\PDF\"&B18&".pdf","XEM")) -> XEM | I18: 1 | O18: 1 | P18: =SUM(D18:O18) -> 2 | Q18: ='[7]LIST S.NO'!AM21 -> 2534.7908 | S18: =$Q18*D18 -> 0 | T18: =$Q18*E18 -> 0 | U18: =$Q18*F18 -> 0 | V18: =$Q18*G18 -> 0 | W18: =$Q18*H18 -> 0 | X18: =$Q18*I18 -> 2534.7908 | Y18: =$Q18*J18 -> 0 | Z18: =$Q18*K18 -> 0 | ... AD18: =$Q18*O18 -> 2534.7908 | AF18: 213512302A | AG18: 17 | AH18: 4 | AI18: AA | AJ18: MA BJ HT GS ED EW GS2 EN GS3 | AK18: 2026/03/25 | AL18: T1+T3 | AN18: 1 | AO18: =AN18*Q18 -> 2534.7908 | AQ18: =AP18*Q18 -> 0 | AR18: 1 | AS18: =AR18*Q18 -> 2534.7908 | AU18: =AT18*Q18 -> 0 | AW18: =AV18*Q18 -> 0 | AY18: =AX18*Q18 -> 0 | BA18: =AZ18*Q18 -> 0 | BC18: =BB18*Q18 -> 0 | BE18: =BD18*Q18 -> 0 | BG18: =BF18*Q18 -> 0 | BI18: =BH18*Q18 -> 0 | BK18: =BJ18*Q18 -> 0
A19: 16 | B19: ='[7]LIST S.NO'!C22 -> R021024 | C19: =IF(B19="","",HYPERLINK("\\vdm-fsvr\Cokhi-機工\CONG VIEC CHUNG 2026\★2026年度年次目標設定\5.COSTDOWN 2026\5.MỤC TIÊU 2026\COSTDOWN 2026\PDF\"&B19&".pdf","XEM")) -> XEM | E19: 1 | J19: 1 | P19: =SUM(D19:O19) -> 2 | Q19: ='[7]LIST S.NO'!AM22 -> 1432.803 | S19: =$Q19*D19 -> 0 | T19: =$Q19*E19 -> 1432.803 | U19: =$Q19*F19 -> 0 | V19: =$Q19*G19 -> 0 | W19: =$Q19*H19 -> 0 | X19: =$Q19*I19 -> 0 | Y19: =$Q19*J19 -> 1432.803 | Z19: =$Q19*K19 -> 0 | ... AD19: =$Q19*O19 -> 0 | AF19: #N/A | AG19: #N/A | AH19: #N/A | AI19: #N/A | AJ19: #N/A | AK19: #N/A | AO19: =AN19*Q19 -> 0 | AQ19: =AP19*Q19 -> 0 | AS19: =AR19*Q19 -> 0 | AU19: =AT19*Q19 -> 0 | AW19: =AV19*Q19 -> 0 | AY19: =AX19*Q19 -> 0 | BA19: =AZ19*Q19 -> 0 | BC19: =BB19*Q19 -> 0 | BE19: =BD19*Q19 -> 0 | BG19: =BF19*Q19 -> 0 | BI19: =BH19*Q19 -> 0 | BK19: =BJ19*Q19 -> 0
A20: 17 | B20: ='[7]LIST S.NO'!C23 -> R307558 | C20: =IF(B20="","",HYPERLINK("\\vdm-fsvr\Cokhi-機工\CONG VIEC CHUNG 2026\★2026年度年次目標設定\5.COSTDOWN 2026\5.MỤC TIÊU 2026\COSTDOWN 2026\PDF\"&B20&".pdf","XEM")) -> XEM | G20: 1 | L20: 1 | P20: =SUM(D20:O20) -> 2 | Q20: ='[7]LIST S.NO'!AM23 -> 310.2411 | S20: =$Q20*D20 -> 0 | T20: =$Q20*E20 -> 0 | U20: =$Q20*F20 -> 0 | V20: =$Q20*G20 -> 310.2411 | W20: =$Q20*H20 -> 0 | X20: =$Q20*I20 -> 0 | Y20: =$Q20*J20 -> 0 | Z20: =$Q20*K20 -> 0 | ... AD20: =$Q20*O20 -> 0 | AF20: 213601060A | AG20: 17 | AH20: 1 | AI20: ED | AJ20: EW,GS2,EN,GS2 | AK20: 2026/03/25 | AO20: =AN20*Q20 -> 0 | AQ20: =AP20*Q20 -> 0 | AS20: =AR20*Q20 -> 0 | AU20: =AT20*Q20 -> 0 | AW20: =AV20*Q20 -> 0 | AY20: =AX20*Q20 -> 0 | BA20: =AZ20*Q20 -> 0 | BC20: =BB20*Q20 -> 0 | BE20: =BD20*Q20 -> 0 | BG20: =BF20*Q20 -> 0 | BI20: =BH20*Q20 -> 0 | BK20: =BJ20*Q20 -> 0
