Workbook

Sheet Tong_Hop
A1: Tỉ lệ % hoạt động có tải
A2: Hạng mục | B2: LA | C2: MA | D2: BJ | E2: GC | F2: GS | G2: GR | H2: EN | I2: GJ | J2: EW | K2: GP | L2: MC | M2: LN
A3: % Mục tiêu | B3: 0.2745098 | C3: 0.39529412 | D3: 0.39529412 | E3: 0.24411765 | F3: 0.46588235 | G3: 0.67764706 | H3: 0.73411765 | I3: 0.67764706 | J3: 0.81882353 | K3: 0.94588235 | L3: 0.81882353 | M3: 0.83294118
A4: % Có tải | B4: =$B7/SUM(B$7:B$9) -> 0.22466026 | C4: =$C7/SUM(C$7:C$9) -> 0.34097363 | D4: =$D7/SUM(D$7:D$9) -> 0.24433168 | E4: =$E7/SUM(E$7:E$9) -> 0.20348126 | F4: =$F7/SUM(F$7:F$9) -> 0.30300161 | G4: =G7/SUM(G$7:G$9) -> 0.4919247 | H4: =H7/SUM(H$7:H$9) -> 0.55419031 | I4: =I7/SUM(I$7:I$9) -> 0.45992775 | J4: =J7/SUM(J$7:J$9) -> 0.59690364 | K4: =K7/SUM(K$7:K$9) -> 0.68356332 | L4: =L7/SUM(L$7:L$9) -> 0.49966534 | M4: =M7/SUM(M$7:M$9) -> 0.60626323
A5: % Không tải | B5: =$B8/SUM(B$7:B$9) -> 0.22927 | C5: =$C8/SUM(C$7:C$9) -> 0.28150925 | D5: =$D8/SUM(D$7:D$9) -> 0.37293198 | E5: =$E8/SUM(E$7:E$9) -> 0.13029696 | F5: =$F8/SUM(F$7:F$9) -> 0.35155889 | G5: =G8/SUM(G$7:G$9) -> 0.1890176 | H5: =H8/SUM(H$7:H$9) -> 0.43458317 | I5: =I8/SUM(I$7:I$9) -> 0.41825962 | J5: =J8/SUM(J$7:J$9) -> 0.37921411 | K5: =K8/SUM(K$7:K$9) -> 0.051997552 | L5: =L8/SUM(L$7:L$9) -> 0.31088015 | M5: =M8/SUM(M$7:M$9) -> 0.17090159
A6: % Tắt máy | B6: =$B9/SUM(B$7:B$9) -> 0.54606974 | C6: =$C9/SUM(C$7:C$9) -> 0.37751712 | D6: =$D9/SUM(D$7:D$9) -> 0.38273634 | E6: =$E9/SUM(E$7:E$9) -> 0.66622178 | F6: =$F9/SUM(F$7:F$9) -> 0.3454395 | G6: =G9/SUM(G$7:G$9) -> 0.3190577 | H6: =H9/SUM(H$7:H$9) -> 0.011226514 | I6: =I9/SUM(I$7:I$9) -> 0.12181263 | J6: =J9/SUM(J$7:J$9) -> 0.023882255 | K6: =K9/SUM(K$7:K$9) -> 0.26443913 | L6: =L9/SUM(L$7:L$9) -> 0.1894545 | M6: =M9/SUM(M$7:M$9) -> 0.22283517
A7: Tổng thời gian h/đ có tải | B7: =SUM(LA!$E$2:$E$53) -> 12184 | C7: =SUM(MA!$E$2:$E$53) -> 18372 | D7: =SUM(BJ!$E$2:$E$53) -> 22005 | E7: =SUM(GC!$E$2:$E$53) -> 7318 | F7: =SUM(GS!$E$2:$E$53) -> 38077 | G7: =SUM(GR!$E$2:$E$53) -> 17666 | H7: =SUM(EN!$E$2:$E$53) -> 40232 | I7: =SUM(GJ!$E$2:$E$53) -> 13113 | J7: =SUM(EW!$E$2:$E$53) -> 42989 | K7: =SUM(GP!$E$2:$E$53) -> 24570 | L7: =SUM(MC!$E$2:$E$53) -> 26875 | M7: =SUM(LN!$E$2:$E$53) -> 21760
A8: Tổng thời gian h/đ không tải | B8: =SUM(LA!$D$2:$D$53) -> 12434 | C8: =SUM(MA!$D$2:$D$53) -> 15168 | D8: =SUM(BJ!$D$2:$D$53) -> 33587 | E8: =SUM(GC!$D$2:$D$53) -> 4686 | F8: =SUM(GS!$D$2:$D$53) -> 44179 | G8: =SUM(GR!$D$2:$D$53) -> 6788 | H8: =SUM(EN!$D$2:$D$53) -> 31549 | I8: =SUM(GJ!$D$2:$D$53) -> 11925 | J8: =SUM(EW!$D$2:$D$53) -> 27311 | K8: =SUM(GP!$D$2:$D$53) -> 1869 | L8: =SUM(MC!$D$2:$D$53) -> 16721 | M8: =SUM(LN!$D$2:$D$53) -> 6134
A9: Tổng thời gian tắt máy | B9: =SUM(LA!$F$2:$F$53) -> 29615 | C9: =SUM(MA!$F$2:$F$53) -> 20341 | D9: =SUM(BJ!$F$2:$F$53) -> 34470 | E9: =SUM(GC!$F$2:$F$53) -> 23960 | F9: =SUM(GS!$F$2:$F$53) -> 43410 | G9: =SUM(GR!$F$2:$F$53) -> 11458 | H9: =SUM(EN!$F$2:$F$53) -> 815 | I9: =SUM(GJ!$F$2:$F$53) -> 3473 | J9: =SUM(EW!$F$2:$F$53) -> 1720 | K9: =SUM(GP!$F$2:$F$53) -> 9505 | L9: =SUM(MC!$F$2:$F$53) -> 10190 | M9: =SUM(LN!$F$2:$F$53) -> 7998

Sheet EN
A1: ID | B1: Ngày tháng | C1: Ca làm việc | D1: Thời gian hoạt động không tải (phút) | E1: Thời gian hoạt động có tải (phút) | F1: Thời gian tắt máy (phút) | H1: Ngày - Ca | I1: Mục Tiêu C1 | J1: Mục Tiêu C2 | K1: % Có Tải | L1: % Không Tải | M1: % Tắt Máy | O1: ID | P1: Ngày tháng | Q1: Ca làm việc | R1: Thời gian hoạt động không tải (phút) | S1: Thời gian hoạt động có tải (phút) | T1: Thời gian tắt máy (phút)
A2: 1 | B2: 01/06/2026 | C2: CN | D2: 718 | E2: 1371 | F2: 802 | H2: T1 | I2: 0.73411765 | J2: 0.72252632 | K2: =IFERROR(SUMIFS(S:S,P:P,"*/01/2026")/(SUMIFS(R:R,P:P,"*/01/2026")+SUMIFS(S:S,P:P,"*/01/2026")+SUMIFS(T:T,P:P,"*/01/2026")),"") -> 0.45989746 | L2: =IFERROR(SUMIFS(R:R,P:P,"*/01/2026")/(SUMIFS(R:R,P:P,"*/01/2026")+SUMIFS(S:S,P:P,"*/01/2026")+SUMIFS(T:T,P:P,"*/01/2026")),"") -> 0.38261494 | M2: =IFERROR(SUMIFS(T:T,P:P,"*/01/2026")/(SUMIFS(R:R,P:P,"*/01/2026")+SUMIFS(S:S,P:P,"*/01/2026")+SUMIFS(T:T,P:P,"*/01/2026")),"") -> 0.1574876 | O2: 1 | P2: 01/01/2026 | Q2: CN | R2: 0 | S2: 0 | T2: 2880
A3: 2 | B3: 01/06/2026 | C3: CD | D3: 864 | E3: 2046 | F3: 0 | H3: T2 | I3: 0.73411765 | J3: 0.72252632 | K3: =IFERROR(SUMIFS(S:S,P:P,"*/02/2026")/(SUMIFS(R:R,P:P,"*/02/2026")+SUMIFS(S:S,P:P,"*/02/2026")+SUMIFS(T:T,P:P,"*/02/2026")),"") -> 0.34446557 | L3: =IFERROR(SUMIFS(R:R,P:P,"*/02/2026")/(SUMIFS(R:R,P:P,"*/02/2026")+SUMIFS(S:S,P:P,"*/02/2026")+SUMIFS(T:T,P:P,"*/02/2026")),"") -> 0.26050166 | M3: =IFERROR(SUMIFS(T:T,P:P,"*/02/2026")/(SUMIFS(R:R,P:P,"*/02/2026")+SUMIFS(S:S,P:P,"*/02/2026")+SUMIFS(T:T,P:P,"*/02/2026")),"") -> 0.39503277 | O3: 2 | P3: 01/01/2026 | Q3: CD | R3: 257 | S3: 5 | T3: 2614
A4: 3 | B4: 02/06/2026 | C4: CN | D4: 888 | E4: 2017 | F4: 0 | H4: T3 | I4: 0.73411765 | J4: 0.72252632 | K4: =IFERROR(SUMIFS(S:S,P:P,"*/03/2026")/(SUMIFS(R:R,P:P,"*/03/2026")+SUMIFS(S:S,P:P,"*/03/2026")+SUMIFS(T:T,P:P,"*/03/2026")),"") -> 0.50857608 | L4: =IFERROR(SUMIFS(R:R,P:P,"*/03/2026")/(SUMIFS(R:R,P:P,"*/03/2026")+SUMIFS(S:S,P:P,"*/03/2026")+SUMIFS(T:T,P:P,"*/03/2026")),"") -> 0.39620043 | M4: =IFERROR(SUMIFS(T:T,P:P,"*/03/2026")/(SUMIFS(R:R,P:P,"*/03/2026")+SUMIFS(S:S,P:P,"*/03/2026")+SUMIFS(T:T,P:P,"*/03/2026")),"") -> 0.095223491 | O4: 3 | P4: 02/01/2026 | Q4: CN | R4: 1188 | S4: 1721 | T4: 0
A5: 4 | B5: 02/06/2026 | C5: CD | D5: 965 | E5: 1938 | F5: 0 | H5: T4 | I5: 0.73411765 | J5: 0.72252632 | K5: =IFERROR(SUMIFS(S:S,P:P,"*/04/2026")/(SUMIFS(R:R,P:P,"*/04/2026")+SUMIFS(S:S,P:P,"*/04/2026")+SUMIFS(T:T,P:P,"*/04/2026")),"") -> 0.49145343 | L5: =IFERROR(SUMIFS(R:R,P:P,"*/04/2026")/(SUMIFS(R:R,P:P,"*/04/2026")+SUMIFS(S:S,P:P,"*/04/2026")+SUMIFS(T:T,P:P,"*/04/2026")),"") -> 0.38246891 | M5: =IFERROR(SUMIFS(T:T,P:P,"*/04/2026")/(SUMIFS(R:R,P:P,"*/04/2026")+SUMIFS(S:S,P:P,"*/04/2026")+SUMIFS(T:T,P:P,"*/04/2026")),"") -> 0.12607766 | O5: 4 | P5: 02/01/2026 | Q5: CD | R5: 1075 | S5: 1397 | T5: 435
A6: 5 | B6: 03/06/2026 | C6: CN | D6: 1800 | E6: 1128 | F6: 0 | H6: T5 | I6: 0.73411765 | J6: 0.72252632 | K6: =IFERROR(SUMIFS(S:S,P:P,"*/05/2026")/(SUMIFS(R:R,P:P,"*/05/2026")+SUMIFS(S:S,P:P,"*/05/2026")+SUMIFS(T:T,P:P,"*/05/2026")),"") -> 0.43639133 | L6: =IFERROR(SUMIFS(R:R,P:P,"*/05/2026")/(SUMIFS(R:R,P:P,"*/05/2026")+SUMIFS(S:S,P:P,"*/05/2026")+SUMIFS(T:T,P:P,"*/05/2026")),"") -> 0.41059209 | M6: =IFERROR(SUMIFS(T:T,P:P,"*/05/2026")/(SUMIFS(R:R,P:P,"*/05/2026")+SUMIFS(S:S,P:P,"*/05/2026")+SUMIFS(T:T,P:P,"*/05/2026")),"") -> 0.15301658 | O6: 5 | P6: 03/01/2026 | Q6: CD | R6: 1228 | S6: 3109 | T6: 374
A7: 6 | B7: 03/06/2026 | C7: CD | D7: 1123 | E7: 1788 | F7: 0 | H7: T6 | I7: 0.73411765 | J7: 0.72252632 | K7: =IFERROR(SUMIFS(S:S,P:P,"*/06/2026")/(SUMIFS(R:R,P:P,"*/06/2026")+SUMIFS(S:S,P:P,"*/06/2026")+SUMIFS(T:T,P:P,"*/06/2026")),"") -> 0.55419031 | L7: =IFERROR(SUMIFS(R:R,P:P,"*/06/2026")/(SUMIFS(R:R,P:P,"*/06/2026")+SUMIFS(S:S,P:P,"*/06/2026")+SUMIFS(T:T,P:P,"*/06/2026")),"") -> 0.43458317 | M7: =IFERROR(SUMIFS(T:T,P:P,"*/06/2026")/(SUMIFS(R:R,P:P,"*/06/2026")+SUMIFS(S:S,P:P,"*/06/2026")+SUMIFS(T:T,P:P,"*/06/2026")),"") -> 0.011226514 | O7: 6 | P7: 04/01/2026 | Q7: CN | R7: 33 | S7: 696 | T7: 2160
A8: 7 | B8: 04/06/2026 | C8: CN | D8: 1651 | E8: 1246 | F8: 0 | H8: T7 | I8: 0.73411765 | J8: 0.72252632 | K8: =IFERROR(SUMIFS(S:S,P:P,"*/07/2026")/(SUMIFS(R:R,P:P,"*/07/2026")+SUMIFS(S:S,P:P,"*/07/2026")+SUMIFS(T:T,P:P,"*/07/2026")),"") | L8: =IFERROR(SUMIFS(R:R,P:P,"*/07/2026")/(SUMIFS(R:R,P:P,"*/07/2026")+SUMIFS(S:S,P:P,"*/07/2026")+SUMIFS(T:T,P:P,"*/07/2026")),"") | M8: =IFERROR(SUMIFS(T:T,P:P,"*/07/2026")/(SUMIFS(R:R,P:P,"*/07/2026")+SUMIFS(S:S,P:P,"*/07/2026")+SUMIFS(T:T,P:P,"*/07/2026")),"") | O8: 7 | P8: 04/01/2026 | Q8: CD | R8: 455 | S8: 268 | T8: 2160
A9: 8 | B9: 04/06/2026 | C9: CD | D9: 1363 | E9: 1559 | F9: 0 | H9: T8 | I9: 0.73411765 | J9: 0.72252632 | K9: =IFERROR(SUMIFS(S:S,P:P,"*/08/2026")/(SUMIFS(R:R,P:P,"*/08/2026")+SUMIFS(S:S,P:P,"*/08/2026")+SUMIFS(T:T,P:P,"*/08/2026")),"") | L9: =IFERROR(SUMIFS(R:R,P:P,"*/08/2026")/(SUMIFS(R:R,P:P,"*/08/2026")+SUMIFS(S:S,P:P,"*/08/2026")+SUMIFS(T:T,P:P,"*/08/2026")),"") | M9: =IFERROR(SUMIFS(T:T,P:P,"*/08/2026")/(SUMIFS(R:R,P:P,"*/08/2026")+SUMIFS(S:S,P:P,"*/08/2026")+SUMIFS(T:T,P:P,"*/08/2026")),"") | O9: 8 | P9: 05/01/2026 | Q9: CN | R9: 987 | S9: 1330 | T9: 574
A10: 9 | B10: 05/06/2026 | C10: CN | D10: 1213 | E10: 1686 | F10: 0 | H10: T9 | I10: 0.73411765 | J10: 0.72252632 | K10: =IFERROR(SUMIFS(S:S,P:P,"*/09/2026")/(SUMIFS(R:R,P:P,"*/09/2026")+SUMIFS(S:S,P:P,"*/09/2026")+SUMIFS(T:T,P:P,"*/09/2026")),"") | L10: =IFERROR(SUMIFS(R:R,P:P,"*/09/2026")/(SUMIFS(R:R,P:P,"*/09/2026")+SUMIFS(S:S,P:P,"*/09/2026")+SUMIFS(T:T,P:P,"*/09/2026")),"") | M10: =IFERROR(SUMIFS(T:T,P:P,"*/09/2026")/(SUMIFS(R:R,P:P,"*/09/2026")+SUMIFS(S:S,P:P,"*/09/2026")+SUMIFS(T:T,P:P,"*/09/2026")),"") | O10: 9 | P10: 05/01/2026 | Q10: CD | R10: 1385 | S10: 1481 | T10: 0
A11: 10 | B11: 05/06/2026 | C11: CD | D11: 1171 | E11: 1740 | F11: 0 | H11: T10 | I11: 0.73411765 | J11: 0.72252632 | K11: =IFERROR(SUMIFS(S:S,P:P,"*/10/2026")/(SUMIFS(R:R,P:P,"*/10/2026")+SUMIFS(S:S,P:P,"*/10/2026")+SUMIFS(T:T,P:P,"*/10/2026")),"") | L11: =IFERROR(SUMIFS(R:R,P:P,"*/10/2026")/(SUMIFS(R:R,P:P,"*/10/2026")+SUMIFS(S:S,P:P,"*/10/2026")+SUMIFS(T:T,P:P,"*/10/2026")),"") | M11: =IFERROR(SUMIFS(T:T,P:P,"*/10/2026")/(SUMIFS(R:R,P:P,"*/10/2026")+SUMIFS(S:S,P:P,"*/10/2026")+SUMIFS(T:T,P:P,"*/10/2026")),"") | O11: 10 | P11: 06/01/2026 | Q11: CN | R11: 1460 | S11: 1428 | T11: 0
A12: 11 | B12: 06/06/2026 | C12: CN | D12: 1575 | E12: 1323 | F12: 0 | H12: T11 | I12: 0.73411765 | J12: 0.72252632 | K12: =IFERROR(SUMIFS(S:S,P:P,"*/11/2026")/(SUMIFS(R:R,P:P,"*/11/2026")+SUMIFS(S:S,P:P,"*/11/2026")+SUMIFS(T:T,P:P,"*/11/2026")),"") | L12: =IFERROR(SUMIFS(R:R,P:P,"*/11/2026")/(SUMIFS(R:R,P:P,"*/11/2026")+SUMIFS(S:S,P:P,"*/11/2026")+SUMIFS(T:T,P:P,"*/11/2026")),"") | M12: =IFERROR(SUMIFS(T:T,P:P,"*/11/2026")/(SUMIFS(R:R,P:P,"*/11/2026")+SUMIFS(S:S,P:P,"*/11/2026")+SUMIFS(T:T,P:P,"*/11/2026")),"") | O12: 11 | P12: 06/01/2026 | Q12: CD | R12: 1269 | S12: 1625 | T12: 0
A13: 12 | B13: 06/06/2026 | C13: CD | D13: 1333 | E13: 1562 | F13: 0 | H13: T12 | I13: 0.73411765 | J13: 0.72252632 | K13: =IFERROR(SUMIFS(S:S,P:P,"*/12/2026")/(SUMIFS(R:R,P:P,"*/12/2026")+SUMIFS(S:S,P:P,"*/12/2026")+SUMIFS(T:T,P:P,"*/12/2026")),"") | L13: =IFERROR(SUMIFS(R:R,P:P,"*/12/2026")/(SUMIFS(R:R,P:P,"*/12/2026")+SUMIFS(S:S,P:P,"*/12/2026")+SUMIFS(T:T,P:P,"*/12/2026")),"") | M13: =IFERROR(SUMIFS(T:T,P:P,"*/12/2026")/(SUMIFS(R:R,P:P,"*/12/2026")+SUMIFS(S:S,P:P,"*/12/2026")+SUMIFS(T:T,P:P,"*/12/2026")),"") | O13: 12 | P13: 07/01/2026 | Q13: CN | R13: 1074 | S13: 311 | T13: 1495
A14: 13 | B14: 07/06/2026 | C14: CN | D14: 1498 | E14: 1412 | F14: 0 | H14: =IF(B2="","",TEXT(B2,"dd/mm")& "-" &IF(UPPER(TRIM(C2))="CN",1,IF(UPPER(TRIM(C2))="CD",2,""))) -> 01/06-1 | I14: 0.73411765 | J14: 0.72252632 | K14: =IFERROR($E2/SUM($D2:$F2),"") -> 0.47423037 | L14: =IFERROR($D2/SUM($D2:$F2),"") -> 0.24835697 | M14: =IFERROR($F2/SUM($D2:$F2),"") -> 0.27741266 | O14: 13 | P14: 07/01/2026 | Q14: CD | R14: 0 | S14: 0 | T14: 2880
A15: 14 | B15: 07/06/2026 | C15: CD | D15: 2601 | E15: 280 | F15: 0 | H15: =IF(B3="","",TEXT(B3,"dd/mm") & "-" & IF(UPPER(TRIM(C3))="CN",1,IF(UPPER(TRIM(C3))="CD",2,""))) -> 01/06-2 | I15: 0.73411765 | J15: 0.72252632 | K15: =IFERROR($E3/SUM($D3:$F3),"") -> 0.70309278 | L15: =IFERROR($D3/SUM($D3:$F3),"") -> 0.29690722 | M15: =IFERROR($F3/SUM($D3:$F3),"") -> 0 | O15: 14 | P15: 08/01/2026 | Q15: CN | R15: 586 | S15: 1499 | T15: 811
A16: 15 | B16: 08/06/2026 | C16: CN | D16: 1743 | E16: 1167 | F16: 0 | H16: =IF(B4="","",TEXT(B4,"dd/mm") & "-" & IF(UPPER(TRIM(C4))="CN",1,IF(UPPER(TRIM(C4))="CD",2,""))) -> 02/06-1 | I16: 0.73411765 | J16: 0.72252632 | K16: =IFERROR($E4/SUM($D4:$F4),"") -> 0.69432014 | L16: =IFERROR($D4/SUM($D4:$F4),"") -> 0.30567986 | M16: =IFERROR($F4/SUM($D4:$F4),"") -> 0 | O16: 15 | P16: 08/01/2026 | Q16: CD | R16: 1410 | S16: 1484 | T16: 0
A17: 16 | B17: 08/06/2026 | C17: CD | D17: 625 | E17: 2283 | F17: 0 | H17: =IF(B5="","",TEXT(B5,"dd/mm") & "-" & IF(UPPER(TRIM(C5))="CN",1,IF(UPPER(TRIM(C5))="CD",2,""))) -> 02/06-2 | I17: 0.73411765 | J17: 0.72252632 | K17: =IFERROR($E5/SUM($D5:$F5),"") -> 0.66758526 | L17: =IFERROR($D5/SUM($D5:$F5),"") -> 0.33241474 | M17: =IFERROR($F5/SUM($D5:$F5),"") -> 0 | O17: 16 | P17: 09/01/2026 | Q17: CN | R17: 1646 | S17: 1253 | T17: 0
A18: 17 | B18: 09/06/2026 | C18: CN | D18: 1138 | E18: 1774 | F18: 0 | H18: =IF(B6="","",TEXT(B6,"dd/mm") & "-" & IF(UPPER(TRIM(C6))="CN",1,IF(UPPER(TRIM(C6))="CD",2,""))) -> 03/06-1 | I18: 0.73411765 | J18: 0.72252632 | K18: =IFERROR($E6/SUM($D6:$F6),"") -> 0.3852459 | L18: =IFERROR($D6/SUM($D6:$F6),"") -> 0.6147541 | M18: =IFERROR($F6/SUM($D6:$F6),"") -> 0 | O18: 17 | P18: 09/01/2026 | Q18: CD | R18: 1282 | S18: 1607 | T18: 0
A19: 18 | B19: 09/06/2026 | C19: CD | D19: 1418 | E19: 1481 | F19: 0 | H19: =IF(B7="","",TEXT(B7,"dd/mm") & "-" & IF(UPPER(TRIM(C7))="CN",1,IF(UPPER(TRIM(C7))="CD",2,""))) -> 03/06-2 | I19: 0.73411765 | J19: 0.72252632 | K19: =IFERROR($E7/SUM($D7:$F7),"") -> 0.61422192 | L19: =IFERROR($D7/SUM($D7:$F7),"") -> 0.38577808 | M19: =IFERROR($F7/SUM($D7:$F7),"") -> 0 | O19: 18 | P19: 10/01/2026 | Q19: CN | R19: 1599 | S19: 1284 | T19: 7
A20: 19 | B20: 10/06/2026 | C20: CN | D20: 1337 | E20: 1577 | F20: 0 | H20: =IF(B8="","",TEXT(B8,"dd/mm") & "-" & IF(UPPER(TRIM(C8))="CN",1,IF(UPPER(TRIM(C8))="CD",2,""))) -> 04/06-1 | I20: 0.73411765 | J20: 0.72252632 | K20: =IFERROR($E8/SUM($D8:$F8),"") -> 0.4301001 | L20: =IFERROR($D8/SUM($D8:$F8),"") -> 0.5698999 | M20: =IFERROR($F8/SUM($D8:$F8),"") -> 0 | O20: 19 | P20: 10/01/2026 | Q20: CD | R20: 0 | S20: 97 | T20: 2782
A21: 20 | B21: 10/06/2026 | C21: CD | D21: 979 | E21: 1922 | F21: 0 | H21: =IF(B9="","",TEXT(B9,"dd/mm") & "-" & IF(UPPER(TRIM(C9))="CN",1,IF(UPPER(TRIM(C9))="CD",2,""))) -> 04/06-2 | I21: 0.73411765 | J21: 0.72252632 | K21: =IFERROR($E9/SUM($D9:$F9),"") -> 0.53353867 | L21: =IFERROR($D9/SUM($D9:$F9),"") -> 0.46646133 | M21: =IFERROR($F9/SUM($D9:$F9),"") -> 0 | O21: 20 | P21: 11/01/2026 | Q21: CN | R21: 0 | S21: 0 | T21: 2880
A22: 21 | B22: 11/06/2026 | C22: CN | D22: 1188 | E22: 1703 | F22: 0 | H22: =IF(B10="","",TEXT(B10,"dd/mm") & "-" & IF(UPPER(TRIM(C10))="CN",1,IF(UPPER(TRIM(C10))="CD",2,""))) -> 05/06-1 | I22: 0.73411765 | J22: 0.72252632 | K22: =IFERROR($E10/SUM($D10:$F10),"") -> 0.58157986 | L22: =IFERROR($D10/SUM($D10:$F10),"") -> 0.41842014 | M22: =IFERROR($F10/SUM($D10:$F10),"") -> 0 | O22: 21 | P22: 11/01/2026 | Q22: CD | R22: 0 | S22: 0 | T22: 2880
A23: 22 | B23: 11/06/2026 | C23: CD | D23: 1183 | E23: 1732 | F23: 0 | H23: =IF(B11="","",TEXT(B11,"dd/mm") & "-" & IF(UPPER(TRIM(C11))="CN",1,IF(UPPER(TRIM(C11))="CD",2,""))) -> 05/06-2 | I23: 0.73411765 | J23: 0.72252632 | K23: =IFERROR($E11/SUM($D11:$F11),"") -> 0.59773274 | L23: =IFERROR($D11/SUM($D11:$F11),"") -> 0.40226726 | M23: =IFERROR($F11/SUM($D11:$F11),"") -> 0 | O23: 22 | P23: 12/01/2026 | Q23: CN | R23: 694 | S23: 1337 | T23: 862
A24: 23 | B24: 12/06/2026 | C24: CN | D24: 1394 | E24: 1502 | F24: 0 | H24: =IF(B12="","",TEXT(B12,"dd/mm") & "-" & IF(UPPER(TRIM(C12))="CN",1,IF(UPPER(TRIM(C12))="CD",2,""))) -> 06/06-1 | I24: 0.73411765 | J24: 0.72252632 | K24: =IFERROR($E12/SUM($D12:$F12),"") -> 0.45652174 | L24: =IFERROR($D12/SUM($D12:$F12),"") -> 0.54347826 | M24: =IFERROR($F12/SUM($D12:$F12),"") -> 0 | O24: 23 | P24: 12/01/2026 | Q24: CD | R24: 1354 | S24: 1549 | T24: 0
A25: 24 | B25: 12/06/2026 | C25: CD | D25: 674 | E25: 2224 | F25: 0 | H25: =IF(B13="","",TEXT(B13,"dd/mm") & "-" & IF(UPPER(TRIM(C13))="CN",1,IF(UPPER(TRIM(C13))="CD",2,""))) -> 06/06-2 | I25: 0.73411765 | J25: 0.72252632 | K25: =IFERROR($E13/SUM($D13:$F13),"") -> 0.53955095 | L25: =IFERROR($D13/SUM($D13:$F13),"") -> 0.46044905 | M25: =IFERROR($F13/SUM($D13:$F13),"") -> 0 | O25: 24 | P25: 13/01/2026 | Q25: CN | R25: 1616 | S25: 1282 | T25: 0
A26: 25 | B26: 13/06/2026 | C26: CN | D26: 1107 | E26: 1771 | F26: 13 | H26: =IF(B14="","",TEXT(B14,"dd/mm") & "-" & IF(UPPER(TRIM(C14))="CN",1,IF(UPPER(TRIM(C14))="CD",2,""))) -> 07/06-1 | I26: 0.73411765 | J26: 0.72252632 | K26: =IFERROR($E14/SUM($D14:$F14),"") -> 0.48522337 | L26: =IFERROR($D14/SUM($D14:$F14),"") -> 0.51477663 | M26: =IFERROR($F14/SUM($D14:$F14),"") -> 0 | O26: 25 | P26: 13/01/2026 | Q26: CD | R26: 1074 | S26: 1818 | T26: 0
H27: =IF(B15="","",TEXT(B15,"dd/mm") & "-" & IF(UPPER(TRIM(C15))="CN",1,IF(UPPER(TRIM(C15))="CD",2,""))) -> 07/06-2 | I27: 0.73411765 | J27: 0.72252632 | K27: =IFERROR($E15/SUM($D15:$F15),"") -> 0.097188476 | L27: =IFERROR($D15/SUM($D15:$F15),"") -> 0.90281152 | M27: =IFERROR($F15/SUM($D15:$F15),"") -> 0 | O27: 26 | P27: 14/01/2026 | Q27: CN | R27: 1437 | S27: 1462 | T27: 0
H28: =IF(B16="","",TEXT(B16,"dd/mm") & "-" & IF(UPPER(TRIM(C16))="CN",1,IF(UPPER(TRIM(C16))="CD",2,""))) -> 08/06-1 | I28: 0.73411765 | J28: 0.72252632 | K28: =IFERROR($E16/SUM($D16:$F16),"") -> 0.40103093 | L28: =IFERROR($D16/SUM($D16:$F16),"") -> 0.59896907 | M28: =IFERROR($F16/SUM($D16:$F16),"") -> 0 | O28: 27 | P28: 14/01/2026 | Q28: CD | R28: 834 | S28: 2054 | T28: 0
H29: =IF(B17="","",TEXT(B17,"dd/mm") & "-" & IF(UPPER(TRIM(C17))="CN",1,IF(UPPER(TRIM(C17))="CD",2,""))) -> 08/06-2 | I29: 0.73411765 | J29: 0.72252632 | K29: =IFERROR($E17/SUM($D17:$F17),"") -> 0.78507565 | L29: =IFERROR($D17/SUM($D17:$F17),"") -> 0.21492435 | M29: =IFERROR($F17/SUM($D17:$F17),"") -> 0 | O29: 28 | P29: 15/01/2026 | Q29: CN | R29: 1399 | S29: 1499 | T29: 0
H30: =IF(B18="","",TEXT(B18,"dd/mm") & "-" & IF(UPPER(TRIM(C18))="CN",1,IF(UPPER(TRIM(C18))="CD",2,""))) -> 09/06-1 | I30: 0.73411765 | J30: 0.72252632 | K30: =IFERROR($E18/SUM($D18:$F18),"") -> 0.6092033 | L30: =IFERROR($D18/SUM($D18:$F18),"") -> 0.3907967 | M30: =IFERROR($F18/SUM($D18:$F18),"") -> 0 | O30: 29 | P30: 15/01/2026 | Q30: CD | R30: 998 | S30: 1898 | T30: 0
H31: =IF(B19="","",TEXT(B19,"dd/mm") & "-" & IF(UPPER(TRIM(C19))="CN",1,IF(UPPER(TRIM(C19))="CD",2,""))) -> 09/06-2 | I31: 0.73411765 | J31: 0.72252632 | K31: =IFERROR($E19/SUM($D19:$F19),"") -> 0.51086582 | L31: =IFERROR($D19/SUM($D19:$F19),"") -> 0.48913418 | M31: =IFERROR($F19/SUM($D19:$F19),"") -> 0 | O31: 30 | P31: 16/01/2026 | Q31: CN | R31: 1790 | S31: 1100 | T31: 0
H32: =IF(B20="","",TEXT(B20,"dd/mm") & "-" & IF(UPPER(TRIM(C20))="CN",1,IF(UPPER(TRIM(C20))="CD",2,""))) -> 10/06-1 | I32: 0.73411765 | J32: 0.72252632 | K32: =IFERROR($E20/SUM($D20:$F20),"") -> 0.54118051 | L32: =IFERROR($D20/SUM($D20:$F20),"") -> 0.45881949 | M32: =IFERROR($F20/SUM($D20:$F20),"") -> 0 | O32: 31 | P32: 16/01/2026 | Q32: CD | R32: 933 | S32: 1974 | T32: 0
H33: =IF(B21="","",TEXT(B21,"dd/mm") & "-" & IF(UPPER(TRIM(C21))="CN",1,IF(UPPER(TRIM(C21))="CD",2,""))) -> 10/06-2 | I33: 0.73411765 | J33: 0.72252632 | K33: =IFERROR($E21/SUM($D21:$F21),"") -> 0.66253016 | L33: =IFERROR($D21/SUM($D21:$F21),"") -> 0.33746984 | M33: =IFERROR($F21/SUM($D21:$F21),"") -> 0 | O33: 32 | P33: 17/01/2026 | Q33: CN | R33: 1191 | S33: 1706 | T33: 0
H34: =IF(B22="","",TEXT(B22,"dd/mm") & "-" & IF(UPPER(TRIM(C22))="CN",1,IF(UPPER(TRIM(C22))="CD",2,""))) -> 11/06-1 | I34: 0.73411765 | J34: 0.72252632 | K34: =IFERROR($E22/SUM($D22:$F22),"") -> 0.58906953 | L34: =IFERROR($D22/SUM($D22:$F22),"") -> 0.41093047 | M34: =IFERROR($F22/SUM($D22:$F22),"") -> 0 | O34: 33 | P34: 17/01/2026 | Q34: CD | R34: 989 | S34: 1898 | T34: 0
H35: =IF(B23="","",TEXT(B23,"dd/mm") & "-" & IF(UPPER(TRIM(C23))="CN",1,IF(UPPER(TRIM(C23))="CD",2,""))) -> 11/06-2 | I35: 0.73411765 | J35: 0.72252632 | K35: =IFERROR($E23/SUM($D23:$F23),"") -> 0.5941681 | L35: =IFERROR($D23/SUM($D23:$F23),"") -> 0.4058319 | M35: =IFERROR($F23/SUM($D23:$F23),"") -> 0 | O35: 34 | P35: 18/01/2026 | Q35: CN | R35: 1806 | S35: 1080 | T35: 0
H36: =IF(B24="","",TEXT(B24,"dd/mm") & "-" & IF(UPPER(TRIM(C24))="CN",1,IF(UPPER(TRIM(C24))="CD",2,""))) -> 12/06-1 | I36: 0.73411765 | J36: 0.72252632 | K36: =IFERROR($E24/SUM($D24:$F24),"") -> 0.51864641 | L36: =IFERROR($D24/SUM($D24:$F24),"") -> 0.48135359 | M36: =IFERROR($F24/SUM($D24:$F24),"") -> 0 | O36: 35 | P36: 18/01/2026 | Q36: CD | R36: 1326 | S36: 351 | T36: 1207
H37: =IF(B25="","",TEXT(B25,"dd/mm") & "-" & IF(UPPER(TRIM(C25))="CN",1,IF(UPPER(TRIM(C25))="CD",2,""))) -> 12/06-2 | I37: 0.73411765 | J37: 0.72252632 | K37: =IFERROR($E25/SUM($D25:$F25),"") -> 0.76742581 | L37: =IFERROR($D25/SUM($D25:$F25),"") -> 0.23257419 | M37: =IFERROR($F25/SUM($D25:$F25),"") -> 0 | O37: 36 | P37: 19/01/2026 | Q37: CN | R37: 1214 | S37: 1261 | T37: 410
H38: =IF(B26="","",TEXT(B26,"dd/mm") & "-" & IF(UPPER(TRIM(C26))="CN",1,IF(UPPER(TRIM(C26))="CD",2,""))) -> 13/06-1 | I38: 0.73411765 | J38: 0.72252632 | K38: =IFERROR($E26/SUM($D26:$F26),"") -> 0.6125908 | L38: =IFERROR($D26/SUM($D26:$F26),"") -> 0.38291249 | M38: =IFERROR($F26/SUM($D26:$F26),"") -> 0.0044967139 | O38: 37 | P38: 19/01/2026 | Q38: CD | R38: 993 | S38: 1905 | T38: 0
H39: =IF(B27="","",TEXT(B27,"dd/mm") & "-" & IF(UPPER(TRIM(C27))="CN",1,IF(UPPER(TRIM(C27))="CD",2,""))) | K39: =IFERROR($E27/SUM($D27:$F27),"") | L39: =IFERROR($D27/SUM($D27:$F27),"") | M39: =IFERROR($F27/SUM($D27:$F27),"") | O39: 38 | P39: 20/01/2026 | Q39: CN | R39: 1428 | S39: 1455 | T39: 0
H40: =IF(B28="","",TEXT(B28,"dd/mm") & "-" & IF(UPPER(TRIM(C28))="CN",1,IF(UPPER(TRIM(C28))="CD",2,""))) | K40: =IFERROR($E28/SUM($D28:$F28),"") | L40: =IFERROR($D28/SUM($D28:$F28),"") | M40: =IFERROR($F28/SUM($D28:$F28),"") | O40: 39 | P40: 20/01/2026 | Q40: CD | R40: 1355 | S40: 1531 | T40: 0
...

Sheet EW
A1: ID | B1: Ngày tháng | C1: Ca làm việc | D1: Thời gian hoạt động không tải (phút) | E1: Thời gian hoạt động có tải (phút) | F1: Thời gian tắt máy (phút) | H1: Ngày - Ca | I1: Mục Tiêu C1 | J1: Mục Tiêu C2 | K1: % Có Tải | L1: % Không Tải | M1: % Tắt Máy
A2: 1 | B2: 01/06/2026 | C2: CN | D2: 684 | E2: 1404 | F2: 794 | H2: T1 | I2: 0.81882353 | J2: 0.84252632 | K2: =IFERROR(SUMIFS(S:S,P:P,"*/01/2026")/(SUMIFS(R:R,P:P,"*/01/2026")+SUMIFS(S:S,P:P,"*/01/2026")+SUMIFS(T:T,P:P,"*/01/2026")),"") -> 0.53119717 | L2: =IFERROR(SUMIFS(R:R,P:P,"*/01/2026")/(SUMIFS(R:R,P:P,"*/01/2026")+SUMIFS(S:S,P:P,"*/01/2026")+SUMIFS(T:T,P:P,"*/01/2026")),"") -> 0.28754255 | M2: =IFERROR(SUMIFS(T:T,P:P,"*/01/2026")/(SUMIFS(R:R,P:P,"*/01/2026")+SUMIFS(S:S,P:P,"*/01/2026")+SUMIFS(T:T,P:P,"*/01/2026")),"") -> 0.18126028 | O2: 1 | P2: 01/01/2026 | Q2: CN | R2: 0 | S2: 0 | T2: 2880
A3: 2 | B3: 01/06/2026 | C3: CD | D3: 750 | E3: 2131 | F3: 0 | H3: T2 | I3: 0.81882353 | J3: 0.84252632 | K3: =IFERROR(SUMIFS(S:S,P:P,"*/02/2026")/(SUMIFS(R:R,P:P,"*/02/2026")+SUMIFS(S:S,P:P,"*/02/2026")+SUMIFS(T:T,P:P,"*/02/2026")),"") -> 0.39814005 | L3: =IFERROR(SUMIFS(R:R,P:P,"*/02/2026")/(SUMIFS(R:R,P:P,"*/02/2026")+SUMIFS(S:S,P:P,"*/02/2026")+SUMIFS(T:T,P:P,"*/02/2026")),"") -> 0.22337952 | M3: =IFERROR(SUMIFS(T:T,P:P,"*/02/2026")/(SUMIFS(R:R,P:P,"*/02/2026")+SUMIFS(S:S,P:P,"*/02/2026")+SUMIFS(T:T,P:P,"*/02/2026")),"") -> 0.37848042 | O3: 2 | P3: 01/01/2026 | Q3: CD | R3: 164 | S3: 136 | T3: 2575
A4: 3 | B4: 02/06/2026 | C4: CN | D4: 1194 | E4: 1687 | F4: 0 | H4: T3 | I4: 0.81882353 | J4: 0.84252632 | K4: =IFERROR(SUMIFS(S:S,P:P,"*/03/2026")/(SUMIFS(R:R,P:P,"*/03/2026")+SUMIFS(S:S,P:P,"*/03/2026")+SUMIFS(T:T,P:P,"*/03/2026")),"") -> 0.59869893 | L4: =IFERROR(SUMIFS(R:R,P:P,"*/03/2026")/(SUMIFS(R:R,P:P,"*/03/2026")+SUMIFS(S:S,P:P,"*/03/2026")+SUMIFS(T:T,P:P,"*/03/2026")),"") -> 0.30992345 | M4: =IFERROR(SUMIFS(T:T,P:P,"*/03/2026")/(SUMIFS(R:R,P:P,"*/03/2026")+SUMIFS(S:S,P:P,"*/03/2026")+SUMIFS(T:T,P:P,"*/03/2026")),"") -> 0.091377618 | O4: 3 | P4: 02/01/2026 | Q4: CN | R4: 832 | S4: 2051 | T4: 0
A5: 4 | B5: 02/06/2026 | C5: CD | D5: 975 | E5: 1910 | F5: 0 | H5: T4 | I5: 0.81882353 | J5: 0.84252632 | K5: =IFERROR(SUMIFS(S:S,P:P,"*/04/2026")/(SUMIFS(R:R,P:P,"*/04/2026")+SUMIFS(S:S,P:P,"*/04/2026")+SUMIFS(T:T,P:P,"*/04/2026")),"") -> 0.56341475 | L5: =IFERROR(SUMIFS(R:R,P:P,"*/04/2026")/(SUMIFS(R:R,P:P,"*/04/2026")+SUMIFS(S:S,P:P,"*/04/2026")+SUMIFS(T:T,P:P,"*/04/2026")),"") -> 0.34952158 | M5: =IFERROR(SUMIFS(T:T,P:P,"*/04/2026")/(SUMIFS(R:R,P:P,"*/04/2026")+SUMIFS(S:S,P:P,"*/04/2026")+SUMIFS(T:T,P:P,"*/04/2026")),"") -> 0.087063669 | O5: 4 | P5: 02/01/2026 | Q5: CD | R5: 505 | S5: 1021 | T5: 1351
A6: 5 | B6: 03/06/2026 | C6: CN | D6: 1536 | E6: 1343 | F6: 0 | H6: T5 | I6: 0.81882353 | J6: 0.84252632 | K6: =IFERROR(SUMIFS(S:S,P:P,"*/05/2026")/(SUMIFS(R:R,P:P,"*/05/2026")+SUMIFS(S:S,P:P,"*/05/2026")+SUMIFS(T:T,P:P,"*/05/2026")),"") -> 0.53236378 | L6: =IFERROR(SUMIFS(R:R,P:P,"*/05/2026")/(SUMIFS(R:R,P:P,"*/05/2026")+SUMIFS(S:S,P:P,"*/05/2026")+SUMIFS(T:T,P:P,"*/05/2026")),"") -> 0.41613539 | M6: =IFERROR(SUMIFS(T:T,P:P,"*/05/2026")/(SUMIFS(R:R,P:P,"*/05/2026")+SUMIFS(S:S,P:P,"*/05/2026")+SUMIFS(T:T,P:P,"*/05/2026")),"") -> 0.051500824 | O6: 5 | P6: 03/01/2026 | Q6: CD | R6: 908 | S6: 3127 | T6: 647
A7: 6 | B7: 03/06/2026 | C7: CD | D7: 828 | E7: 2055 | F7: 0 | H7: T6 | I7: 0.81882353 | J7: 0.84252632 | K7: =IFERROR(SUMIFS(S:S,P:P,"*/06/2026")/(SUMIFS(R:R,P:P,"*/06/2026")+SUMIFS(S:S,P:P,"*/06/2026")+SUMIFS(T:T,P:P,"*/06/2026")),"") -> 0.59690364 | L7: =IFERROR(SUMIFS(R:R,P:P,"*/06/2026")/(SUMIFS(R:R,P:P,"*/06/2026")+SUMIFS(S:S,P:P,"*/06/2026")+SUMIFS(T:T,P:P,"*/06/2026")),"") -> 0.37921411 | M7: =IFERROR(SUMIFS(T:T,P:P,"*/06/2026")/(SUMIFS(R:R,P:P,"*/06/2026")+SUMIFS(S:S,P:P,"*/06/2026")+SUMIFS(T:T,P:P,"*/06/2026")),"") -> 0.023882255 | O7: 6 | P7: 04/01/2026 | Q7: CN | R7: 0 | S7: 0 | T7: 2880
A8: 7 | B8: 04/06/2026 | C8: CN | D8: 1244 | E8: 1639 | F8: 0 | H8: T7 | I8: 0.81882353 | J8: 0.84252632 | K8: =IFERROR(SUMIFS(S:S,P:P,"*/07/2026")/(SUMIFS(R:R,P:P,"*/07/2026")+SUMIFS(S:S,P:P,"*/07/2026")+SUMIFS(T:T,P:P,"*/07/2026")),"") | L8: =IFERROR(SUMIFS(R:R,P:P,"*/07/2026")/(SUMIFS(R:R,P:P,"*/07/2026")+SUMIFS(S:S,P:P,"*/07/2026")+SUMIFS(T:T,P:P,"*/07/2026")),"") | M8: =IFERROR(SUMIFS(T:T,P:P,"*/07/2026")/(SUMIFS(R:R,P:P,"*/07/2026")+SUMIFS(S:S,P:P,"*/07/2026")+SUMIFS(T:T,P:P,"*/07/2026")),"") | O8: 7 | P8: 04/01/2026 | Q8: CD | R8: 0 | S8: 0 | T8: 2880
A9: 8 | B9: 04/06/2026 | C9: CD | D9: 1072 | E9: 1809 | F9: 0 | H9: T8 | I9: 0.81882353 | J9: 0.84252632 | K9: =IFERROR(SUMIFS(S:S,P:P,"*/08/2026")/(SUMIFS(R:R,P:P,"*/08/2026")+SUMIFS(S:S,P:P,"*/08/2026")+SUMIFS(T:T,P:P,"*/08/2026")),"") | L9: =IFERROR(SUMIFS(R:R,P:P,"*/08/2026")/(SUMIFS(R:R,P:P,"*/08/2026")+SUMIFS(S:S,P:P,"*/08/2026")+SUMIFS(T:T,P:P,"*/08/2026")),"") | M9: =IFERROR(SUMIFS(T:T,P:P,"*/08/2026")/(SUMIFS(R:R,P:P,"*/08/2026")+SUMIFS(S:S,P:P,"*/08/2026")+SUMIFS(T:T,P:P,"*/08/2026")),"") | O9: 8 | P9: 05/01/2026 | Q9: CN | R9: 423 | S9: 1670 | T9: 784
A10: 9 | B10: 05/06/2026 | C10: CN | D10: 1375 | E10: 1508 | F10: 0 | H10: T9 | I10: 0.81882353 | J10: 0.84252632 | K10: =IFERROR(SUMIFS(S:S,P:P,"*/09/2026")/(SUMIFS(R:R,P:P,"*/09/2026")+SUMIFS(S:S,P:P,"*/09/2026")+SUMIFS(T:T,P:P,"*/09/2026")),"") | L10: =IFERROR(SUMIFS(R:R,P:P,"*/09/2026")/(SUMIFS(R:R,P:P,"*/09/2026")+SUMIFS(S:S,P:P,"*/09/2026")+SUMIFS(T:T,P:P,"*/09/2026")),"") | M10: =IFERROR(SUMIFS(T:T,P:P,"*/09/2026")/(SUMIFS(R:R,P:P,"*/09/2026")+SUMIFS(S:S,P:P,"*/09/2026")+SUMIFS(T:T,P:P,"*/09/2026")),"") | O10: 9 | P10: 05/01/2026 | Q10: CD | R10: 615 | S10: 1983 | T10: 248
A11: 10 | B11: 05/06/2026 | C11: CD | D11: 712 | E11: 2170 | F11: 0 | H11: T10 | I11: 0.81882353 | J11: 0.84252632 | K11: =IFERROR(SUMIFS(S:S,P:P,"*/10/2026")/(SUMIFS(R:R,P:P,"*/10/2026")+SUMIFS(S:S,P:P,"*/10/2026")+SUMIFS(T:T,P:P,"*/10/2026")),"") | L11: =IFERROR(SUMIFS(R:R,P:P,"*/10/2026")/(SUMIFS(R:R,P:P,"*/10/2026")+SUMIFS(S:S,P:P,"*/10/2026")+SUMIFS(T:T,P:P,"*/10/2026")),"") | M11: =IFERROR(SUMIFS(T:T,P:P,"*/10/2026")/(SUMIFS(R:R,P:P,"*/10/2026")+SUMIFS(S:S,P:P,"*/10/2026")+SUMIFS(T:T,P:P,"*/10/2026")),"") | O11: 10 | P11: 06/01/2026 | Q11: CN | R11: 991 | S11: 1481 | T11: 409
A12: 11 | B12: 06/06/2026 | C12: CN | D12: 1190 | E12: 1689 | F12: 0 | H12: T11 | I12: 0.81882353 | J12: 0.84252632 | K12: =IFERROR(SUMIFS(S:S,P:P,"*/11/2026")/(SUMIFS(R:R,P:P,"*/11/2026")+SUMIFS(S:S,P:P,"*/11/2026")+SUMIFS(T:T,P:P,"*/11/2026")),"") | L12: =IFERROR(SUMIFS(R:R,P:P,"*/11/2026")/(SUMIFS(R:R,P:P,"*/11/2026")+SUMIFS(S:S,P:P,"*/11/2026")+SUMIFS(T:T,P:P,"*/11/2026")),"") | M12: =IFERROR(SUMIFS(T:T,P:P,"*/11/2026")/(SUMIFS(R:R,P:P,"*/11/2026")+SUMIFS(S:S,P:P,"*/11/2026")+SUMIFS(T:T,P:P,"*/11/2026")),"") | O12: 11 | P12: 06/01/2026 | Q12: CD | R12: 882 | S12: 2000 | T12: 0
A13: 12 | B13: 06/06/2026 | C13: CD | D13: 1306 | E13: 1573 | F13: 0 | H13: T12 | I13: 0.81882353 | J13: 0.84252632 | K13: =IFERROR(SUMIFS(S:S,P:P,"*/12/2026")/(SUMIFS(R:R,P:P,"*/12/2026")+SUMIFS(S:S,P:P,"*/12/2026")+SUMIFS(T:T,P:P,"*/12/2026")),"") | L13: =IFERROR(SUMIFS(R:R,P:P,"*/12/2026")/(SUMIFS(R:R,P:P,"*/12/2026")+SUMIFS(S:S,P:P,"*/12/2026")+SUMIFS(T:T,P:P,"*/12/2026")),"") | M13: =IFERROR(SUMIFS(T:T,P:P,"*/12/2026")/(SUMIFS(R:R,P:P,"*/12/2026")+SUMIFS(S:S,P:P,"*/12/2026")+SUMIFS(T:T,P:P,"*/12/2026")),"") | O13: 12 | P13: 07/01/2026 | Q13: CN | R13: 758 | S13: 642 | T13: 1475
A14: 13 | B14: 07/06/2026 | C14: CN | D14: 1430 | E14: 1441 | F14: 6 | H14: =IF(B2="","",TEXT(B2,"dd/mm")& "-" &IF(UPPER(TRIM(C2))="CN",1,IF(UPPER(TRIM(C2))="CD",2,""))) -> 01/06-1 | I14: 0.81882353 | J14: 0.84252632 | K14: =IFERROR($E2/SUM($D2:$F2),"") -> 0.48716169 | L14: =IFERROR($D2/SUM($D2:$F2),"") -> 0.23733518 | M14: =IFERROR($F2/SUM($D2:$F2),"") -> 0.27550312 | O14: 13 | P14: 07/01/2026 | Q14: CD | R14: 0 | S14: 0 | T14: 2880
A15: 14 | B15: 07/06/2026 | C15: CD | D15: 1946 | E15: 212 | F15: 720 | H15: =IF(B3="","",TEXT(B3,"dd/mm") & "-" & IF(UPPER(TRIM(C3))="CN",1,IF(UPPER(TRIM(C3))="CD",2,""))) -> 01/06-2 | I15: 0.81882353 | J15: 0.84252632 | K15: =IFERROR($E3/SUM($D3:$F3),"") -> 0.73967372 | L15: =IFERROR($D3/SUM($D3:$F3),"") -> 0.26032628 | M15: =IFERROR($F3/SUM($D3:$F3),"") -> 0 | O15: 14 | P15: 08/01/2026 | Q15: CN | R15: 524 | S15: 1542 | T15: 812
A16: 15 | B16: 08/06/2026 | C16: CN | D16: 1172 | E16: 1509 | F16: 200 | H16: =IF(B4="","",TEXT(B4,"dd/mm") & "-" & IF(UPPER(TRIM(C4))="CN",1,IF(UPPER(TRIM(C4))="CD",2,""))) -> 02/06-1 | I16: 0.81882353 | J16: 0.84252632 | K16: =IFERROR($E4/SUM($D4:$F4),"") -> 0.58556057 | L16: =IFERROR($D4/SUM($D4:$F4),"") -> 0.41443943 | M16: =IFERROR($F4/SUM($D4:$F4),"") -> 0 | O16: 15 | P16: 08/01/2026 | Q16: CD | R16: 945 | S16: 1938 | T16: 0
A17: 16 | B17: 08/06/2026 | C17: CD | D17: 495 | E17: 2385 | F17: 0 | H17: =IF(B5="","",TEXT(B5,"dd/mm") & "-" & IF(UPPER(TRIM(C5))="CN",1,IF(UPPER(TRIM(C5))="CD",2,""))) -> 02/06-2 | I17: 0.81882353 | J17: 0.84252632 | K17: =IFERROR($E5/SUM($D5:$F5),"") -> 0.66204506 | L17: =IFERROR($D5/SUM($D5:$F5),"") -> 0.33795494 | M17: =IFERROR($F5/SUM($D5:$F5),"") -> 0 | O17: 16 | P17: 09/01/2026 | Q17: CN | R17: 1363 | S17: 1517 | T17: 0
A18: 17 | B18: 09/06/2026 | C18: CN | D18: 1234 | E18: 1649 | F18: 0 | H18: =IF(B6="","",TEXT(B6,"dd/mm") & "-" & IF(UPPER(TRIM(C6))="CN",1,IF(UPPER(TRIM(C6))="CD",2,""))) -> 03/06-1 | I18: 0.81882353 | J18: 0.84252632 | K18: =IFERROR($E6/SUM($D6:$F6),"") -> 0.46648142 | L18: =IFERROR($D6/SUM($D6:$F6),"") -> 0.53351858 | M18: =IFERROR($F6/SUM($D6:$F6),"") -> 0 | O18: 17 | P18: 09/01/2026 | Q18: CD | R18: 1090 | S18: 1790 | T18: 0
A19: 18 | B19: 09/06/2026 | C19: CD | D19: 892 | E19: 1990 | F19: 0 | H19: =IF(B7="","",TEXT(B7,"dd/mm") & "-" & IF(UPPER(TRIM(C7))="CN",1,IF(UPPER(TRIM(C7))="CD",2,""))) -> 03/06-2 | I19: 0.81882353 | J19: 0.84252632 | K19: =IFERROR($E7/SUM($D7:$F7),"") -> 0.71279917 | L19: =IFERROR($D7/SUM($D7:$F7),"") -> 0.28720083 | M19: =IFERROR($F7/SUM($D7:$F7),"") -> 0 | O19: 18 | P19: 10/01/2026 | Q19: CN | R19: 1434 | S19: 1426 | T19: 16
A20: 19 | B20: 10/06/2026 | C20: CN | D20: 1250 | E20: 1630 | F20: 0 | H20: =IF(B8="","",TEXT(B8,"dd/mm") & "-" & IF(UPPER(TRIM(C8))="CN",1,IF(UPPER(TRIM(C8))="CD",2,""))) -> 04/06-1 | I20: 0.81882353 | J20: 0.84252632 | K20: =IFERROR($E8/SUM($D8:$F8),"") -> 0.56850503 | L20: =IFERROR($D8/SUM($D8:$F8),"") -> 0.43149497 | M20: =IFERROR($F8/SUM($D8:$F8),"") -> 0 | O20: 19 | P20: 10/01/2026 | Q20: CD | R20: 0 | S20: 0 | T20: 2880
A21: 20 | B21: 10/06/2026 | C21: CD | D21: 759 | E21: 2120 | F21: 0 | H21: =IF(B9="","",TEXT(B9,"dd/mm") & "-" & IF(UPPER(TRIM(C9))="CN",1,IF(UPPER(TRIM(C9))="CD",2,""))) -> 04/06-2 | I21: 0.81882353 | J21: 0.84252632 | K21: =IFERROR($E9/SUM($D9:$F9),"") -> 0.62790698 | L21: =IFERROR($D9/SUM($D9:$F9),"") -> 0.37209302 | M21: =IFERROR($F9/SUM($D9:$F9),"") -> 0 | O21: 20 | P21: 11/01/2026 | Q21: CN | R21: 0 | S21: 0 | T21: 2880
A22: 21 | B22: 11/06/2026 | C22: CN | D22: 1170 | E22: 1710 | F22: 0 | H22: =IF(B10="","",TEXT(B10,"dd/mm") & "-" & IF(UPPER(TRIM(C10))="CN",1,IF(UPPER(TRIM(C10))="CD",2,""))) -> 05/06-1 | I22: 0.81882353 | J22: 0.84252632 | K22: =IFERROR($E10/SUM($D10:$F10),"") -> 0.52306625 | L22: =IFERROR($D10/SUM($D10:$F10),"") -> 0.47693375 | M22: =IFERROR($F10/SUM($D10:$F10),"") -> 0 | O22: 21 | P22: 11/01/2026 | Q22: CD | R22: 0 | S22: 0 | T22: 2880
A23: 22 | B23: 11/06/2026 | C23: CD | D23: 640 | E23: 2239 | F23: 0 | H23: =IF(B11="","",TEXT(B11,"dd/mm") & "-" & IF(UPPER(TRIM(C11))="CN",1,IF(UPPER(TRIM(C11))="CD",2,""))) -> 05/06-2 | I23: 0.81882353 | J23: 0.84252632 | K23: =IFERROR($E11/SUM($D11:$F11),"") -> 0.75294934 | L23: =IFERROR($D11/SUM($D11:$F11),"") -> 0.24705066 | M23: =IFERROR($F11/SUM($D11:$F11),"") -> 0 | O23: 22 | P23: 12/01/2026 | Q23: CN | R23: 683 | S23: 1374 | T23: 824
A24: 23 | B24: 12/06/2026 | C24: CN | D24: 1230 | E24: 1650 | F24: 0 | H24: =IF(B12="","",TEXT(B12,"dd/mm") & "-" & IF(UPPER(TRIM(C12))="CN",1,IF(UPPER(TRIM(C12))="CD",2,""))) -> 06/06-1 | I24: 0.81882353 | J24: 0.84252632 | K24: =IFERROR($E12/SUM($D12:$F12),"") -> 0.58666204 | L24: =IFERROR($D12/SUM($D12:$F12),"") -> 0.41333796 | M24: =IFERROR($F12/SUM($D12:$F12),"") -> 0 | O24: 23 | P24: 12/01/2026 | Q24: CD | R24: 1084 | S24: 1796 | T24: 0
A25: 24 | B25: 12/06/2026 | C25: CD | D25: 897 | E25: 1985 | F25: 0 | H25: =IF(B13="","",TEXT(B13,"dd/mm") & "-" & IF(UPPER(TRIM(C13))="CN",1,IF(UPPER(TRIM(C13))="CD",2,""))) -> 06/06-2 | I25: 0.81882353 | J25: 0.84252632 | K25: =IFERROR($E13/SUM($D13:$F13),"") -> 0.54637027 | L25: =IFERROR($D13/SUM($D13:$F13),"") -> 0.45362973 | M25: =IFERROR($F13/SUM($D13:$F13),"") -> 0 | O25: 24 | P25: 13/01/2026 | Q25: CN | R25: 1197 | S25: 1684 | T25: 0
A26: 25 | B26: 13/06/2026 | C26: CN | D26: 1330 | E26: 1551 | F26: 0 | H26: =IF(B14="","",TEXT(B14,"dd/mm") & "-" & IF(UPPER(TRIM(C14))="CN",1,IF(UPPER(TRIM(C14))="CD",2,""))) -> 07/06-1 | I26: 0.81882353 | J26: 0.84252632 | K26: =IFERROR($E14/SUM($D14:$F14),"") -> 0.50086896 | L26: =IFERROR($D14/SUM($D14:$F14),"") -> 0.49704553 | M26: =IFERROR($F14/SUM($D14:$F14),"") -> 0.0020855057 | O26: 25 | P26: 13/01/2026 | Q26: CD | R26: 932 | S26: 1946 | T26: 4
H27: =IF(B15="","",TEXT(B15,"dd/mm") & "-" & IF(UPPER(TRIM(C15))="CN",1,IF(UPPER(TRIM(C15))="CD",2,""))) -> 07/06-2 | I27: 0.81882353 | J27: 0.84252632 | K27: =IFERROR($E15/SUM($D15:$F15),"") -> 0.073662265 | L27: =IFERROR($D15/SUM($D15:$F15),"") -> 0.676164 | M27: =IFERROR($F15/SUM($D15:$F15),"") -> 0.25017373 | O27: 26 | P27: 14/01/2026 | Q27: CN | R27: 1375 | S27: 1506 | T27: 0
H28: =IF(B16="","",TEXT(B16,"dd/mm") & "-" & IF(UPPER(TRIM(C16))="CN",1,IF(UPPER(TRIM(C16))="CD",2,""))) -> 08/06-1 | I28: 0.81882353 | J28: 0.84252632 | K28: =IFERROR($E16/SUM($D16:$F16),"") -> 0.52377647 | L28: =IFERROR($D16/SUM($D16:$F16),"") -> 0.40680319 | M28: =IFERROR($F16/SUM($D16:$F16),"") -> 0.06942034 | O28: 27 | P28: 14/01/2026 | Q28: CD | R28: 1219 | S28: 1663 | T28: 0
H29: =IF(B17="","",TEXT(B17,"dd/mm") & "-" & IF(UPPER(TRIM(C17))="CN",1,IF(UPPER(TRIM(C17))="CD",2,""))) -> 08/06-2 | I29: 0.81882353 | J29: 0.84252632 | K29: =IFERROR($E17/SUM($D17:$F17),"") -> 0.828125 | L29: =IFERROR($D17/SUM($D17:$F17),"") -> 0.171875 | M29: =IFERROR($F17/SUM($D17:$F17),"") -> 0 | O29: 28 | P29: 15/01/2026 | Q29: CN | R29: 1292 | S29: 1591 | T29: 0
H30: =IF(B18="","",TEXT(B18,"dd/mm") & "-" & IF(UPPER(TRIM(C18))="CN",1,IF(UPPER(TRIM(C18))="CD",2,""))) -> 09/06-1 | I30: 0.81882353 | J30: 0.84252632 | K30: =IFERROR($E18/SUM($D18:$F18),"") -> 0.57197364 | L30: =IFERROR($D18/SUM($D18:$F18),"") -> 0.42802636 | M30: =IFERROR($F18/SUM($D18:$F18),"") -> 0 | O30: 29 | P30: 15/01/2026 | Q30: CD | R30: 929 | S30: 1954 | T30: 0
H31: =IF(B19="","",TEXT(B19,"dd/mm") & "-" & IF(UPPER(TRIM(C19))="CN",1,IF(UPPER(TRIM(C19))="CD",2,""))) -> 09/06-2 | I31: 0.81882353 | J31: 0.84252632 | K31: =IFERROR($E19/SUM($D19:$F19),"") -> 0.69049271 | L31: =IFERROR($D19/SUM($D19:$F19),"") -> 0.30950729 | M31: =IFERROR($F19/SUM($D19:$F19),"") -> 0 | O31: 30 | P31: 16/01/2026 | Q31: CN | R31: 1165 | S31: 1718 | T31: 0
H32: =IF(B20="","",TEXT(B20,"dd/mm") & "-" & IF(UPPER(TRIM(C20))="CN",1,IF(UPPER(TRIM(C20))="CD",2,""))) -> 10/06-1 | I32: 0.81882353 | J32: 0.84252632 | K32: =IFERROR($E20/SUM($D20:$F20),"") -> 0.56597222 | L32: =IFERROR($D20/SUM($D20:$F20),"") -> 0.43402778 | M32: =IFERROR($F20/SUM($D20:$F20),"") -> 0 | O32: 31 | P32: 16/01/2026 | Q32: CD | R32: 1184 | S32: 1700 | T32: 0
H33: =IF(B21="","",TEXT(B21,"dd/mm") & "-" & IF(UPPER(TRIM(C21))="CN",1,IF(UPPER(TRIM(C21))="CD",2,""))) -> 10/06-2 | I33: 0.81882353 | J33: 0.84252632 | K33: =IFERROR($E21/SUM($D21:$F21),"") -> 0.73636679 | L33: =IFERROR($D21/SUM($D21:$F21),"") -> 0.26363321 | M33: =IFERROR($F21/SUM($D21:$F21),"") -> 0 | O33: 32 | P33: 17/01/2026 | Q33: CN | R33: 1127 | S33: 1753 | T33: 0
H34: =IF(B22="","",TEXT(B22,"dd/mm") & "-" & IF(UPPER(TRIM(C22))="CN",1,IF(UPPER(TRIM(C22))="CD",2,""))) -> 11/06-1 | I34: 0.81882353 | J34: 0.84252632 | K34: =IFERROR($E22/SUM($D22:$F22),"") -> 0.59375 | L34: =IFERROR($D22/SUM($D22:$F22),"") -> 0.40625 | M34: =IFERROR($F22/SUM($D22:$F22),"") -> 0 | O34: 33 | P34: 17/01/2026 | Q34: CD | R34: 545 | S34: 2333 | T34: 0
H35: =IF(B23="","",TEXT(B23,"dd/mm") & "-" & IF(UPPER(TRIM(C23))="CN",1,IF(UPPER(TRIM(C23))="CD",2,""))) -> 11/06-2 | I35: 0.81882353 | J35: 0.84252632 | K35: =IFERROR($E23/SUM($D23:$F23),"") -> 0.77770059 | L35: =IFERROR($D23/SUM($D23:$F23),"") -> 0.22229941 | M35: =IFERROR($F23/SUM($D23:$F23),"") -> 0 | O35: 34 | P35: 18/01/2026 | Q35: CN | R35: 1452 | S35: 1424 | T35: 0
H36: =IF(B24="","",TEXT(B24,"dd/mm") & "-" & IF(UPPER(TRIM(C24))="CN",1,IF(UPPER(TRIM(C24))="CD",2,""))) -> 12/06-1 | I36: 0.81882353 | J36: 0.84252632 | K36: =IFERROR($E24/SUM($D24:$F24),"") -> 0.57291667 | L36: =IFERROR($D24/SUM($D24:$F24),"") -> 0.42708333 | M36: =IFERROR($F24/SUM($D24:$F24),"") -> 0 | O36: 35 | P36: 18/01/2026 | Q36: CD | R36: 1571 | S36: 672 | T36: 634
H37: =IF(B25="","",TEXT(B25,"dd/mm") & "-" & IF(UPPER(TRIM(C25))="CN",1,IF(UPPER(TRIM(C25))="CD",2,""))) -> 12/06-2 | I37: 0.81882353 | J37: 0.84252632 | K37: =IFERROR($E25/SUM($D25:$F25),"") -> 0.68875781 | L37: =IFERROR($D25/SUM($D25:$F25),"") -> 0.31124219 | M37: =IFERROR($F25/SUM($D25:$F25),"") -> 0 | O37: 36 | P37: 19/01/2026 | Q37: CN | R37: 1003 | S37: 1656 | T37: 220
H38: =IF(B26="","",TEXT(B26,"dd/mm") & "-" & IF(UPPER(TRIM(C26))="CN",1,IF(UPPER(TRIM(C26))="CD",2,""))) -> 13/06-1 | I38: 0.81882353 | J38: 0.84252632 | K38: =IFERROR($E26/SUM($D26:$F26),"") -> 0.53835474 | L38: =IFERROR($D26/SUM($D26:$F26),"") -> 0.46164526 | M38: =IFERROR($F26/SUM($D26:$F26),"") -> 0 | O38: 37 | P38: 19/01/2026 | Q38: CD | R38: 674 | S38: 2207 | T38: 0
H39: =IF(B27="","",TEXT(B27,"dd/mm") & "-" & IF(UPPER(TRIM(C27))="CN",1,IF(UPPER(TRIM(C27))="CD",2,""))) | K39: =IFERROR($E27/SUM($D27:$F27),"") | L39: =IFERROR($D27/SUM($D27:$F27),"") | M39: =IFERROR($F27/SUM($D27:$F27),"") | O39: 38 | P39: 20/01/2026 | Q39: CN | R39: 1082 | S39: 1800 | T39: 0
H40: =IF(B28="","",TEXT(B28,"dd/mm") & "-" & IF(UPPER(TRIM(C28))="CN",1,IF(UPPER(TRIM(C28))="CD",2,""))) | K40: =IFERROR($E28/SUM($D28:$F28),"") | L40: =IFERROR($D28/SUM($D28:$F28),"") | M40: =IFERROR($F28/SUM($D28:$F28),"") | O40: 39 | P40: 20/01/2026 | Q40: CD | R40: 773 | S40: 2108 | T40: 0
...

Sheet GJ
A1: ID | B1: Ngày tháng | C1: Ca làm việc | D1: Thời gian hoạt động không tải (phút) | E1: Thời gian hoạt động có tải (phút) | F1: Thời gian tắt máy (phút) | H1: Ngày - Ca | I1: Mục Tiêu C1 | J1: Mục Tiêu C2 | K1: % Có Tải | L1: % Không Tải | M1: % Tắt Máy
A2: 1 | B2: 01/06/2026 | C2: CN | D2: 75 | E2: 441 | F2: 202 | H2: T1 | I2: 0.67764706 | J2: 0.66694737 | K2: =IFERROR(SUMIFS(S:S,P:P,"*/01/2026")/(SUMIFS(R:R,P:P,"*/01/2026")+SUMIFS(S:S,P:P,"*/01/2026")+SUMIFS(T:T,P:P,"*/01/2026")),"") -> 0.48270368 | L2: =IFERROR(SUMIFS(R:R,P:P,"*/01/2026")/(SUMIFS(R:R,P:P,"*/01/2026")+SUMIFS(S:S,P:P,"*/01/2026")+SUMIFS(T:T,P:P,"*/01/2026")),"") -> 0.376844 | M2: =IFERROR(SUMIFS(T:T,P:P,"*/01/2026")/(SUMIFS(R:R,P:P,"*/01/2026")+SUMIFS(S:S,P:P,"*/01/2026")+SUMIFS(T:T,P:P,"*/01/2026")),"") -> 0.14045233 | O2: 1 | P2: 01/01/2026 | Q2: CN | R2: 0 | S2: 0 | T2: 720
A3: 2 | B3: 01/06/2026 | C3: CD | D3: 343 | E3: 377 | F3: 0 | H3: T2 | I3: 0.67764706 | J3: 0.66694737 | K3: =IFERROR(SUMIFS(S:S,P:P,"*/02/2026")/(SUMIFS(R:R,P:P,"*/02/2026")+SUMIFS(S:S,P:P,"*/02/2026")+SUMIFS(T:T,P:P,"*/02/2026")),"") -> 0.41719428 | L3: =IFERROR(SUMIFS(R:R,P:P,"*/02/2026")/(SUMIFS(R:R,P:P,"*/02/2026")+SUMIFS(S:S,P:P,"*/02/2026")+SUMIFS(T:T,P:P,"*/02/2026")),"") -> 0.3093866 | M3: =IFERROR(SUMIFS(T:T,P:P,"*/02/2026")/(SUMIFS(R:R,P:P,"*/02/2026")+SUMIFS(S:S,P:P,"*/02/2026")+SUMIFS(T:T,P:P,"*/02/2026")),"") -> 0.27341912 | O3: 2 | P3: 01/01/2026 | Q3: CD | R3: 80 | S3: 41 | T3: 658
A4: 3 | B4: 02/06/2026 | C4: CN | D4: 304 | E4: 416 | F4: 0 | H4: T3 | I4: 0.67764706 | J4: 0.66694737 | K4: =IFERROR(SUMIFS(S:S,P:P,"*/03/2026")/(SUMIFS(R:R,P:P,"*/03/2026")+SUMIFS(S:S,P:P,"*/03/2026")+SUMIFS(T:T,P:P,"*/03/2026")),"") -> 0.36643715 | L4: =IFERROR(SUMIFS(R:R,P:P,"*/03/2026")/(SUMIFS(R:R,P:P,"*/03/2026")+SUMIFS(S:S,P:P,"*/03/2026")+SUMIFS(T:T,P:P,"*/03/2026")),"") -> 0.37231892 | M4: =IFERROR(SUMIFS(T:T,P:P,"*/03/2026")/(SUMIFS(R:R,P:P,"*/03/2026")+SUMIFS(S:S,P:P,"*/03/2026")+SUMIFS(T:T,P:P,"*/03/2026")),"") -> 0.26124394 | O4: 3 | P4: 02/01/2026 | Q4: CN | R4: 486 | S4: 954 | T4: 1
A5: 4 | B5: 02/06/2026 | C5: CD | D5: 276 | E5: 443 | F5: 0 | H5: T4 | I5: 0.67764706 | J5: 0.66694737 | K5: =IFERROR(SUMIFS(S:S,P:P,"*/04/2026")/(SUMIFS(R:R,P:P,"*/04/2026")+SUMIFS(S:S,P:P,"*/04/2026")+SUMIFS(T:T,P:P,"*/04/2026")),"") -> 0.43801561 | L5: =IFERROR(SUMIFS(R:R,P:P,"*/04/2026")/(SUMIFS(R:R,P:P,"*/04/2026")+SUMIFS(S:S,P:P,"*/04/2026")+SUMIFS(T:T,P:P,"*/04/2026")),"") -> 0.35510033 | M5: =IFERROR(SUMIFS(T:T,P:P,"*/04/2026")/(SUMIFS(R:R,P:P,"*/04/2026")+SUMIFS(S:S,P:P,"*/04/2026")+SUMIFS(T:T,P:P,"*/04/2026")),"") -> 0.20688406 | O5: 4 | P5: 02/01/2026 | Q5: CD | R5: 986 | S5: 453 | T5: 1
A6: 5 | B6: 03/06/2026 | C6: CN | D6: 338 | E6: 382 | F6: 0 | H6: T5 | I6: 0.67764706 | J6: 0.66694737 | K6: =IFERROR(SUMIFS(S:S,P:P,"*/05/2026")/(SUMIFS(R:R,P:P,"*/05/2026")+SUMIFS(S:S,P:P,"*/05/2026")+SUMIFS(T:T,P:P,"*/05/2026")),"") -> 0.40828035 | L6: =IFERROR(SUMIFS(R:R,P:P,"*/05/2026")/(SUMIFS(R:R,P:P,"*/05/2026")+SUMIFS(S:S,P:P,"*/05/2026")+SUMIFS(T:T,P:P,"*/05/2026")),"") -> 0.28403372 | M6: =IFERROR(SUMIFS(T:T,P:P,"*/05/2026")/(SUMIFS(R:R,P:P,"*/05/2026")+SUMIFS(S:S,P:P,"*/05/2026")+SUMIFS(T:T,P:P,"*/05/2026")),"") -> 0.30768594 | O6: 5 | P6: 03/01/2026 | Q6: CD | R6: 620 | S6: 1400 | T6: 160
A7: 6 | B7: 03/06/2026 | C7: CD | D7: 251 | E7: 468 | F7: 0 | H7: T6 | I7: 0.67764706 | J7: 0.66694737 | K7: =IFERROR(SUMIFS(S:S,P:P,"*/06/2026")/(SUMIFS(R:R,P:P,"*/06/2026")+SUMIFS(S:S,P:P,"*/06/2026")+SUMIFS(T:T,P:P,"*/06/2026")),"") -> 0.45992775 | L7: =IFERROR(SUMIFS(R:R,P:P,"*/06/2026")/(SUMIFS(R:R,P:P,"*/06/2026")+SUMIFS(S:S,P:P,"*/06/2026")+SUMIFS(T:T,P:P,"*/06/2026")),"") -> 0.41825962 | M7: =IFERROR(SUMIFS(T:T,P:P,"*/06/2026")/(SUMIFS(R:R,P:P,"*/06/2026")+SUMIFS(S:S,P:P,"*/06/2026")+SUMIFS(T:T,P:P,"*/06/2026")),"") -> 0.12181263 | O7: 6 | P7: 04/01/2026 | Q7: CN | R7: 0 | S7: 0 | T7: 720
A8: 7 | B8: 04/06/2026 | C8: CN | D8: 317 | E8: 403 | F8: 0 | H8: T7 | I8: 0.67764706 | J8: 0.66694737 | K8: =IFERROR(SUMIFS(S:S,P:P,"*/07/2026")/(SUMIFS(R:R,P:P,"*/07/2026")+SUMIFS(S:S,P:P,"*/07/2026")+SUMIFS(T:T,P:P,"*/07/2026")),"") | L8: =IFERROR(SUMIFS(R:R,P:P,"*/07/2026")/(SUMIFS(R:R,P:P,"*/07/2026")+SUMIFS(S:S,P:P,"*/07/2026")+SUMIFS(T:T,P:P,"*/07/2026")),"") | M8: =IFERROR(SUMIFS(T:T,P:P,"*/07/2026")/(SUMIFS(R:R,P:P,"*/07/2026")+SUMIFS(S:S,P:P,"*/07/2026")+SUMIFS(T:T,P:P,"*/07/2026")),"") | O8: 7 | P8: 04/01/2026 | Q8: CD | R8: 0 | S8: 0 | T8: 720
A9: 8 | B9: 04/06/2026 | C9: CD | D9: 546 | E9: 818 | F9: 1 | H9: T8 | I9: 0.67764706 | J9: 0.66694737 | K9: =IFERROR(SUMIFS(S:S,P:P,"*/08/2026")/(SUMIFS(R:R,P:P,"*/08/2026")+SUMIFS(S:S,P:P,"*/08/2026")+SUMIFS(T:T,P:P,"*/08/2026")),"") | L9: =IFERROR(SUMIFS(R:R,P:P,"*/08/2026")/(SUMIFS(R:R,P:P,"*/08/2026")+SUMIFS(S:S,P:P,"*/08/2026")+SUMIFS(T:T,P:P,"*/08/2026")),"") | M9: =IFERROR(SUMIFS(T:T,P:P,"*/08/2026")/(SUMIFS(R:R,P:P,"*/08/2026")+SUMIFS(S:S,P:P,"*/08/2026")+SUMIFS(T:T,P:P,"*/08/2026")),"") | O9: 8 | P9: 05/01/2026 | Q9: CN | R9: 181 | S9: 854 | T9: 202
A10: 9 | B10: 05/06/2026 | C10: CN | D10: 482 | E10: 0 | F10: 478 | H10: T9 | I10: 0.67764706 | J10: 0.66694737 | K10: =IFERROR(SUMIFS(S:S,P:P,"*/09/2026")/(SUMIFS(R:R,P:P,"*/09/2026")+SUMIFS(S:S,P:P,"*/09/2026")+SUMIFS(T:T,P:P,"*/09/2026")),"") | L10: =IFERROR(SUMIFS(R:R,P:P,"*/09/2026")/(SUMIFS(R:R,P:P,"*/09/2026")+SUMIFS(S:S,P:P,"*/09/2026")+SUMIFS(T:T,P:P,"*/09/2026")),"") | M10: =IFERROR(SUMIFS(T:T,P:P,"*/09/2026")/(SUMIFS(R:R,P:P,"*/09/2026")+SUMIFS(S:S,P:P,"*/09/2026")+SUMIFS(T:T,P:P,"*/09/2026")),"") | O10: 9 | P10: 05/01/2026 | Q10: CD | R10: 597 | S10: 826 | T10: 1
A11: 10 | B11: 05/06/2026 | C11: CD | D11: 565 | E11: 714 | F11: 161 | H11: T10 | I11: 0.67764706 | J11: 0.66694737 | K11: =IFERROR(SUMIFS(S:S,P:P,"*/10/2026")/(SUMIFS(R:R,P:P,"*/10/2026")+SUMIFS(S:S,P:P,"*/10/2026")+SUMIFS(T:T,P:P,"*/10/2026")),"") | L11: =IFERROR(SUMIFS(R:R,P:P,"*/10/2026")/(SUMIFS(R:R,P:P,"*/10/2026")+SUMIFS(S:S,P:P,"*/10/2026")+SUMIFS(T:T,P:P,"*/10/2026")),"") | M11: =IFERROR(SUMIFS(T:T,P:P,"*/10/2026")/(SUMIFS(R:R,P:P,"*/10/2026")+SUMIFS(S:S,P:P,"*/10/2026")+SUMIFS(T:T,P:P,"*/10/2026")),"") | O11: 10 | P11: 06/01/2026 | Q11: CN | R11: 858 | S11: 581 | T11: 1
A12: 11 | B12: 06/06/2026 | C12: CN | D12: 720 | E12: 0 | F12: 720 | H12: T11 | I12: 0.67764706 | J12: 0.66694737 | K12: =IFERROR(SUMIFS(S:S,P:P,"*/11/2026")/(SUMIFS(R:R,P:P,"*/11/2026")+SUMIFS(S:S,P:P,"*/11/2026")+SUMIFS(T:T,P:P,"*/11/2026")),"") | L12: =IFERROR(SUMIFS(R:R,P:P,"*/11/2026")/(SUMIFS(R:R,P:P,"*/11/2026")+SUMIFS(S:S,P:P,"*/11/2026")+SUMIFS(T:T,P:P,"*/11/2026")),"") | M12: =IFERROR(SUMIFS(T:T,P:P,"*/11/2026")/(SUMIFS(R:R,P:P,"*/11/2026")+SUMIFS(S:S,P:P,"*/11/2026")+SUMIFS(T:T,P:P,"*/11/2026")),"") | O12: 11 | P12: 06/01/2026 | Q12: CD | R12: 659 | S12: 779 | T12: 1
A13: 12 | B13: 06/06/2026 | C13: CD | D13: 352 | E13: 580 | F13: 259 | H13: T12 | I13: 0.67764706 | J13: 0.66694737 | K13: =IFERROR(SUMIFS(S:S,P:P,"*/12/2026")/(SUMIFS(R:R,P:P,"*/12/2026")+SUMIFS(S:S,P:P,"*/12/2026")+SUMIFS(T:T,P:P,"*/12/2026")),"") | L13: =IFERROR(SUMIFS(R:R,P:P,"*/12/2026")/(SUMIFS(R:R,P:P,"*/12/2026")+SUMIFS(S:S,P:P,"*/12/2026")+SUMIFS(T:T,P:P,"*/12/2026")),"") | M13: =IFERROR(SUMIFS(T:T,P:P,"*/12/2026")/(SUMIFS(R:R,P:P,"*/12/2026")+SUMIFS(S:S,P:P,"*/12/2026")+SUMIFS(T:T,P:P,"*/12/2026")),"") | O13: 12 | P13: 07/01/2026 | Q13: CN | R13: 529 | S13: 147 | T13: 381
A14: 13 | B14: 07/06/2026 | C14: CN | D14: 0 | E14: 0 | F14: 720 | H14: =IF(B2="","",TEXT(B2,"dd/mm")& "-" &IF(UPPER(TRIM(C2))="CN",1,IF(UPPER(TRIM(C2))="CD",2,""))) -> 01/06-1 | I14: 0.67764706 | J14: 0.66694737 | K14: =IFERROR($E2/SUM($D2:$F2),"") -> 0.61420613 | L14: =IFERROR($D2/SUM($D2:$F2),"") -> 0.10445682 | M14: =IFERROR($F2/SUM($D2:$F2),"") -> 0.28133705 | O14: 13 | P14: 07/01/2026 | Q14: CD | R14: 0 | S14: 0 | T14: 720
A15: 14 | B15: 07/06/2026 | C15: CD | D15: 0 | E15: 0 | F15: 720 | H15: =IF(B3="","",TEXT(B3,"dd/mm") & "-" & IF(UPPER(TRIM(C3))="CN",1,IF(UPPER(TRIM(C3))="CD",2,""))) -> 01/06-2 | I15: 0.67764706 | J15: 0.66694737 | K15: =IFERROR($E3/SUM($D3:$F3),"") -> 0.52361111 | L15: =IFERROR($D3/SUM($D3:$F3),"") -> 0.47638889 | M15: =IFERROR($F3/SUM($D3:$F3),"") -> 0 | O15: 14 | P15: 08/01/2026 | Q15: CN | R15: 370 | S15: 653 | T15: 208
A16: 15 | B16: 08/06/2026 | C16: CN | D16: 312 | E16: 722 | F16: 203 | H16: =IF(B4="","",TEXT(B4,"dd/mm") & "-" & IF(UPPER(TRIM(C4))="CN",1,IF(UPPER(TRIM(C4))="CD",2,""))) -> 02/06-1 | I16: 0.67764706 | J16: 0.66694737 | K16: =IFERROR($E4/SUM($D4:$F4),"") -> 0.57777778 | L16: =IFERROR($D4/SUM($D4:$F4),"") -> 0.42222222 | M16: =IFERROR($F4/SUM($D4:$F4),"") -> 0 | O16: 15 | P16: 08/01/2026 | Q16: CD | R16: 634 | S16: 805 | T16: 1
A17: 16 | B17: 08/06/2026 | C17: CD | D17: 566 | E17: 874 | F17: 1 | H17: =IF(B5="","",TEXT(B5,"dd/mm") & "-" & IF(UPPER(TRIM(C5))="CN",1,IF(UPPER(TRIM(C5))="CD",2,""))) -> 02/06-2 | I17: 0.67764706 | J17: 0.66694737 | K17: =IFERROR($E5/SUM($D5:$F5),"") -> 0.61613352 | L17: =IFERROR($D5/SUM($D5:$F5),"") -> 0.38386648 | M17: =IFERROR($F5/SUM($D5:$F5),"") -> 0 | O17: 16 | P17: 09/01/2026 | Q17: CN | R17: 836 | S17: 602 | T17: 1
A18: 17 | B18: 09/06/2026 | C18: CN | D18: 690 | E18: 749 | F18: 1 | H18: =IF(B6="","",TEXT(B6,"dd/mm") & "-" & IF(UPPER(TRIM(C6))="CN",1,IF(UPPER(TRIM(C6))="CD",2,""))) -> 03/06-1 | I18: 0.67764706 | J18: 0.66694737 | K18: =IFERROR($E6/SUM($D6:$F6),"") -> 0.53055556 | L18: =IFERROR($D6/SUM($D6:$F6),"") -> 0.46944444 | M18: =IFERROR($F6/SUM($D6:$F6),"") -> 0 | O18: 17 | P18: 09/01/2026 | Q18: CD | R18: 625 | S18: 815 | T18: 1
A19: 18 | B19: 09/06/2026 | C19: CD | D19: 487 | E19: 951 | F19: 1 | H19: =IF(B7="","",TEXT(B7,"dd/mm") & "-" & IF(UPPER(TRIM(C7))="CN",1,IF(UPPER(TRIM(C7))="CD",2,""))) -> 03/06-2 | I19: 0.67764706 | J19: 0.66694737 | K19: =IFERROR($E7/SUM($D7:$F7),"") -> 0.65090403 | L19: =IFERROR($D7/SUM($D7:$F7),"") -> 0.34909597 | M19: =IFERROR($F7/SUM($D7:$F7),"") -> 0 | O19: 18 | P19: 10/01/2026 | Q19: CN | R19: 804 | S19: 632 | T19: 1
A20: 19 | B20: 10/06/2026 | C20: CN | D20: 714 | E20: 726 | F20: 1 | H20: =IF(B8="","",TEXT(B8,"dd/mm") & "-" & IF(UPPER(TRIM(C8))="CN",1,IF(UPPER(TRIM(C8))="CD",2,""))) -> 04/06-1 | I20: 0.67764706 | J20: 0.66694737 | K20: =IFERROR($E8/SUM($D8:$F8),"") -> 0.55972222 | L20: =IFERROR($D8/SUM($D8:$F8),"") -> 0.44027778 | M20: =IFERROR($F8/SUM($D8:$F8),"") -> 0 | O20: 19 | P20: 10/01/2026 | Q20: CD | R20: 0 | S20: 0 | T20: 720
A21: 20 | B21: 10/06/2026 | C21: CD | D21: 475 | E21: 964 | F21: 1 | H21: =IF(B9="","",TEXT(B9,"dd/mm") & "-" & IF(UPPER(TRIM(C9))="CN",1,IF(UPPER(TRIM(C9))="CD",2,""))) -> 04/06-2 | I21: 0.67764706 | J21: 0.66694737 | K21: =IFERROR($E9/SUM($D9:$F9),"") -> 0.5992674 | L21: =IFERROR($D9/SUM($D9:$F9),"") -> 0.4 | M21: =IFERROR($F9/SUM($D9:$F9),"") -> 0.00073260073 | O21: 20 | P21: 11/01/2026 | Q21: CN | R21: 0 | S21: 0 | T21: 720
A22: 21 | B22: 11/06/2026 | C22: CN | D22: 714 | E22: 725 | F22: 1 | H22: =IF(B10="","",TEXT(B10,"dd/mm") & "-" & IF(UPPER(TRIM(C10))="CN",1,IF(UPPER(TRIM(C10))="CD",2,""))) -> 05/06-1 | I22: 0.67764706 | J22: 0.66694737 | K22: =IFERROR($E10/SUM($D10:$F10),"") -> 0 | L22: =IFERROR($D10/SUM($D10:$F10),"") -> 0.50208333 | M22: =IFERROR($F10/SUM($D10:$F10),"") -> 0.49791667 | O22: 21 | P22: 11/01/2026 | Q22: CD | R22: 0 | S22: 0 | T22: 720
A23: 22 | B23: 11/06/2026 | C23: CD | D23: 549 | E23: 889 | F23: 1 | H23: =IF(B11="","",TEXT(B11,"dd/mm") & "-" & IF(UPPER(TRIM(C11))="CN",1,IF(UPPER(TRIM(C11))="CD",2,""))) -> 05/06-2 | I23: 0.67764706 | J23: 0.66694737 | K23: =IFERROR($E11/SUM($D11:$F11),"") -> 0.49583333 | L23: =IFERROR($D11/SUM($D11:$F11),"") -> 0.39236111 | M23: =IFERROR($F11/SUM($D11:$F11),"") -> 0.11180556 | O23: 22 | P23: 12/01/2026 | Q23: CN | R23: 303 | S23: 719 | T23: 208
A24: 23 | B24: 12/06/2026 | C24: CN | D24: 804 | E24: 636 | F24: 1 | H24: =IF(B12="","",TEXT(B12,"dd/mm") & "-" & IF(UPPER(TRIM(C12))="CN",1,IF(UPPER(TRIM(C12))="CD",2,""))) -> 06/06-1 | I24: 0.67764706 | J24: 0.66694737 | K24: =IFERROR($E12/SUM($D12:$F12),"") -> 0 | L24: =IFERROR($D12/SUM($D12:$F12),"") -> 0.5 | M24: =IFERROR($F12/SUM($D12:$F12),"") -> 0.5 | O24: 23 | P24: 12/01/2026 | Q24: CD | R24: 469 | S24: 970 | T24: 1
A25: 24 | B25: 12/06/2026 | C25: CD | D25: 605 | E25: 835 | F25: 1 | H25: =IF(B13="","",TEXT(B13,"dd/mm") & "-" & IF(UPPER(TRIM(C13))="CN",1,IF(UPPER(TRIM(C13))="CD",2,""))) -> 06/06-2 | I25: 0.67764706 | J25: 0.66694737 | K25: =IFERROR($E13/SUM($D13:$F13),"") -> 0.48698573 | L25: =IFERROR($D13/SUM($D13:$F13),"") -> 0.29554996 | M25: =IFERROR($F13/SUM($D13:$F13),"") -> 0.21746432 | O25: 24 | P25: 13/01/2026 | Q25: CN | R25: 716 | S25: 722 | T25: 1
A26: 25 | B26: 13/06/2026 | C26: CN | D26: 1440 | E26: 0 | F26: 0 | H26: =IF(B14="","",TEXT(B14,"dd/mm") & "-" & IF(UPPER(TRIM(C14))="CN",1,IF(UPPER(TRIM(C14))="CD",2,""))) -> 07/06-1 | I26: 0.67764706 | J26: 0.66694737 | K26: =IFERROR($E14/SUM($D14:$F14),"") -> 0 | L26: =IFERROR($D14/SUM($D14:$F14),"") -> 0 | M26: =IFERROR($F14/SUM($D14:$F14),"") -> 1 | O26: 25 | P26: 13/01/2026 | Q26: CD | R26: 675 | S26: 764 | T26: 1
H27: =IF(B15="","",TEXT(B15,"dd/mm") & "-" & IF(UPPER(TRIM(C15))="CN",1,IF(UPPER(TRIM(C15))="CD",2,""))) -> 07/06-2 | I27: 0.67764706 | J27: 0.66694737 | K27: =IFERROR($E15/SUM($D15:$F15),"") -> 0 | L27: =IFERROR($D15/SUM($D15:$F15),"") -> 0 | M27: =IFERROR($F15/SUM($D15:$F15),"") -> 1 | O27: 26 | P27: 14/01/2026 | Q27: CN | R27: 743 | S27: 695 | T27: 1
H28: =IF(B16="","",TEXT(B16,"dd/mm") & "-" & IF(UPPER(TRIM(C16))="CN",1,IF(UPPER(TRIM(C16))="CD",2,""))) -> 08/06-1 | I28: 0.67764706 | J28: 0.66694737 | K28: =IFERROR($E16/SUM($D16:$F16),"") -> 0.58367017 | L28: =IFERROR($D16/SUM($D16:$F16),"") -> 0.25222312 | M28: =IFERROR($F16/SUM($D16:$F16),"") -> 0.16410671 | O28: 27 | P28: 14/01/2026 | Q28: CD | R28: 548 | S28: 892 | T28: 1
H29: =IF(B17="","",TEXT(B17,"dd/mm") & "-" & IF(UPPER(TRIM(C17))="CN",1,IF(UPPER(TRIM(C17))="CD",2,""))) -> 08/06-2 | I29: 0.67764706 | J29: 0.66694737 | K29: =IFERROR($E17/SUM($D17:$F17),"") -> 0.60652325 | L29: =IFERROR($D17/SUM($D17:$F17),"") -> 0.39278279 | M29: =IFERROR($F17/SUM($D17:$F17),"") -> 0.00069396253 | O29: 28 | P29: 15/01/2026 | Q29: CN | R29: 719 | S29: 720 | T29: 1
H30: =IF(B18="","",TEXT(B18,"dd/mm") & "-" & IF(UPPER(TRIM(C18))="CN",1,IF(UPPER(TRIM(C18))="CD",2,""))) -> 09/06-1 | I30: 0.67764706 | J30: 0.66694737 | K30: =IFERROR($E18/SUM($D18:$F18),"") -> 0.52013889 | L30: =IFERROR($D18/SUM($D18:$F18),"") -> 0.47916667 | M30: =IFERROR($F18/SUM($D18:$F18),"") -> 0.00069444444 | O30: 29 | P30: 15/01/2026 | Q30: CD | R30: 581 | S30: 858 | T30: 1
H31: =IF(B19="","",TEXT(B19,"dd/mm") & "-" & IF(UPPER(TRIM(C19))="CN",1,IF(UPPER(TRIM(C19))="CD",2,""))) -> 09/06-2 | I31: 0.67764706 | J31: 0.66694737 | K31: =IFERROR($E19/SUM($D19:$F19),"") -> 0.66087561 | L31: =IFERROR($D19/SUM($D19:$F19),"") -> 0.33842946 | M31: =IFERROR($F19/SUM($D19:$F19),"") -> 0.00069492703 | O31: 30 | P31: 16/01/2026 | Q31: CN | R31: 738 | S31: 701 | T31: 1
H32: =IF(B20="","",TEXT(B20,"dd/mm") & "-" & IF(UPPER(TRIM(C20))="CN",1,IF(UPPER(TRIM(C20))="CD",2,""))) -> 10/06-1 | I32: 0.67764706 | J32: 0.66694737 | K32: =IFERROR($E20/SUM($D20:$F20),"") -> 0.50381679 | L32: =IFERROR($D20/SUM($D20:$F20),"") -> 0.49548924 | M32: =IFERROR($F20/SUM($D20:$F20),"") -> 0.00069396253 | O32: 31 | P32: 16/01/2026 | Q32: CD | R32: 611 | S32: 828 | T32: 1
H33: =IF(B21="","",TEXT(B21,"dd/mm") & "-" & IF(UPPER(TRIM(C21))="CN",1,IF(UPPER(TRIM(C21))="CD",2,""))) -> 10/06-2 | I33: 0.67764706 | J33: 0.66694737 | K33: =IFERROR($E21/SUM($D21:$F21),"") -> 0.66944444 | L33: =IFERROR($D21/SUM($D21:$F21),"") -> 0.32986111 | M33: =IFERROR($F21/SUM($D21:$F21),"") -> 0.00069444444 | O33: 32 | P33: 17/01/2026 | Q33: CN | R33: 774 | S33: 665 | T33: 1
H34: =IF(B22="","",TEXT(B22,"dd/mm") & "-" & IF(UPPER(TRIM(C22))="CN",1,IF(UPPER(TRIM(C22))="CD",2,""))) -> 11/06-1 | I34: 0.67764706 | J34: 0.66694737 | K34: =IFERROR($E22/SUM($D22:$F22),"") -> 0.50347222 | L34: =IFERROR($D22/SUM($D22:$F22),"") -> 0.49583333 | M34: =IFERROR($F22/SUM($D22:$F22),"") -> 0.00069444444 | O34: 33 | P34: 17/01/2026 | Q34: CD | R34: 206 | S34: 747 | T34: 242
H35: =IF(B23="","",TEXT(B23,"dd/mm") & "-" & IF(UPPER(TRIM(C23))="CN",1,IF(UPPER(TRIM(C23))="CD",2,""))) -> 11/06-2 | I35: 0.67764706 | J35: 0.66694737 | K35: =IFERROR($E23/SUM($D23:$F23),"") -> 0.61779013 | L35: =IFERROR($D23/SUM($D23:$F23),"") -> 0.38151494 | M35: =IFERROR($F23/SUM($D23:$F23),"") -> 0.00069492703 | O35: 34 | P35: 18/01/2026 | Q35: CN | R35: 0 | S35: 0 | T35: 720
H36: =IF(B24="","",TEXT(B24,"dd/mm") & "-" & IF(UPPER(TRIM(C24))="CN",1,IF(UPPER(TRIM(C24))="CD",2,""))) -> 12/06-1 | I36: 0.67764706 | J36: 0.66694737 | K36: =IFERROR($E24/SUM($D24:$F24),"") -> 0.44136017 | L36: =IFERROR($D24/SUM($D24:$F24),"") -> 0.55794587 | M36: =IFERROR($F24/SUM($D24:$F24),"") -> 0.00069396253 | O36: 35 | P36: 18/01/2026 | Q36: CD | R36: 0 | S36: 0 | T36: 720
H37: =IF(B25="","",TEXT(B25,"dd/mm") & "-" & IF(UPPER(TRIM(C25))="CN",1,IF(UPPER(TRIM(C25))="CD",2,""))) -> 12/06-2 | I37: 0.67764706 | J37: 0.66694737 | K37: =IFERROR($E25/SUM($D25:$F25),"") -> 0.57945871 | L37: =IFERROR($D25/SUM($D25:$F25),"") -> 0.41984733 | M37: =IFERROR($F25/SUM($D25:$F25),"") -> 0.00069396253 | O37: 36 | P37: 19/01/2026 | Q37: CN | R37: 300 | S37: 720 | T37: 211
H38: =IF(B26="","",TEXT(B26,"dd/mm") & "-" & IF(UPPER(TRIM(C26))="CN",1,IF(UPPER(TRIM(C26))="CD",2,""))) -> 13/06-1 | I38: 0.67764706 | J38: 0.66694737 | K38: =IFERROR($E26/SUM($D26:$F26),"") -> 0 | L38: =IFERROR($D26/SUM($D26:$F26),"") -> 1 | M38: =IFERROR($F26/SUM($D26:$F26),"") -> 0 | O38: 37 | P38: 19/01/2026 | Q38: CD | R38: 569 | S38: 870 | T38: 1
H39: =IF(B27="","",TEXT(B27,"dd/mm") & "-" & IF(UPPER(TRIM(C27))="CN",1,IF(UPPER(TRIM(C27))="CD",2,""))) | K39: =IFERROR($E27/SUM($D27:$F27),"") | L39: =IFERROR($D27/SUM($D27:$F27),"") | M39: =IFERROR($F27/SUM($D27:$F27),"") | O39: 38 | P39: 20/01/2026 | Q39: CN | R39: 660 | S39: 779 | T39: 1
H40: =IF(B28="","",TEXT(B28,"dd/mm") & "-" & IF(UPPER(TRIM(C28))="CN",1,IF(UPPER(TRIM(C28))="CD",2,""))) | K40: =IFERROR($E28/SUM($D28:$F28),"") | L40: =IFERROR($D28/SUM($D28:$F28),"") | M40: =IFERROR($F28/SUM($D28:$F28),"") | O40: 39 | P40: 20/01/2026 | Q40: CD | R40: 585 | S40: 854 | T40: 1
...

Sheet GS
A1: ID | B1: Ngày tháng | C1: Ca làm việc | D1: Thời gian hoạt động không tải (phút) | E1: Thời gian hoạt động có tải (phút) | F1: Thời gian tắt máy (phút) | H1: Ngày - Ca | I1: Mục Tiêu C1 | J1: Mục Tiêu C2 | K1: % Có Tải | L1: % Không Tải | M1: % Tắt Máy
A2: 1 | B2: 01/06/2026 | C2: CN | D2: 1848 | E2: 1756 | F2: 1421 | H2: T1 | I2: 0.46588235 | J2: 0.47936842 | K2: =IFERROR(SUMIFS(S:S,P:P,"*/01/2026")/(SUMIFS(R:R,P:P,"*/01/2026")+SUMIFS(S:S,P:P,"*/01/2026")+SUMIFS(T:T,P:P,"*/01/2026")),"") -> 0.27141935 | L2: =IFERROR(SUMIFS(R:R,P:P,"*/01/2026")/(SUMIFS(R:R,P:P,"*/01/2026")+SUMIFS(S:S,P:P,"*/01/2026")+SUMIFS(T:T,P:P,"*/01/2026")),"") -> 0.30444172 | M2: =IFERROR(SUMIFS(T:T,P:P,"*/01/2026")/(SUMIFS(R:R,P:P,"*/01/2026")+SUMIFS(S:S,P:P,"*/01/2026")+SUMIFS(T:T,P:P,"*/01/2026")),"") -> 0.42413893 | O2: 1 | P2: 01/01/2026 | Q2: CN | R2: 0 | S2: 0 | T2: 5040
A3: 2 | B3: 01/06/2026 | C3: CD | D3: 2126 | E3: 1771 | F3: 1128 | H3: T2 | I3: 0.46588235 | J3: 0.47936842 | K3: =IFERROR(SUMIFS(S:S,P:P,"*/02/2026")/(SUMIFS(R:R,P:P,"*/02/2026")+SUMIFS(S:S,P:P,"*/02/2026")+SUMIFS(T:T,P:P,"*/02/2026")),"") -> 0.21431031 | L3: =IFERROR(SUMIFS(R:R,P:P,"*/02/2026")/(SUMIFS(R:R,P:P,"*/02/2026")+SUMIFS(S:S,P:P,"*/02/2026")+SUMIFS(T:T,P:P,"*/02/2026")),"") -> 0.21273084 | M3: =IFERROR(SUMIFS(T:T,P:P,"*/02/2026")/(SUMIFS(R:R,P:P,"*/02/2026")+SUMIFS(S:S,P:P,"*/02/2026")+SUMIFS(T:T,P:P,"*/02/2026")),"") -> 0.57295885 | O3: 2 | P3: 01/01/2026 | Q3: CD | R3: 302 | S3: 165 | T3: 4563
